Workbook

Sheet Base_linha_a_linha
A1: CD_SAFRA | B1: FAZENDA | C1: AMBIENTE | D1: VARIEDADE | E1: CORTE | F1: AREA_HA | G1: TON_CANA | H1: KG_ACUCAR | I1: TCH | J1: ATR | K1: TAH_LINHA
A2: 22122 | B2: Laranjeira Industria | C2: Ambiente C | D2: RB92579 | E2: 4 | F2: 4.69 | G2: 233.932 | H2: 33219.159 | I2: =IFERROR(G2/F2,0) -> 49.878891 | J2: =IFERROR(H2/G2,0) -> 142.00348 | K2: =IFERROR(H2/1000/F2,0) -> 7.0829763
A3: 22223 | B3: Laranjeira Industria | C3: Ambiente C | D3: RB92579 | E3: 5 | F3: 4.69 | G3: 423.178 | H3: 57457.629 | I3: =IFERROR(G3/F3,0) -> 90.229851 | J3: =IFERROR(H3/G3,0) -> 135.7765 | K3: =IFERROR(H3/1000/F3,0) -> 12.251094
A4: 22324 | B4: Laranjeira Industria | C4: Ambiente C | D4: RB92579 | E4: 6 | F4: 4.69 | G4: 97.672 | H4: 12583.776 | I4: =IFERROR(G4/F4,0) -> 20.825586 | J4: =IFERROR(H4/G4,0) -> 128.83709 | K4: =IFERROR(H4/1000/F4,0) -> 2.6831079
A5: 22122 | B5: Laranjeira Industria | C5: Ambiente C | D5: RB92579 | E5: 4 | F5: 1.88 | G5: 92.906 | H5: 13192.976 | I5: =IFERROR(G5/F5,0) -> 49.418085 | J5: =IFERROR(H5/G5,0) -> 142.00348 | K5: =IFERROR(H5/1000/F5,0) -> 7.0175403
A6: 22223 | B6: Laranjeira Industria | C6: Ambiente C | D6: RB92579 | E6: 5 | F6: 1.88 | G6: 170.819 | H6: 23193.204 | I6: =IFERROR(G6/F6,0) -> 90.86117 | J6: =IFERROR(H6/G6,0) -> 135.77649 | K6: =IFERROR(H6/1000/F6,0) -> 12.336811
A7: 22324 | B7: Laranjeira Industria | C7: Ambiente C | D7: RB92579 | E7: 6 | F7: 1.88 | G7: 39.482 | H7: 5086.7459 | I7: =IFERROR(G7/F7,0) -> 21.001064 | J7: =IFERROR(H7/G7,0) -> 128.83709 | K7: =IFERROR(H7/1000/F7,0) -> 2.7057159
A8: 22122 | B8: Laranjeira Industria | C8: Ambiente C | D8: RB92579 | E8: 4 | F8: 1.19 | G8: 59.742 | H8: 8483.5721 | I8: =IFERROR(G8/F8,0) -> 50.203361 | J8: =IFERROR(H8/G8,0) -> 142.00348 | K8: =IFERROR(H8/1000/F8,0) -> 7.1290522
A9: 22223 | B9: Laranjeira Industria | C9: Ambiente C | D9: RB92579 | E9: 5 | F9: 1.19 | G9: 108.733 | H9: 14763.383 | I9: =IFERROR(G9/F9,0) -> 91.372269 | J9: =IFERROR(H9/G9,0) -> 135.77647 | K9: =IFERROR(H9/1000/F9,0) -> 12.406204
A10: 22324 | B10: Laranjeira Industria | C10: Ambiente C | D10: RB92579 | E10: 6 | F10: 1.19 | G10: 24.946 | H10: 3213.97 | I10: =IFERROR(G10/F10,0) -> 20.963025 | J10: =IFERROR(H10/G10,0) -> 128.83709 | K10: =IFERROR(H10/1000/F10,0) -> 2.7008151
A11: 22122 | B11: Laranjeiras | C11: Ambiente C | D11: RB92579 | E11: 5 | F11: 13.63 | G11: 397.839 | H11: 54527.016 | I11: =IFERROR(G11/F11,0) -> 29.188481 | J11: =IFERROR(H11/G11,0) -> 137.058 | K11: =IFERROR(H11/1000/F11,0) -> 4.0005148
A12: 22122 | B12: Laranjeiras | C12: Ambiente C | D12: RB92579 | E12: 4 | F12: 8.93 | G12: 260.852 | H12: 35751.851 | I12: =IFERROR(G12/F12,0) -> 29.21075 | J12: =IFERROR(H12/G12,0) -> 137.05799 | K12: =IFERROR(H12/1000/F12,0) -> 4.0035668
A13: 22122 | B13: Laranjeiras | C13: Ambiente C | D13: RB92579 | E13: 4 | F13: 4.84 | G13: 141.389 | H13: 19378.496 | I13: =IFERROR(G13/F13,0) -> 29.212603 | J13: =IFERROR(H13/G13,0) -> 137.05801 | K13: =IFERROR(H13/1000/F13,0) -> 4.0038214
... A13589: 22425 | B13589: Setor/Lote E-43 Fazenda Jatay | C13589: A Definir | D13589: CV0470 | E13589: 2 | F13589: 9.26 | G13589: 648.244 | H13589: 95599.504 | I13589: =IFERROR(G13589/F13589,0) -> 70.004752 | J13589: =IFERROR(H13589/G13589,0) -> 147.47457 | K13589: =IFERROR(H13589/1000/F13589,0) -> 10.32392

Sheet Variedade_x_Corte
A1: VARIEDADE | B1: C1 | C1: C2 | D1: C3 | E1: C4 | F1: C5 | G1: C6 | H1: C7 | I1: MEDIA | J1: CORTES_COM_DADO | K1: AREA_TOTAL_HA | L1: TAH_GERAL
A2: RB127825 | B2: =IFERROR(SUMIFS(Base_linha_a_linha!$H:$H,Base_linha_a_linha!$D:$D,$A2,Base_linha_a_linha!$E:$E,VALUE(RIGHT(B$1,1)))/1000/SUMIFS(Base_linha_a_linha!$F:$F,Base_linha_a_linha!$D:$D,$A2,Base_linha_a_linha!$E:$E,VALUE(RIGHT(B$1,1))),0) -> 15.986525 | C2: =IFERROR(SUMIFS(Base_linha_a_linha!$H:$H,Base_linha_a_linha!$D:$D,$A2,Base_linha_a_linha!$E:$E,VALUE(RIGHT(C$1,1)))/1000/SUMIFS(Base_linha_a_linha!$F:$F,Base_linha_a_linha!$D:$D,$A2,Base_linha_a_linha!$E:$E,VALUE(RIGHT(C$1,1))),0) -> 0 | D2: =IFERROR(SUMIFS(Base_linha_a_linha!$H:$H,Base_linha_a_linha!$D:$D,$A2,Base_linha_a_linha!$E:$E,VALUE(RIGHT(D$1,1)))/1000/SUMIFS(Base_linha_a_linha!$F:$F,Base_linha_a_linha!$D:$D,$A2,Base_linha_a_linha!$E:$E,VALUE(RIGHT(D$1,1))),0) -> 0 | E2: =IFERROR(SUMIFS(Base_linha_a_linha!$H:$H,Base_linha_a_linha!$D:$D,$A2,Base_linha_a_linha!$E:$E,VALUE(RIGHT(E$1,1)))/1000/SUMIFS(Base_linha_a_linha!$F:$F,Base_linha_a_linha!$D:$D,$A2,Base_linha_a_linha!$E:$E,VALUE(RIGHT(E$1,1))),0) -> 0 | F2: =IFERROR(SUMIFS(Base_linha_a_linha!$H:$H,Base_linha_a_linha!$D:$D,$A2,Base_linha_a_linha!$E:$E,VALUE(RIGHT(F$1,1)))/1000/SUMIFS(Base_linha_a_linha!$F:$F,Base_linha_a_linha!$D:$D,$A2,Base_linha_a_linha!$E:$E,VALUE(RIGHT(F$1,1))),0) -> 0 | G2: =IFERROR(SUMIFS(Base_linha_a_linha!$H:$H,Base_linha_a_linha!$D:$D,$A2,Base_linha_a_linha!$E:$E,VALUE(RIGHT(G$1,1)))/1000/SUMIFS(Base_linha_a_linha!$F:$F,Base_linha_a_linha!$D:$D,$A2,Base_linha_a_linha!$E:$E,VALUE(RIGHT(G$1,1))),0) -> 0 | H2: =IFERROR(SUMIFS(Base_linha_a_linha!$H:$H,Base_linha_a_linha!$D:$D,$A2,Base_linha_a_linha!$E:$E,VALUE(RIGHT(H$1,1)))/1000/SUMIFS(Base_linha_a_linha!$F:$F,Base_linha_a_linha!$D:$D,$A2,Base_linha_a_linha!$E:$E,VALUE(RIGHT(H$1,1))),0) -> 0 | I2: =IFERROR(AVERAGEIF(B2:H2,">0"),0) -> 15.986525 | J2: =COUNTIF(B2:H2,">0") -> 1 | K2: =SUMIFS(Base_linha_a_linha!$F:$F,Base_linha_a_linha!$D:$D,$A2) -> 215.3 | L2: =IFERROR(SUMIFS(Base_linha_a_linha!$H:$H,Base_linha_a_linha!$D:$D,$A2)/1000/SUMIFS(Base_linha_a_linha!$F:$F,Base_linha_a_linha!$D:$D,$A2),0) -> 15.986525
A3: RB975162 | B3: =IFERROR(SUMIFS(Base_linha_a_linha!$H:$H,Base_linha_a_linha!$D:$D,$A3,Base_linha_a_linha!$E:$E,VALUE(RIGHT(B$1,1)))/1000/SUMIFS(Base_linha_a_linha!$F:$F,Base_linha_a_linha!$D:$D,$A3,Base_linha_a_linha!$E:$E,VALUE(RIGHT(B$1,1))),0) -> 17.687664 | C3: =IFERROR(SUMIFS(Base_linha_a_linha!$H:$H,Base_linha_a_linha!$D:$D,$A3,Base_linha_a_linha!$E:$E,VALUE(RIGHT(C$1,1)))/1000/SUMIFS(Base_linha_a_linha!$F:$F,Base_linha_a_linha!$D:$D,$A3,Base_linha_a_linha!$E:$E,VALUE(RIGHT(C$1,1))),0) -> 15.598813 | D3: =IFERROR(SUMIFS(Base_linha_a_linha!$H:$H,Base_linha_a_linha!$D:$D,$A3,Base_linha_a_linha!$E:$E,VALUE(RIGHT(D$1,1)))/1000/SUMIFS(Base_linha_a_linha!$F:$F,Base_linha_a_linha!$D:$D,$A3,Base_linha_a_linha!$E:$E,VALUE(RIGHT(D$1,1))),0) -> 13.513787 | E3: =IFERROR(SUMIFS(Base_linha_a_linha!$H:$H,Base_linha_a_linha!$D:$D,$A3,Base_linha_a_linha!$E:$E,VALUE(RIGHT(E$1,1)))/1000/SUMIFS(Base_linha_a_linha!$F:$F,Base_linha_a_linha!$D:$D,$A3,Base_linha_a_linha!$E:$E,VALUE(RIGHT(E$1,1))),0) -> 0 | F3: =IFERROR(SUMIFS(Base_linha_a_linha!$H:$H,Base_linha_a_linha!$D:$D,$A3,Base_linha_a_linha!$E:$E,VALUE(RIGHT(F$1,1)))/1000/SUMIFS(Base_linha_a_linha!$F:$F,Base_linha_a_linha!$D:$D,$A3,Base_linha_a_linha!$E:$E,VALUE(RIGHT(F$1,1))),0) -> 0 | G3: =IFERROR(SUMIFS(Base_linha_a_linha!$H:$H,Base_linha_a_linha!$D:$D,$A3,Base_linha_a_linha!$E:$E,VALUE(RIGHT(G$1,1)))/1000/SUMIFS(Base_linha_a_linha!$F:$F,Base_linha_a_linha!$D:$D,$A3,Base_linha_a_linha!$E:$E,VALUE(RIGHT(G$1,1))),0) -> 0 | H3: =IFERROR(SUMIFS(Base_linha_a_linha!$H:$H,Base_linha_a_linha!$D:$D,$A3,Base_linha_a_linha!$E:$E,VALUE(RIGHT(H$1,1)))/1000/SUMIFS(Base_linha_a_linha!$F:$F,Base_linha_a_linha!$D:$D,$A3,Base_linha_a_linha!$E:$E,VALUE(RIGHT(H$1,1))),0) -> 0 | I3: =IFERROR(AVERAGEIF(B3:H3,">0"),0) -> 15.600088 | J3: =COUNTIF(B3:H3,">0") -> 3 | K3: =SUMIFS(Base_linha_a_linha!$F:$F,Base_linha_a_linha!$D:$D,$A3) -> 58.85 | L3: =IFERROR(SUMIFS(Base_linha_a_linha!$H:$H,Base_linha_a_linha!$D:$D,$A3)/1000/SUMIFS(Base_linha_a_linha!$F:$F,Base_linha_a_linha!$D:$D,$A3),0) -> 16.08789
A4: CTC9003BT | B4: =IFERROR(SUMIFS(Base_linha_a_linha!$H:$H,Base_linha_a_linha!$D:$D,$A4,Base_linha_a_linha!$E:$E,VALUE(RIGHT(B$1,1)))/1000/SUMIFS(Base_linha_a_linha!$F:$F,Base_linha_a_linha!$D:$D,$A4,Base_linha_a_linha!$E:$E,VALUE(RIGHT(B$1,1))),0) -> 16.441686 | C4: =IFERROR(SUMIFS(Base_linha_a_linha!$H:$H,Base_linha_a_linha!$D:$D,$A4,Base_linha_a_linha!$E:$E,VALUE(RIGHT(C$1,1)))/1000/SUMIFS(Base_linha_a_linha!$F:$F,Base_linha_a_linha!$D:$D,$A4,Base_linha_a_linha!$E:$E,VALUE(RIGHT(C$1,1))),0) -> 16.436425 | D4: =IFERROR(SUMIFS(Base_linha_a_linha!$H:$H,Base_linha_a_linha!$D:$D,$A4,Base_linha_a_linha!$E:$E,VALUE(RIGHT(D$1,1)))/1000/SUMIFS(Base_linha_a_linha!$F:$F,Base_linha_a_linha!$D:$D,$A4,Base_linha_a_linha!$E:$E,VALUE(RIGHT(D$1,1))),0) -> 12.779894 | E4: =IFERROR(SUMIFS(Base_linha_a_linha!$H:$H,Base_linha_a_linha!$D:$D,$A4,Base_linha_a_linha!$E:$E,VALUE(RIGHT(E$1,1)))/1000/SUMIFS(Base_linha_a_linha!$F:$F,Base_linha_a_linha!$D:$D,$A4,Base_linha_a_linha!$E:$E,VALUE(RIGHT(E$1,1))),0) -> 8.5924397 | F4: =IFERROR(SUMIFS(Base_linha_a_linha!$H:$H,Base_linha_a_linha!$D:$D,$A4,Base_linha_a_linha!$E:$E,VALUE(RIGHT(F$1,1)))/1000/SUMIFS(Base_linha_a_linha!$F:$F,Base_linha_a_linha!$D:$D,$A4,Base_linha_a_linha!$E:$E,VALUE(RIGHT(F$1,1))),0) -> 0 | G4: =IFERROR(SUMIFS(Base_linha_a_linha!$H:$H,Base_linha_a_linha!$D:$D,$A4,Base_linha_a_linha!$E:$E,VALUE(RIGHT(G$1,1)))/1000/SUMIFS(Base_linha_a_linha!$F:$F,Base_linha_a_linha!$D:$D,$A4,Base_linha_a_linha!$E:$E,VALUE(RIGHT(G$1,1))),0) -> 0 | H4: =IFERROR(SUMIFS(Base_linha_a_linha!$H:$H,Base_linha_a_linha!$D:$D,$A4,Base_linha_a_linha!$E:$E,VALUE(RIGHT(H$1,1)))/1000/SUMIFS(Base_linha_a_linha!$F:$F,Base_linha_a_linha!$D:$D,$A4,Base_linha_a_linha!$E:$E,VALUE(RIGHT(H$1,1))),0) -> 0 | I4: =IFERROR(AVERAGEIF(B4:H4,">0"),0) -> 13.562611 | J4: =COUNTIF(B4:H4,">0") -> 4 | K4: =SUMIFS(Base_linha_a_linha!$F:$F,Base_linha_a_linha!$D:$D,$A4) -> 224.99 | L4: =IFERROR(SUMIFS(Base_linha_a_linha!$H:$H,Base_linha_a_linha!$D:$D,$A4)/1000/SUMIFS(Base_linha_a_linha!$F:$F,Base_linha_a_linha!$D:$D,$A4),0) -> 14.062059
A5: CV7870 | B5: =IFERROR(SUMIFS(Base_linha_a_linha!$H:$H,Base_linha_a_linha!$D:$D,$A5,Base_linha_a_linha!$E:$E,VALUE(RIGHT(B$1,1)))/1000/SUMIFS(Base_linha_a_linha!$F:$F,Base_linha_a_linha!$D:$D,$A5,Base_linha_a_linha!$E:$E,VALUE(RIGHT(B$1,1))),0) -> 12.923202 | C5: =IFERROR(SUMIFS(Base_linha_a_linha!$H:$H,Base_linha_a_linha!$D:$D,$A5,Base_linha_a_linha!$E:$E,VALUE(RIGHT(C$1,1)))/1000/SUMIFS(Base_linha_a_linha!$F:$F,Base_linha_a_linha!$D:$D,$A5,Base_linha_a_linha!$E:$E,VALUE(RIGHT(C$1,1))),0) -> 0 | D5: =IFERROR(SUMIFS(Base_linha_a_linha!$H:$H,Base_linha_a_linha!$D:$D,$A5,Base_linha_a_linha!$E:$E,VALUE(RIGHT(D$1,1)))/1000/SUMIFS(Base_linha_a_linha!$F:$F,Base_linha_a_linha!$D:$D,$A5,Base_linha_a_linha!$E:$E,VALUE(RIGHT(D$1,1))),0) -> 0 | E5: =IFERROR(SUMIFS(Base_linha_a_linha!$H:$H,Base_linha_a_linha!$D:$D,$A5,Base_linha_a_linha!$E:$E,VALUE(RIGHT(E$1,1)))/1000/SUMIFS(Base_linha_a_linha!$F:$F,Base_linha_a_linha!$D:$D,$A5,Base_linha_a_linha!$E:$E,VALUE(RIGHT(E$1,1))),0) -> 0 | F5: =IFERROR(SUMIFS(Base_linha_a_linha!$H:$H,Base_linha_a_linha!$D:$D,$A5,Base_linha_a_linha!$E:$E,VALUE(RIGHT(F$1,1)))/1000/SUMIFS(Base_linha_a_linha!$F:$F,Base_linha_a_linha!$D:$D,$A5,Base_linha_a_linha!$E:$E,VALUE(RIGHT(F$1,1))),0) -> 0 | G5: =IFERROR(SUMIFS(Base_linha_a_linha!$H:$H,Base_linha_a_linha!$D:$D,$A5,Base_linha_a_linha!$E:$E,VALUE(RIGHT(G$1,1)))/1000/SUMIFS(Base_linha_a_linha!$F:$F,Base_linha_a_linha!$D:$D,$A5,Base_linha_a_linha!$E:$E,VALUE(RIGHT(G$1,1))),0) -> 0 | H5: =IFERROR(SUMIFS(Base_linha_a_linha!$H:$H,Base_linha_a_linha!$D:$D,$A5,Base_linha_a_linha!$E:$E,VALUE(RIGHT(H$1,1)))/1000/SUMIFS(Base_linha_a_linha!$F:$F,Base_linha_a_linha!$D:$D,$A5,Base_linha_a_linha!$E:$E,VALUE(RIGHT(H$1,1))),0) -> 0 | I5: =IFERROR(AVERAGEIF(B5:H5,">0"),0) -> 12.923202 | J5: =COUNTIF(B5:H5,">0") -> 1 | K5: =SUMIFS(Base_linha_a_linha!$F:$F,Base_linha_a_linha!$D:$D,$A5) -> 195.94 | L5: =IFERROR(SUMIFS(Base_linha_a_linha!$H:$H,Base_linha_a_linha!$D:$D,$A5)/1000/SUMIFS(Base_linha_a_linha!$F:$F,Base_linha_a_linha!$D:$D,$A5),0) -> 12.923202
A6: IACSP04-6007 | B6: =IFERROR(SUMIFS(Base_linha_a_linha!$H:$H,Base_linha_a_linha!$D:$D,$A6,Base_linha_a_linha!$E:$E,VALUE(RIGHT(B$1,1)))/1000/SUMIFS(Base_linha_a_linha!$F:$F,Base_linha_a_linha!$D:$D,$A6,Base_linha_a_linha!$E:$E,VALUE(RIGHT(B$1,1))),0) -> 13.80521 | C6: =IFERROR(SUMIFS(Base_linha_a_linha!$H:$H,Base_linha_a_linha!$D:$D,$A6,Base_linha_a_linha!$E:$E,VALUE(RIGHT(C$1,1)))/1000/SUMIFS(Base_linha_a_linha!$F:$F,Base_linha_a_linha!$D:$D,$A6,Base_linha_a_linha!$E:$E,VALUE(RIGHT(C$1,1))),0) -> 12.935461 | D6: =IFERROR(SUMIFS(Base_linha_a_linha!$H:$H,Base_linha_a_linha!$D:$D,$A6,Base_linha_a_linha!$E:$E,VALUE(RIGHT(D$1,1)))/1000/SUMIFS(Base_linha_a_linha!$F:$F,Base_linha_a_linha!$D:$D,$A6,Base_linha_a_linha!$E:$E,VALUE(RIGHT(D$1,1))),0) -> 11.969002 | E6: =IFERROR(SUMIFS(Base_linha_a_linha!$H:$H,Base_linha_a_linha!$D:$D,$A6,Base_linha_a_linha!$E:$E,VALUE(RIGHT(E$1,1)))/1000/SUMIFS(Base_linha_a_linha!$F:$F,Base_linha_a_linha!$D:$D,$A6,Base_linha_a_linha!$E:$E,VALUE(RIGHT(E$1,1))),0) -> 0 | F6: =IFERROR(SUMIFS(Base_linha_a_linha!$H:$H,Base_linha_a_linha!$D:$D,$A6,Base_linha_a_linha!$E:$E,VALUE(RIGHT(F$1,1)))/1000/SUMIFS(Base_linha_a_linha!$F:$F,Base_linha_a_linha!$D:$D,$A6,Base_linha_a_linha!$E:$E,VALUE(RIGHT(F$1,1))),0) -> 0 | G6: =IFERROR(SUMIFS(Base_linha_a_linha!$H:$H,Base_linha_a_linha!$D:$D,$A6,Base_linha_a_linha!$E:$E,VALUE(RIGHT(G$1,1)))/1000/SUMIFS(Base_linha_a_linha!$F:$F,Base_linha_a_linha!$D:$D,$A6,Base_linha_a_linha!$E:$E,VALUE(RIGHT(G$1,1))),0) -> 0 | H6: =IFERROR(SUMIFS(Base_linha_a_linha!$H:$H,Base_linha_a_linha!$D:$D,$A6,Base_linha_a_linha!$E:$E,VALUE(RIGHT(H$1,1)))/1000/SUMIFS(Base_linha_a_linha!$F:$F,Base_linha_a_linha!$D:$D,$A6,Base_linha_a_linha!$E:$E,VALUE(RIGHT(H$1,1))),0) -> 0 | I6: =IFERROR(AVERAGEIF(B6:H6,">0"),0) -> 12.903224 | J6: =COUNTIF(B6:H6,">0") -> 3 | K6: =SUMIFS(Base_linha_a_linha!$F:$F,Base_linha_a_linha!$D:$D,$A6) -> 937.33 | L6: =IFERROR(SUMIFS(Base_linha_a_linha!$H:$H,Base_linha_a_linha!$D:$D,$A6)/1000/SUMIFS(Base_linha_a_linha!$F:$F,Base_linha_a_linha!$D:$D,$A6),0) -> 13.521039
A7: CTC9004 | B7: =IFERROR(SUMIFS(Base_linha_a_linha!$H:$H,Base_linha_a_linha!$D:$D,$A7,Base_linha_a_linha!$E:$E,VALUE(RIGHT(B$1,1)))/1000/SUMIFS(Base_linha_a_linha!$F:$F,Base_linha_a_linha!$D:$D,$A7,Base_linha_a_linha!$E:$E,VALUE(RIGHT(B$1,1))),0) -> 14.566127 | C7: =IFERROR(SUMIFS(Base_linha_a_linha!$H:$H,Base_linha_a_linha!$D:$D,$A7,Base_linha_a_linha!$E:$E,VALUE(RIGHT(C$1,1)))/1000/SUMIFS(Base_linha_a_linha!$F:$F,Base_linha_a_linha!$D:$D,$A7,Base_linha_a_linha!$E:$E,VALUE(RIGHT(C$1,1))),0) -> 0 | D7: =IFERROR(SUMIFS(Base_linha_a_linha!$H:$H,Base_linha_a_linha!$D:$D,$A7,Base_linha_a_linha!$E:$E,VALUE(RIGHT(D$1,1)))/1000/SUMIFS(Base_linha_a_linha!$F:$F,Base_linha_a_linha!$D:$D,$A7,Base_linha_a_linha!$E:$E,VALUE(RIGHT(D$1,1))),0) -> 0 | E7: =IFERROR(SUMIFS(Base_linha_a_linha!$H:$H,Base_linha_a_linha!$D:$D,$A7,Base_linha_a_linha!$E:$E,VALUE(RIGHT(E$1,1)))/1000/SUMIFS(Base_linha_a_linha!$F:$F,Base_linha_a_linha!$D:$D,$A7,Base_linha_a_linha!$E:$E,VALUE(RIGHT(E$1,1))),0) -> 11.148243 | F7: =IFERROR(SUMIFS(Base_linha_a_linha!$H:$H,Base_linha_a_linha!$D:$D,$A7,Base_linha_a_linha!$E:$E,VALUE(RIGHT(F$1,1)))/1000/SUMIFS(Base_linha_a_linha!$F:$F,Base_linha_a_linha!$D:$D,$A7,Base_linha_a_linha!$E:$E,VALUE(RIGHT(F$1,1))),0) -> 0 | G7: =IFERROR(SUMIFS(Base_linha_a_linha!$H:$H,Base_linha_a_linha!$D:$D,$A7,Base_linha_a_linha!$E:$E,VALUE(RIGHT(G$1,1)))/1000/SUMIFS(Base_linha_a_linha!$F:$F,Base_linha_a_linha!$D:$D,$A7,Base_linha_a_linha!$E:$E,VALUE(RIGHT(G$1,1))),0) -> 0 | H7: =IFERROR(SUMIFS(Base_linha_a_linha!$H:$H,Base_linha_a_linha!$D:$D,$A7,Base_linha_a_linha!$E:$E,VALUE(RIGHT(H$1,1)))/1000/SUMIFS(Base_linha_a_linha!$F:$F,Base_linha_a_linha!$D:$D,$A7,Base_linha_a_linha!$E:$E,VALUE(RIGHT(H$1,1))),0) -> 0 | I7: =IFERROR(AVERAGEIF(B7:H7,">0"),0) -> 12.857185 | J7: =COUNTIF(B7:H7,">0") -> 2 | K7: =SUMIFS(Base_linha_a_linha!$F:$F,Base_linha_a_linha!$D:$D,$A7) -> 95.42 | L7: =IFERROR(SUMIFS(Base_linha_a_linha!$H:$H,Base_linha_a_linha!$D:$D,$A7)/1000/SUMIFS(Base_linha_a_linha!$F:$F,Base_linha_a_linha!$D:$D,$A7),0) -> 14.410671
A8: CTC1007 | B8: =IFERROR(SUMIFS(Base_linha_a_linha!$H:$H,Base_linha_a_linha!$D:$D,$A8,Base_linha_a_linha!$E:$E,VALUE(RIGHT(B$1,1)))/1000/SUMIFS(Base_linha_a_linha!$F:$F,Base_linha_a_linha!$D:$D,$A8,Base_linha_a_linha!$E:$E,VALUE(RIGHT(B$1,1))),0) -> 12.619942 | C8: =IFERROR(SUMIFS(Base_linha_a_linha!$H:$H,Base_linha_a_linha!$D:$D,$A8,Base_linha_a_linha!$E:$E,VALUE(RIGHT(C$1,1)))/1000/SUMIFS(Base_linha_a_linha!$F:$F,Base_linha_a_linha!$D:$D,$A8,Base_linha_a_linha!$E:$E,VALUE(RIGHT(C$1,1))),0) -> 0 | D8: =IFERROR(SUMIFS(Base_linha_a_linha!$H:$H,Base_linha_a_linha!$D:$D,$A8,Base_linha_a_linha!$E:$E,VALUE(RIGHT(D$1,1)))/1000/SUMIFS(Base_linha_a_linha!$F:$F,Base_linha_a_linha!$D:$D,$A8,Base_linha_a_linha!$E:$E,VALUE(RIGHT(D$1,1))),0) -> 0 | E8: =IFERROR(SUMIFS(Base_linha_a_linha!$H:$H,Base_linha_a_linha!$D:$D,$A8,Base_linha_a_linha!$E:$E,VALUE(RIGHT(E$1,1)))/1000/SUMIFS(Base_linha_a_linha!$F:$F,Base_linha_a_linha!$D:$D,$A8,Base_linha_a_linha!$E:$E,VALUE(RIGHT(E$1,1))),0) -> 0 | F8: =IFERROR(SUMIFS(Base_linha_a_linha!$H:$H,Base_linha_a_linha!$D:$D,$A8,Base_linha_a_linha!$E:$E,VALUE(RIGHT(F$1,1)))/1000/SUMIFS(Base_linha_a_linha!$F:$F,Base_linha_a_linha!$D:$D,$A8,Base_linha_a_linha!$E:$E,VALUE(RIGHT(F$1,1))),0) -> 0 | G8: =IFERROR(SUMIFS(Base_linha_a_linha!$H:$H,Base_linha_a_linha!$D:$D,$A8,Base_linha_a_linha!$E:$E,VALUE(RIGHT(G$1,1)))/1000/SUMIFS(Base_linha_a_linha!$F:$F,Base_linha_a_linha!$D:$D,$A8,Base_linha_a_linha!$E:$E,VALUE(RIGHT(G$1,1))),0) -> 0 | H8: =IFERROR(SUMIFS(Base_linha_a_linha!$H:$H,Base_linha_a_linha!$D:$D,$A8,Base_linha_a_linha!$E:$E,VALUE(RIGHT(H$1,1)))/1000/SUMIFS(Base_linha_a_linha!$F:$F,Base_linha_a_linha!$D:$D,$A8,Base_linha_a_linha!$E:$E,VALUE(RIGHT(H$1,1))),0) -> 0 | I8: =IFERROR(AVERAGEIF(B8:H8,">0"),0) -> 12.619942 | J8: =COUNTIF(B8:H8,">0") -> 1 | K8: =SUMIFS(Base_linha_a_linha!$F:$F,Base_linha_a_linha!$D:$D,$A8) -> 342.49 | L8: =IFERROR(SUMIFS(Base_linha_a_linha!$H:$H,Base_linha_a_linha!$D:$D,$A8)/1000/SUMIFS(Base_linha_a_linha!$F:$F,Base_linha_a_linha!$D:$D,$A8),0) -> 12.619942
A9: CTC9006 | B9: =IFERROR(SUMIFS(Base_linha_a_linha!$H:$H,Base_linha_a_linha!$D:$D,$A9,Base_linha_a_linha!$E:$E,VALUE(RIGHT(B$1,1)))/1000/SUMIFS(Base_linha_a_linha!$F:$F,Base_linha_a_linha!$D:$D,$A9,Base_linha_a_linha!$E:$E,VALUE(RIGHT(B$1,1))),0) -> 15.166844 | C9: =IFERROR(SUMIFS(Base_linha_a_linha!$H:$H,Base_linha_a_linha!$D:$D,$A9,Base_linha_a_linha!$E:$E,VALUE(RIGHT(C$1,1)))/1000/SUMIFS(Base_linha_a_linha!$F:$F,Base_linha_a_linha!$D:$D,$A9,Base_linha_a_linha!$E:$E,VALUE(RIGHT(C$1,1))),0) -> 13.123065 | D9: =IFERROR(SUMIFS(Base_linha_a_linha!$H:$H,Base_linha_a_linha!$D:$D,$A9,Base_linha_a_linha!$E:$E,VALUE(RIGHT(D$1,1)))/1000/SUMIFS(Base_linha_a_linha!$F:$F,Base_linha_a_linha!$D:$D,$A9,Base_linha_a_linha!$E:$E,VALUE(RIGHT(D$1,1))),0) -> 11.464103 | E9: =IFERROR(SUMIFS(Base_linha_a_linha!$H:$H,Base_linha_a_linha!$D:$D,$A9,Base_linha_a_linha!$E:$E,VALUE(RIGHT(E$1,1)))/1000/SUMIFS(Base_linha_a_linha!$F:$F,Base_linha_a_linha!$D:$D,$A9,Base_linha_a_linha!$E:$E,VALUE(RIGHT(E$1,1))),0) -> 11.728651 | F9: =IFERROR(SUMIFS(Base_linha_a_linha!$H:$H,Base_linha_a_linha!$D:$D,$A9,Base_linha_a_linha!$E:$E,VALUE(RIGHT(F$1,1)))/1000/SUMIFS(Base_linha_a_linha!$F:$F,Base_linha_a_linha!$D:$D,$A9,Base_linha_a_linha!$E:$E,VALUE(RIGHT(F$1,1))),0) -> 9.5508073 | G9: =IFERROR(SUMIFS(Base_linha_a_linha!$H:$H,Base_linha_a_linha!$D:$D,$A9,Base_linha_a_linha!$E:$E,VALUE(RIGHT(G$1,1)))/1000/SUMIFS(Base_linha_a_linha!$F:$F,Base_linha_a_linha!$D:$D,$A9,Base_linha_a_linha!$E:$E,VALUE(RIGHT(G$1,1))),0) -> 0 | H9: =IFERROR(SUMIFS(Base_linha_a_linha!$H:$H,Base_linha_a_linha!$D:$D,$A9,Base_linha_a_linha!$E:$E,VALUE(RIGHT(H$1,1)))/1000/SUMIFS(Base_linha_a_linha!$F:$F,Base_linha_a_linha!$D:$D,$A9,Base_linha_a_linha!$E:$E,VALUE(RIGHT(H$1,1))),0) -> 0 | I9: =IFERROR(AVERAGEIF(B9:H9,">0"),0) -> 12.206694 | J9: =COUNTIF(B9:H9,">0") -> 5 | K9: =SUMIFS(Base_linha_a_linha!$F:$F,Base_linha_a_linha!$D:$D,$A9) -> 6851.24 | L9: =IFERROR(SUMIFS(Base_linha_a_linha!$H:$H,Base_linha_a_linha!$D:$D,$A9)/1000/SUMIFS(Base_linha_a_linha!$F:$F,Base_linha_a_linha!$D:$D,$A9),0) -> 13.802882
A10: CTC9001BT | B10: =IFERROR(SUMIFS(Base_linha_a_linha!$H:$H,Base_linha_a_linha!$D:$D,$A10,Base_linha_a_linha!$E:$E,VALUE(RIGHT(B$1,1)))/1000/SUMIFS(Base_linha_a_linha!$F:$F,Base_linha_a_linha!$D:$D,$A10,Base_linha_a_linha!$E:$E,VALUE(RIGHT(B$1,1))),0) -> 13.54824 | C10: =IFERROR(SUMIFS(Base_linha_a_linha!$H:$H,Base_linha_a_linha!$D:$D,$A10,Base_linha_a_linha!$E:$E,VALUE(RIGHT(C$1,1)))/1000/SUMIFS(Base_linha_a_linha!$F:$F,Base_linha_a_linha!$D:$D,$A10,Base_linha_a_linha!$E:$E,VALUE(RIGHT(C$1,1))),0) -> 14.841034 | D10: =IFERROR(SUMIFS(Base_linha_a_linha!$H:$H,Base_linha_a_linha!$D:$D,$A10,Base_linha_a_linha!$E:$E,VALUE(RIGHT(D$1,1)))/1000/SUMIFS(Base_linha_a_linha!$F:$F,Base_linha_a_linha!$D:$D,$A10,Base_linha_a_linha!$E:$E,VALUE(RIGHT(D$1,1))),0) -> 10.519892 | E10: =IFERROR(SUMIFS(Base_linha_a_linha!$H:$H,Base_linha_a_linha!$D:$D,$A10,Base_linha_a_linha!$E:$E,VALUE(RIGHT(E$1,1)))/1000/SUMIFS(Base_linha_a_linha!$F:$F,Base_linha_a_linha!$D:$D,$A10,Base_linha_a_linha!$E:$E,VALUE(RIGHT(E$1,1))),0) -> 9.7303184 | F10: =IFERROR(SUMIFS(Base_linha_a_linha!$H:$H,Base_linha_a_linha!$D:$D,$A10,Base_linha_a_linha!$E:$E,VALUE(RIGHT(F$1,1)))/1000/SUMIFS(Base_linha_a_linha!$F:$F,Base_linha_a_linha!$D:$D,$A10,Base_linha_a_linha!$E:$E,VALUE(RIGHT(F$1,1))),0) -> 0 | G10: =IFERROR(SUMIFS(Base_linha_a_linha!$H:$H,Base_linha_a_linha!$D:$D,$A10,Base_linha_a_linha!$E:$E,VALUE(RIGHT(G$1,1)))/1000/SUMIFS(Base_linha_a_linha!$F:$F,Base_linha_a_linha!$D:$D,$A10,Base_linha_a_linha!$E:$E,VALUE(RIGHT(G$1,1))),0) -> 0 | H10: =IFERROR(SUMIFS(Base_linha_a_linha!$H:$H,Base_linha_a_linha!$D:$D,$A10,Base_linha_a_linha!$E:$E,VALUE(RIGHT(H$1,1)))/1000/SUMIFS(Base_linha_a_linha!$F:$F,Base_linha_a_linha!$D:$D,$A10,Base_linha_a_linha!$E:$E,VALUE(RIGHT(H$1,1))),0) -> 0 | I10: =IFERROR(AVERAGEIF(B10:H10,">0"),0) -> 12.159871 | J10: =COUNTIF(B10:H10,">0") -> 4 | K10: =SUMIFS(Base_linha_a_linha!$F:$F,Base_linha_a_linha!$D:$D,$A10) -> 7111.55 | L10: =IFERROR(SUMIFS(Base_linha_a_linha!$H:$H,Base_linha_a_linha!$D:$D,$A10)/1000/SUMIFS(Base_linha_a_linha!$F:$F,Base_linha_a_linha!$D:$D,$A10),0) -> 12.398233
A11: CTC9007 | B11: =IFERROR(SUMIFS(Base_linha_a_linha!$H:$H,Base_linha_a_linha!$D:$D,$A11,Base_linha_a_linha!$E:$E,VALUE(RIGHT(B$1,1)))/1000/SUMIFS(Base_linha_a_linha!$F:$F,Base_linha_a_linha!$D:$D,$A11,Base_linha_a_linha!$E:$E,VALUE(RIGHT(B$1,1))),0) -> 15.478772 | C11: =IFERROR(SUMIFS(Base_linha_a_linha!$H:$H,Base_linha_a_linha!$D:$D,$A11,Base_linha_a_linha!$E:$E,VALUE(RIGHT(C$1,1)))/1000/SUMIFS(Base_linha_a_linha!$F:$F,Base_linha_a_linha!$D:$D,$A11,Base_linha_a_linha!$E:$E,VALUE(RIGHT(C$1,1))),0) -> 14.173295 | D11: =IFERROR(SUMIFS(Base_linha_a_linha!$H:$H,Base_linha_a_linha!$D:$D,$A11,Base_linha_a_linha!$E:$E,VALUE(RIGHT(D$1,1)))/1000/SUMIFS(Base_linha_a_linha!$F:$F,Base_linha_a_linha!$D:$D,$A11,Base_linha_a_linha!$E:$E,VALUE(RIGHT(D$1,1))),0) -> 10.486858 | E11: =IFERROR(SUMIFS(Base_linha_a_linha!$H:$H,Base_linha_a_linha!$D:$D,$A11,Base_linha_a_linha!$E:$E,VALUE(RIGHT(E$1,1)))/1000/SUMIFS(Base_linha_a_linha!$F:$F,Base_linha_a_linha!$D:$D,$A11,Base_linha_a_linha!$E:$E,VALUE(RIGHT(E$1,1))),0) -> 8.198113 | F11: =IFERROR(SUMIFS(Base_linha_a_linha!$H:$H,Base_linha_a_linha!$D:$D,$A11,Base_linha_a_linha!$E:$E,VALUE(RIGHT(F$1,1)))/1000/SUMIFS(Base_linha_a_linha!$F:$F,Base_linha_a_linha!$D:$D,$A11,Base_linha_a_linha!$E:$E,VALUE(RIGHT(F$1,1))),0) -> 0 | G11: =IFERROR(SUMIFS(Base_linha_a_linha!$H:$H,Base_linha_a_linha!$D:$D,$A11,Base_linha_a_linha!$E:$E,VALUE(RIGHT(G$1,1)))/1000/SUMIFS(Base_linha_a_linha!$F:$F,Base_linha_a_linha!$D:$D,$A11,Base_linha_a_linha!$E:$E,VALUE(RIGHT(G$1,1))),0) -> 0 | H11: =IFERROR(SUMIFS(Base_linha_a_linha!$H:$H,Base_linha_a_linha!$D:$D,$A11,Base_linha_a_linha!$E:$E,VALUE(RIGHT(H$1,1)))/1000/SUMIFS(Base_linha_a_linha!$F:$F,Base_linha_a_linha!$D:$D,$A11,Base_linha_a_linha!$E:$E,VALUE(RIGHT(H$1,1))),0) -> 0 | I11: =IFERROR(AVERAGEIF(B11:H11,">0"),0) -> 12.084259 | J11: =COUNTIF(B11:H11,">0") -> 4 | K11: =SUMIFS(Base_linha_a_linha!$F:$F,Base_linha_a_linha!$D:$D,$A11) -> 3412.37 | L11: =IFERROR(SUMIFS(Base_linha_a_linha!$H:$H,Base_linha_a_linha!$D:$D,$A11)/1000/SUMIFS(Base_linha_a_linha!$F:$F,Base_linha_a_linha!$D:$D,$A11),0) -> 13.606544
A12: RB075322 | B12: =IFERROR(SUMIFS(Base_linha_a_linha!$H:$H,Base_linha_a_linha!$D:$D,$A12,Base_linha_a_linha!$E:$E,VALUE(RIGHT(B$1,1)))/1000/SUMIFS(Base_linha_a_linha!$F:$F,Base_linha_a_linha!$D:$D,$A12,Base_linha_a_linha!$E:$E,VALUE(RIGHT(B$1,1))),0) -> 11.745395 | C12: =IFERROR(SUMIFS(Base_linha_a_linha!$H:$H,Base_linha_a_linha!$D:$D,$A12,Base_linha_a_linha!$E:$E,VALUE(RIGHT(C$1,1)))/1000/SUMIFS(Base_linha_a_linha!$F:$F,Base_linha_a_linha!$D:$D,$A12,Base_linha_a_linha!$E:$E,VALUE(RIGHT(C$1,1))),0) -> 12.265259 | D12: =IFERROR(SUMIFS(Base_linha_a_linha!$H:$H,Base_linha_a_linha!$D:$D,$A12,Base_linha_a_linha!$E:$E,VALUE(RIGHT(D$1,1)))/1000/SUMIFS(Base_linha_a_linha!$F:$F,Base_linha_a_linha!$D:$D,$A12,Base_linha_a_linha!$E:$E,VALUE(RIGHT(D$1,1))),0) -> 0 | E12: =IFERROR(SUMIFS(Base_linha_a_linha!$H:$H,Base_linha_a_linha!$D:$D,$A12,Base_linha_a_linha!$E:$E,VALUE(RIGHT(E$1,1)))/1000/SUMIFS(Base_linha_a_linha!$F:$F,Base_linha_a_linha!$D:$D,$A12,Base_linha_a_linha!$E:$E,VALUE(RIGHT(E$1,1))),0) -> 0 | F12: =IFERROR(SUMIFS(Base_linha_a_linha!$H:$H,Base_linha_a_linha!$D:$D,$A12,Base_linha_a_linha!$E:$E,VALUE(RIGHT(F$1,1)))/1000/SUMIFS(Base_linha_a_linha!$F:$F,Base_linha_a_linha!$D:$D,$A12,Base_linha_a_linha!$E:$E,VALUE(RIGHT(F$1,1))),0) -> 0 | G12: =IFERROR(SUMIFS(Base_linha_a_linha!$H:$H,Base_linha_a_linha!$D:$D,$A12,Base_linha_a_linha!$E:$E,VALUE(RIGHT(G$1,1)))/1000/SUMIFS(Base_linha_a_linha!$F:$F,Base_linha_a_linha!$D:$D,$A12,Base_linha_a_linha!$E:$E,VALUE(RIGHT(G$1,1))),0) -> 0 | H12: =IFERROR(SUMIFS(Base_linha_a_linha!$H:$H,Base_linha_a_linha!$D:$D,$A12,Base_linha_a_linha!$E:$E,VALUE(RIGHT(H$1,1)))/1000/SUMIFS(Base_linha_a_linha!$F:$F,Base_linha_a_linha!$D:$D,$A12,Base_linha_a_linha!$E:$E,VALUE(RIGHT(H$1,1))),0) -> 0 | I12: =IFERROR(AVERAGEIF(B12:H12,">0"),0) -> 12.005327 | J12: =COUNTIF(B12:H12,">0") -> 2 | K12: =SUMIFS(Base_linha_a_linha!$F:$F,Base_linha_a_linha!$D:$D,$A12) -> 56.15 | L12: =IFERROR(SUMIFS(Base_linha_a_linha!$H:$H,Base_linha_a_linha!$D:$D,$A12)/1000/SUMIFS(Base_linha_a_linha!$F:$F,Base_linha_a_linha!$D:$D,$A12),0) -> 11.799557
A13: RB985476 | B13: =IFERROR(SUMIFS(Base_linha_a_linha!$H:$H,Base_linha_a_linha!$D:$D,$A13,Base_linha_a_linha!$E:$E,VALUE(RIGHT(B$1,1)))/1000/SUMIFS(Base_linha_a_linha!$F:$F,Base_linha_a_linha!$D:$D,$A13,Base_linha_a_linha!$E:$E,VALUE(RIGHT(B$1,1))),0) -> 14.88988 | C13: =IFERROR(SUMIFS(Base_linha_a_linha!$H:$H,Base_linha_a_linha!$D:$D,$A13,Base_linha_a_linha!$E:$E,VALUE(RIGHT(C$1,1)))/1000/SUMIFS(Base_linha_a_linha!$F:$F,Base_linha_a_linha!$D:$D,$A13,Base_linha_a_linha!$E:$E,VALUE(RIGHT(C$1,1))),0) -> 12.619551 | D13: =IFERROR(SUMIFS(Base_linha_a_linha!$H:$H,Base_linha_a_linha!$D:$D,$A13,Base_linha_a_linha!$E:$E,VALUE(RIGHT(D$1,1)))/1000/SUMIFS(Base_linha_a_linha!$F:$F,Base_linha_a_linha!$D:$D,$A13,Base_linha_a_linha!$E:$E,VALUE(RIGHT(D$1,1))),0) -> 11.676782 | E13: =IFERROR(SUMIFS(Base_linha_a_linha!$H:$H,Base_linha_a_linha!$D:$D,$A13,Base_linha_a_linha!$E:$E,VALUE(RIGHT(E$1,1)))/1000/SUMIFS(Base_linha_a_linha!$F:$F,Base_linha_a_linha!$D:$D,$A13,Base_linha_a_linha!$E:$E,VALUE(RIGHT(E$1,1))),0) -> 8.6046932 | F13: =IFERROR(SUMIFS(Base_linha_a_linha!$H:$H,Base_linha_a_linha!$D:$D,$A13,Base_linha_a_linha!$E:$E,VALUE(RIGHT(F$1,1)))/1000/SUMIFS(Base_linha_a_linha!$F:$F,Base_linha_a_linha!$D:$D,$A13,Base_linha_a_linha!$E:$E,VALUE(RIGHT(F$1,1))),0) -> 0 | G13: =IFERROR(SUMIFS(Base_linha_a_linha!$H:$H,Base_linha_a_linha!$D:$D,$A13,Base_linha_a_linha!$E:$E,VALUE(RIGHT(G$1,1)))/1000/SUMIFS(Base_linha_a_linha!$F:$F,Base_linha_a_linha!$D:$D,$A13,Base_linha_a_linha!$E:$E,VALUE(RIGHT(G$1,1))),0) -> 0 | H13: =IFERROR(SUMIFS(Base_linha_a_linha!$H:$H,Base_linha_a_linha!$D:$D,$A13,Base_linha_a_linha!$E:$E,VALUE(RIGHT(H$1,1)))/1000/SUMIFS(Base_linha_a_linha!$F:$F,Base_linha_a_linha!$D:$D,$A13,Base_linha_a_linha!$E:$E,VALUE(RIGHT(H$1,1))),0) -> 0 | I13: =IFERROR(AVERAGEIF(B13:H13,">0"),0) -> 11.947727 | J13: =COUNTIF(B13:H13,">0") -> 4 | K13: =SUMIFS(Base_linha_a_linha!$F:$F,Base_linha_a_linha!$D:$D,$A13) -> 674.12 | L13: =IFERROR(SUMIFS(Base_linha_a_linha!$H:$H,Base_linha_a_linha!$D:$D,$A13)/1000/SUMIFS(Base_linha_a_linha!$F:$F,Base_linha_a_linha!$D:$D,$A13),0) -> 12.697885
... A50: RB935744 | B50: =IFERROR(SUMIFS(Base_linha_a_linha!$H:$H,Base_linha_a_linha!$D:$D,$A50,Base_linha_a_linha!$E:$E,VALUE(RIGHT(B$1,1)))/1000/SUMIFS(Base_linha_a_linha!$F:$F,Base_linha_a_linha!$D:$D,$A50,Base_linha_a_linha!$E:$E,VALUE(RIGHT(B$1,1))),0) -> 0 | C50: =IFERROR(SUMIFS(Base_linha_a_linha!$H:$H,Base_linha_a_linha!$D:$D,$A50,Base_linha_a_linha!$E:$E,VALUE(RIGHT(C$1,1)))/1000/SUMIFS(Base_linha_a_linha!$F:$F,Base_linha_a_linha!$D:$D,$A50,Base_linha_a_linha!$E:$E,VALUE(RIGHT(C$1,1))),0) -> 0 | D50: =IFERROR(SUMIFS(Base_linha_a_linha!$H:$H,Base_linha_a_linha!$D:$D,$A50,Base_linha_a_linha!$E:$E,VALUE(RIGHT(D$1,1)))/1000/SUMIFS(Base_linha_a_linha!$F:$F,Base_linha_a_linha!$D:$D,$A50,Base_linha_a_linha!$E:$E,VALUE(RIGHT(D$1,1))),0) -> 0 | E50: =IFERROR(SUMIFS(Base_linha_a_linha!$H:$H,Base_linha_a_linha!$D:$D,$A50,Base_linha_a_linha!$E:$E,VALUE(RIGHT(E$1,1)))/1000/SUMIFS(Base_linha_a_linha!$F:$F,Base_linha_a_linha!$D:$D,$A50,Base_linha_a_linha!$E:$E,VALUE(RIGHT(E$1,1))),0) -> 0 | F50: =IFERROR(SUMIFS(Base_linha_a_linha!$H:$H,Base_linha_a_linha!$D:$D,$A50,Base_linha_a_linha!$E:$E,VALUE(RIGHT(F$1,1)))/1000/SUMIFS(Base_linha_a_linha!$F:$F,Base_linha_a_linha!$D:$D,$A50,Base_linha_a_linha!$E:$E,VALUE(RIGHT(F$1,1))),0) -> 0 | G50: =IFERROR(SUMIFS(Base_linha_a_linha!$H:$H,Base_linha_a_linha!$D:$D,$A50,Base_linha_a_linha!$E:$E,VALUE(RIGHT(G$1,1)))/1000/SUMIFS(Base_linha_a_linha!$F:$F,Base_linha_a_linha!$D:$D,$A50,Base_linha_a_linha!$E:$E,VALUE(RIGHT(G$1,1))),0) -> 0 | H50: =IFERROR(SUMIFS(Base_linha_a_linha!$H:$H,Base_linha_a_linha!$D:$D,$A50,Base_linha_a_linha!$E:$E,VALUE(RIGHT(H$1,1)))/1000/SUMIFS(Base_linha_a_linha!$F:$F,Base_linha_a_linha!$D:$D,$A50,Base_linha_a_linha!$E:$E,VALUE(RIGHT(H$1,1))),0) -> 3.6437555 | I50: =IFERROR(AVERAGEIF(B50:H50,">0"),0) -> 3.6437555 | J50: =COUNTIF(B50:H50,">0") -> 1 | K50: =SUMIFS(Base_linha_a_linha!$F:$F,Base_linha_a_linha!$D:$D,$A50) -> 214.6 | L50: =IFERROR(SUMIFS(Base_linha_a_linha!$H:$H,Base_linha_a_linha!$D:$D,$A50)/1000/SUMIFS(Base_linha_a_linha!$F:$F,Base_linha_a_linha!$D:$D,$A50),0) -> 3.6437555

Sheet Fazenda_x_Corte
A1: FAZENDA | B1: C1 | C1: C2 | D1: C3 | E1: C4 | F1: C5 | G1: C6 | H1: C7 | I1: MEDIA | J1: CORTES_COM_DADO | K1: AREA_TOTAL_HA | L1: TAH_GERAL
A2: Sitio Boa Esperanca (Ricardo) | B2: =IFERROR(SUMIFS(Base_linha_a_linha!$H:$H,Base_linha_a_linha!$B:$B,$A2,Base_linha_a_linha!$E:$E,VALUE(RIGHT(B$1,1)))/1000/SUMIFS(Base_linha_a_linha!$F:$F,Base_linha_a_linha!$B:$B,$A2,Base_linha_a_linha!$E:$E,VALUE(RIGHT(B$1,1))),0) -> 17.407979 | C2: =IFERROR(SUMIFS(Base_linha_a_linha!$H:$H,Base_linha_a_linha!$B:$B,$A2,Base_linha_a_linha!$E:$E,VALUE(RIGHT(C$1,1)))/1000/SUMIFS(Base_linha_a_linha!$F:$F,Base_linha_a_linha!$B:$B,$A2,Base_linha_a_linha!$E:$E,VALUE(RIGHT(C$1,1))),0) -> 0 | D2: =IFERROR(SUMIFS(Base_linha_a_linha!$H:$H,Base_linha_a_linha!$B:$B,$A2,Base_linha_a_linha!$E:$E,VALUE(RIGHT(D$1,1)))/1000/SUMIFS(Base_linha_a_linha!$F:$F,Base_linha_a_linha!$B:$B,$A2,Base_linha_a_linha!$E:$E,VALUE(RIGHT(D$1,1))),0) -> 0 | E2: =IFERROR(SUMIFS(Base_linha_a_linha!$H:$H,Base_linha_a_linha!$B:$B,$A2,Base_linha_a_linha!$E:$E,VALUE(RIGHT(E$1,1)))/1000/SUMIFS(Base_linha_a_linha!$F:$F,Base_linha_a_linha!$B:$B,$A2,Base_linha_a_linha!$E:$E,VALUE(RIGHT(E$1,1))),0) -> 0 | F2: =IFERROR(SUMIFS(Base_linha_a_linha!$H:$H,Base_linha_a_linha!$B:$B,$A2,Base_linha_a_linha!$E:$E,VALUE(RIGHT(F$1,1)))/1000/SUMIFS(Base_linha_a_linha!$F:$F,Base_linha_a_linha!$B:$B,$A2,Base_linha_a_linha!$E:$E,VALUE(RIGHT(F$1,1))),0) -> 0 | G2: =IFERROR(SUMIFS(Base_linha_a_linha!$H:$H,Base_linha_a_linha!$B:$B,$A2,Base_linha_a_linha!$E:$E,VALUE(RIGHT(G$1,1)))/1000/SUMIFS(Base_linha_a_linha!$F:$F,Base_linha_a_linha!$B:$B,$A2,Base_linha_a_linha!$E:$E,VALUE(RIGHT(G$1,1))),0) -> 0 | H2: =IFERROR(SUMIFS(Base_linha_a_linha!$H:$H,Base_linha_a_linha!$B:$B,$A2,Base_linha_a_linha!$E:$E,VALUE(RIGHT(H$1,1)))/1000/SUMIFS(Base_linha_a_linha!$F:$F,Base_linha_a_linha!$B:$B,$A2,Base_linha_a_linha!$E:$E,VALUE(RIGHT(H$1,1))),0) -> 0 | I2: =IFERROR(AVERAGEIF(B2:H2,">0"),0) -> 17.407979 | J2: =COUNTIF(B2:H2,">0") -> 1 | K2: =SUMIFS(Base_linha_a_linha!$F:$F,Base_linha_a_linha!$B:$B,$A2) -> 12.55 | L2: =IFERROR(SUMIFS(Base_linha_a_linha!$H:$H,Base_linha_a_linha!$B:$B,$A2)/1000/SUMIFS(Base_linha_a_linha!$F:$F,Base_linha_a_linha!$B:$B,$A2),0) -> 17.407979
A3: Fazenda Isadora - Lerosa | B3: =IFERROR(SUMIFS(Base_linha_a_linha!$H:$H,Base_linha_a_linha!$B:$B,$A3,Base_linha_a_linha!$E:$E,VALUE(RIGHT(B$1,1)))/1000/SUMIFS(Base_linha_a_linha!$F:$F,Base_linha_a_linha!$B:$B,$A3,Base_linha_a_linha!$E:$E,VALUE(RIGHT(B$1,1))),0) -> 16.103127 | C3: =IFERROR(SUMIFS(Base_linha_a_linha!$H:$H,Base_linha_a_linha!$B:$B,$A3,Base_linha_a_linha!$E:$E,VALUE(RIGHT(C$1,1)))/1000/SUMIFS(Base_linha_a_linha!$F:$F,Base_linha_a_linha!$B:$B,$A3,Base_linha_a_linha!$E:$E,VALUE(RIGHT(C$1,1))),0) -> 0 | D3: =IFERROR(SUMIFS(Base_linha_a_linha!$H:$H,Base_linha_a_linha!$B:$B,$A3,Base_linha_a_linha!$E:$E,VALUE(RIGHT(D$1,1)))/1000/SUMIFS(Base_linha_a_linha!$F:$F,Base_linha_a_linha!$B:$B,$A3,Base_linha_a_linha!$E:$E,VALUE(RIGHT(D$1,1))),0) -> 0 | E3: =IFERROR(SUMIFS(Base_linha_a_linha!$H:$H,Base_linha_a_linha!$B:$B,$A3,Base_linha_a_linha!$E:$E,VALUE(RIGHT(E$1,1)))/1000/SUMIFS(Base_linha_a_linha!$F:$F,Base_linha_a_linha!$B:$B,$A3,Base_linha_a_linha!$E:$E,VALUE(RIGHT(E$1,1))),0) -> 0 | F3: =IFERROR(SUMIFS(Base_linha_a_linha!$H:$H,Base_linha_a_linha!$B:$B,$A3,Base_linha_a_linha!$E:$E,VALUE(RIGHT(F$1,1)))/1000/SUMIFS(Base_linha_a_linha!$F:$F,Base_linha_a_linha!$B:$B,$A3,Base_linha_a_linha!$E:$E,VALUE(RIGHT(F$1,1))),0) -> 0 | G3: =IFERROR(SUMIFS(Base_linha_a_linha!$H:$H,Base_linha_a_linha!$B:$B,$A3,Base_linha_a_linha!$E:$E,VALUE(RIGHT(G$1,1)))/1000/SUMIFS(Base_linha_a_linha!$F:$F,Base_linha_a_linha!$B:$B,$A3,Base_linha_a_linha!$E:$E,VALUE(RIGHT(G$1,1))),0) -> 0 | H3: =IFERROR(SUMIFS(Base_linha_a_linha!$H:$H,Base_linha_a_linha!$B:$B,$A3,Base_linha_a_linha!$E:$E,VALUE(RIGHT(H$1,1)))/1000/SUMIFS(Base_linha_a_linha!$F:$F,Base_linha_a_linha!$B:$B,$A3,Base_linha_a_linha!$E:$E,VALUE(RIGHT(H$1,1))),0) -> 0 | I3: =IFERROR(AVERAGEIF(B3:H3,">0"),0) -> 16.103127 | J3: =COUNTIF(B3:H3,">0") -> 1 | K3: =SUMIFS(Base_linha_a_linha!$F:$F,Base_linha_a_linha!$B:$B,$A3) -> 66.81 | L3: =IFERROR(SUMIFS(Base_linha_a_linha!$H:$H,Base_linha_a_linha!$B:$B,$A3)/1000/SUMIFS(Base_linha_a_linha!$F:$F,Base_linha_a_linha!$B:$B,$A3),0) -> 16.103127
A4: Fazenda Laranjeiras-Lote4QuadraA-Lerosa | B4: =IFERROR(SUMIFS(Base_linha_a_linha!$H:$H,Base_linha_a_linha!$B:$B,$A4,Base_linha_a_linha!$E:$E,VALUE(RIGHT(B$1,1)))/1000/SUMIFS(Base_linha_a_linha!$F:$F,Base_linha_a_linha!$B:$B,$A4,Base_linha_a_linha!$E:$E,VALUE(RIGHT(B$1,1))),0) -> 16.03612 | C4: =IFERROR(SUMIFS(Base_linha_a_linha!$H:$H,Base_linha_a_linha!$B:$B,$A4,Base_linha_a_linha!$E:$E,VALUE(RIGHT(C$1,1)))/1000/SUMIFS(Base_linha_a_linha!$F:$F,Base_linha_a_linha!$B:$B,$A4,Base_linha_a_linha!$E:$E,VALUE(RIGHT(C$1,1))),0) -> 0 | D4: =IFERROR(SUMIFS(Base_linha_a_linha!$H:$H,Base_linha_a_linha!$B:$B,$A4,Base_linha_a_linha!$E:$E,VALUE(RIGHT(D$1,1)))/1000/SUMIFS(Base_linha_a_linha!$F:$F,Base_linha_a_linha!$B:$B,$A4,Base_linha_a_linha!$E:$E,VALUE(RIGHT(D$1,1))),0) -> 0 | E4: =IFERROR(SUMIFS(Base_linha_a_linha!$H:$H,Base_linha_a_linha!$B:$B,$A4,Base_linha_a_linha!$E:$E,VALUE(RIGHT(E$1,1)))/1000/SUMIFS(Base_linha_a_linha!$F:$F,Base_linha_a_linha!$B:$B,$A4,Base_linha_a_linha!$E:$E,VALUE(RIGHT(E$1,1))),0) -> 0 | F4: =IFERROR(SUMIFS(Base_linha_a_linha!$H:$H,Base_linha_a_linha!$B:$B,$A4,Base_linha_a_linha!$E:$E,VALUE(RIGHT(F$1,1)))/1000/SUMIFS(Base_linha_a_linha!$F:$F,Base_linha_a_linha!$B:$B,$A4,Base_linha_a_linha!$E:$E,VALUE(RIGHT(F$1,1))),0) -> 0 | G4: =IFERROR(SUMIFS(Base_linha_a_linha!$H:$H,Base_linha_a_linha!$B:$B,$A4,Base_linha_a_linha!$E:$E,VALUE(RIGHT(G$1,1)))/1000/SUMIFS(Base_linha_a_linha!$F:$F,Base_linha_a_linha!$B:$B,$A4,Base_linha_a_linha!$E:$E,VALUE(RIGHT(G$1,1))),0) -> 0 | H4: =IFERROR(SUMIFS(Base_linha_a_linha!$H:$H,Base_linha_a_linha!$B:$B,$A4,Base_linha_a_linha!$E:$E,VALUE(RIGHT(H$1,1)))/1000/SUMIFS(Base_linha_a_linha!$F:$F,Base_linha_a_linha!$B:$B,$A4,Base_linha_a_linha!$E:$E,VALUE(RIGHT(H$1,1))),0) -> 0 | I4: =IFERROR(AVERAGEIF(B4:H4,">0"),0) -> 16.03612 | J4: =COUNTIF(B4:H4,">0") -> 1 | K4: =SUMIFS(Base_linha_a_linha!$F:$F,Base_linha_a_linha!$B:$B,$A4) -> 31.01 | L4: =IFERROR(SUMIFS(Base_linha_a_linha!$H:$H,Base_linha_a_linha!$B:$B,$A4)/1000/SUMIFS(Base_linha_a_linha!$F:$F,Base_linha_a_linha!$B:$B,$A4),0) -> 16.03612
A5: Fazenda Astorga | B5: =IFERROR(SUMIFS(Base_linha_a_linha!$H:$H,Base_linha_a_linha!$B:$B,$A5,Base_linha_a_linha!$E:$E,VALUE(RIGHT(B$1,1)))/1000/SUMIFS(Base_linha_a_linha!$F:$F,Base_linha_a_linha!$B:$B,$A5,Base_linha_a_linha!$E:$E,VALUE(RIGHT(B$1,1))),0) -> 23.159952 | C5: =IFERROR(SUMIFS(Base_linha_a_linha!$H:$H,Base_linha_a_linha!$B:$B,$A5,Base_linha_a_linha!$E:$E,VALUE(RIGHT(C$1,1)))/1000/SUMIFS(Base_linha_a_linha!$F:$F,Base_linha_a_linha!$B:$B,$A5,Base_linha_a_linha!$E:$E,VALUE(RIGHT(C$1,1))),0) -> 15.948044 | D5: =IFERROR(SUMIFS(Base_linha_a_linha!$H:$H,Base_linha_a_linha!$B:$B,$A5,Base_linha_a_linha!$E:$E,VALUE(RIGHT(D$1,1)))/1000/SUMIFS(Base_linha_a_linha!$F:$F,Base_linha_a_linha!$B:$B,$A5,Base_linha_a_linha!$E:$E,VALUE(RIGHT(D$1,1))),0) -> 7.76629 | E5: =IFERROR(SUMIFS(Base_linha_a_linha!$H:$H,Base_linha_a_linha!$B:$B,$A5,Base_linha_a_linha!$E:$E,VALUE(RIGHT(E$1,1)))/1000/SUMIFS(Base_linha_a_linha!$F:$F,Base_linha_a_linha!$B:$B,$A5,Base_linha_a_linha!$E:$E,VALUE(RIGHT(E$1,1))),0) -> 0 | F5: =IFERROR(SUMIFS(Base_linha_a_linha!$H:$H,Base_linha_a_linha!$B:$B,$A5,Base_linha_a_linha!$E:$E,VALUE(RIGHT(F$1,1)))/1000/SUMIFS(Base_linha_a_linha!$F:$F,Base_linha_a_linha!$B:$B,$A5,Base_linha_a_linha!$E:$E,VALUE(RIGHT(F$1,1))),0) -> 0 | G5: =IFERROR(SUMIFS(Base_linha_a_linha!$H:$H,Base_linha_a_linha!$B:$B,$A5,Base_linha_a_linha!$E:$E,VALUE(RIGHT(G$1,1)))/1000/SUMIFS(Base_linha_a_linha!$F:$F,Base_linha_a_linha!$B:$B,$A5,Base_linha_a_linha!$E:$E,VALUE(RIGHT(G$1,1))),0) -> 0 | H5: =IFERROR(SUMIFS(Base_linha_a_linha!$H:$H,Base_linha_a_linha!$B:$B,$A5,Base_linha_a_linha!$E:$E,VALUE(RIGHT(H$1,1)))/1000/SUMIFS(Base_linha_a_linha!$F:$F,Base_linha_a_linha!$B:$B,$A5,Base_linha_a_linha!$E:$E,VALUE(RIGHT(H$1,1))),0) -> 0 | I5: =IFERROR(AVERAGEIF(B5:H5,">0"),0) -> 15.624762 | J5: =COUNTIF(B5:H5,">0") -> 3 | K5: =SUMIFS(Base_linha_a_linha!$F:$F,Base_linha_a_linha!$B:$B,$A5) -> 268.98 | L5: =IFERROR(SUMIFS(Base_linha_a_linha!$H:$H,Base_linha_a_linha!$B:$B,$A5)/1000/SUMIFS(Base_linha_a_linha!$F:$F,Base_linha_a_linha!$B:$B,$A5),0) -> 15.624762
A6: Fazenda Água do Valão | B6: =IFERROR(SUMIFS(Base_linha_a_linha!$H:$H,Base_linha_a_linha!$B:$B,$A6,Base_linha_a_linha!$E:$E,VALUE(RIGHT(B$1,1)))/1000/SUMIFS(Base_linha_a_linha!$F:$F,Base_linha_a_linha!$B:$B,$A6,Base_linha_a_linha!$E:$E,VALUE(RIGHT(B$1,1))),0) -> 22.586666 | C6: =IFERROR(SUMIFS(Base_linha_a_linha!$H:$H,Base_linha_a_linha!$B:$B,$A6,Base_linha_a_linha!$E:$E,VALUE(RIGHT(C$1,1)))/1000/SUMIFS(Base_linha_a_linha!$F:$F,Base_linha_a_linha!$B:$B,$A6,Base_linha_a_linha!$E:$E,VALUE(RIGHT(C$1,1))),0) -> 14.184475 | D6: =IFERROR(SUMIFS(Base_linha_a_linha!$H:$H,Base_linha_a_linha!$B:$B,$A6,Base_linha_a_linha!$E:$E,VALUE(RIGHT(D$1,1)))/1000/SUMIFS(Base_linha_a_linha!$F:$F,Base_linha_a_linha!$B:$B,$A6,Base_linha_a_linha!$E:$E,VALUE(RIGHT(D$1,1))),0) -> 9.8728836 | E6: =IFERROR(SUMIFS(Base_linha_a_linha!$H:$H,Base_linha_a_linha!$B:$B,$A6,Base_linha_a_linha!$E:$E,VALUE(RIGHT(E$1,1)))/1000/SUMIFS(Base_linha_a_linha!$F:$F,Base_linha_a_linha!$B:$B,$A6,Base_linha_a_linha!$E:$E,VALUE(RIGHT(E$1,1))),0) -> 0 | F6: =IFERROR(SUMIFS(Base_linha_a_linha!$H:$H,Base_linha_a_linha!$B:$B,$A6,Base_linha_a_linha!$E:$E,VALUE(RIGHT(F$1,1)))/1000/SUMIFS(Base_linha_a_linha!$F:$F,Base_linha_a_linha!$B:$B,$A6,Base_linha_a_linha!$E:$E,VALUE(RIGHT(F$1,1))),0) -> 0 | G6: =IFERROR(SUMIFS(Base_linha_a_linha!$H:$H,Base_linha_a_linha!$B:$B,$A6,Base_linha_a_linha!$E:$E,VALUE(RIGHT(G$1,1)))/1000/SUMIFS(Base_linha_a_linha!$F:$F,Base_linha_a_linha!$B:$B,$A6,Base_linha_a_linha!$E:$E,VALUE(RIGHT(G$1,1))),0) -> 0 | H6: =IFERROR(SUMIFS(Base_linha_a_linha!$H:$H,Base_linha_a_linha!$B:$B,$A6,Base_linha_a_linha!$E:$E,VALUE(RIGHT(H$1,1)))/1000/SUMIFS(Base_linha_a_linha!$F:$F,Base_linha_a_linha!$B:$B,$A6,Base_linha_a_linha!$E:$E,VALUE(RIGHT(H$1,1))),0) -> 0 | I6: =IFERROR(AVERAGEIF(B6:H6,">0"),0) -> 15.548008 | J6: =COUNTIF(B6:H6,">0") -> 3 | K6: =SUMIFS(Base_linha_a_linha!$F:$F,Base_linha_a_linha!$B:$B,$A6) -> 462.82 | L6: =IFERROR(SUMIFS(Base_linha_a_linha!$H:$H,Base_linha_a_linha!$B:$B,$A6)/1000/SUMIFS(Base_linha_a_linha!$F:$F,Base_linha_a_linha!$B:$B,$A6),0) -> 15.582508
A7: Sitio Ebenezer | B7: =IFERROR(SUMIFS(Base_linha_a_linha!$H:$H,Base_linha_a_linha!$B:$B,$A7,Base_linha_a_linha!$E:$E,VALUE(RIGHT(B$1,1)))/1000/SUMIFS(Base_linha_a_linha!$F:$F,Base_linha_a_linha!$B:$B,$A7,Base_linha_a_linha!$E:$E,VALUE(RIGHT(B$1,1))),0) -> 19.152298 | C7: =IFERROR(SUMIFS(Base_linha_a_linha!$H:$H,Base_linha_a_linha!$B:$B,$A7,Base_linha_a_linha!$E:$E,VALUE(RIGHT(C$1,1)))/1000/SUMIFS(Base_linha_a_linha!$F:$F,Base_linha_a_linha!$B:$B,$A7,Base_linha_a_linha!$E:$E,VALUE(RIGHT(C$1,1))),0) -> 15.994618 | D7: =IFERROR(SUMIFS(Base_linha_a_linha!$H:$H,Base_linha_a_linha!$B:$B,$A7,Base_linha_a_linha!$E:$E,VALUE(RIGHT(D$1,1)))/1000/SUMIFS(Base_linha_a_linha!$F:$F,Base_linha_a_linha!$B:$B,$A7,Base_linha_a_linha!$E:$E,VALUE(RIGHT(D$1,1))),0) -> 11.095026 | E7: =IFERROR(SUMIFS(Base_linha_a_linha!$H:$H,Base_linha_a_linha!$B:$B,$A7,Base_linha_a_linha!$E:$E,VALUE(RIGHT(E$1,1)))/1000/SUMIFS(Base_linha_a_linha!$F:$F,Base_linha_a_linha!$B:$B,$A7,Base_linha_a_linha!$E:$E,VALUE(RIGHT(E$1,1))),0) -> 0 | F7: =IFERROR(SUMIFS(Base_linha_a_linha!$H:$H,Base_linha_a_linha!$B:$B,$A7,Base_linha_a_linha!$E:$E,VALUE(RIGHT(F$1,1)))/1000/SUMIFS(Base_linha_a_linha!$F:$F,Base_linha_a_linha!$B:$B,$A7,Base_linha_a_linha!$E:$E,VALUE(RIGHT(F$1,1))),0) -> 0 | G7: =IFERROR(SUMIFS(Base_linha_a_linha!$H:$H,Base_linha_a_linha!$B:$B,$A7,Base_linha_a_linha!$E:$E,VALUE(RIGHT(G$1,1)))/1000/SUMIFS(Base_linha_a_linha!$F:$F,Base_linha_a_linha!$B:$B,$A7,Base_linha_a_linha!$E:$E,VALUE(RIGHT(G$1,1))),0) -> 0 | H7: =IFERROR(SUMIFS(Base_linha_a_linha!$H:$H,Base_linha_a_linha!$B:$B,$A7,Base_linha_a_linha!$E:$E,VALUE(RIGHT(H$1,1)))/1000/SUMIFS(Base_linha_a_linha!$F:$F,Base_linha_a_linha!$B:$B,$A7,Base_linha_a_linha!$E:$E,VALUE(RIGHT(H$1,1))),0) -> 0 | I7: =IFERROR(AVERAGEIF(B7:H7,">0"),0) -> 15.413981 | J7: =COUNTIF(B7:H7,">0") -> 3 | K7: =SUMIFS(Base_linha_a_linha!$F:$F,Base_linha_a_linha!$B:$B,$A7) -> 110.71 | L7: =IFERROR(SUMIFS(Base_linha_a_linha!$H:$H,Base_linha_a_linha!$B:$B,$A7)/1000/SUMIFS(Base_linha_a_linha!$F:$F,Base_linha_a_linha!$B:$B,$A7),0) -> 15.435592
A8: Fazenda São Roque II | B8: =IFERROR(SUMIFS(Base_linha_a_linha!$H:$H,Base_linha_a_linha!$B:$B,$A8,Base_linha_a_linha!$E:$E,VALUE(RIGHT(B$1,1)))/1000/SUMIFS(Base_linha_a_linha!$F:$F,Base_linha_a_linha!$B:$B,$A8,Base_linha_a_linha!$E:$E,VALUE(RIGHT(B$1,1))),0) -> 21.692408 | C8: =IFERROR(SUMIFS(Base_linha_a_linha!$H:$H,Base_linha_a_linha!$B:$B,$A8,Base_linha_a_linha!$E:$E,VALUE(RIGHT(C$1,1)))/1000/SUMIFS(Base_linha_a_linha!$F:$F,Base_linha_a_linha!$B:$B,$A8,Base_linha_a_linha!$E:$E,VALUE(RIGHT(C$1,1))),0) -> 15.194274 | D8: =IFERROR(SUMIFS(Base_linha_a_linha!$H:$H,Base_linha_a_linha!$B:$B,$A8,Base_linha_a_linha!$E:$E,VALUE(RIGHT(D$1,1)))/1000/SUMIFS(Base_linha_a_linha!$F:$F,Base_linha_a_linha!$B:$B,$A8,Base_linha_a_linha!$E:$E,VALUE(RIGHT(D$1,1))),0) -> 9.1156728 | E8: =IFERROR(SUMIFS(Base_linha_a_linha!$H:$H,Base_linha_a_linha!$B:$B,$A8,Base_linha_a_linha!$E:$E,VALUE(RIGHT(E$1,1)))/1000/SUMIFS(Base_linha_a_linha!$F:$F,Base_linha_a_linha!$B:$B,$A8,Base_linha_a_linha!$E:$E,VALUE(RIGHT(E$1,1))),0) -> 0 | F8: =IFERROR(SUMIFS(Base_linha_a_linha!$H:$H,Base_linha_a_linha!$B:$B,$A8,Base_linha_a_linha!$E:$E,VALUE(RIGHT(F$1,1)))/1000/SUMIFS(Base_linha_a_linha!$F:$F,Base_linha_a_linha!$B:$B,$A8,Base_linha_a_linha!$E:$E,VALUE(RIGHT(F$1,1))),0) -> 0 | G8: =IFERROR(SUMIFS(Base_linha_a_linha!$H:$H,Base_linha_a_linha!$B:$B,$A8,Base_linha_a_linha!$E:$E,VALUE(RIGHT(G$1,1)))/1000/SUMIFS(Base_linha_a_linha!$F:$F,Base_linha_a_linha!$B:$B,$A8,Base_linha_a_linha!$E:$E,VALUE(RIGHT(G$1,1))),0) -> 0 | H8: =IFERROR(SUMIFS(Base_linha_a_linha!$H:$H,Base_linha_a_linha!$B:$B,$A8,Base_linha_a_linha!$E:$E,VALUE(RIGHT(H$1,1)))/1000/SUMIFS(Base_linha_a_linha!$F:$F,Base_linha_a_linha!$B:$B,$A8,Base_linha_a_linha!$E:$E,VALUE(RIGHT(H$1,1))),0) -> 0 | I8: =IFERROR(AVERAGEIF(B8:H8,">0"),0) -> 15.334118 | J8: =COUNTIF(B8:H8,">0") -> 3 | K8: =SUMIFS(Base_linha_a_linha!$F:$F,Base_linha_a_linha!$B:$B,$A8) -> 157.2 | L8: =IFERROR(SUMIFS(Base_linha_a_linha!$H:$H,Base_linha_a_linha!$B:$B,$A8)/1000/SUMIFS(Base_linha_a_linha!$F:$F,Base_linha_a_linha!$B:$B,$A8),0) -> 15.334118
A9: Fazenda Bandeirantes I | B9: =IFERROR(SUMIFS(Base_linha_a_linha!$H:$H,Base_linha_a_linha!$B:$B,$A9,Base_linha_a_linha!$E:$E,VALUE(RIGHT(B$1,1)))/1000/SUMIFS(Base_linha_a_linha!$F:$F,Base_linha_a_linha!$B:$B,$A9,Base_linha_a_linha!$E:$E,VALUE(RIGHT(B$1,1))),0) -> 13.522795 | C9: =IFERROR(SUMIFS(Base_linha_a_linha!$H:$H,Base_linha_a_linha!$B:$B,$A9,Base_linha_a_linha!$E:$E,VALUE(RIGHT(C$1,1)))/1000/SUMIFS(Base_linha_a_linha!$F:$F,Base_linha_a_linha!$B:$B,$A9,Base_linha_a_linha!$E:$E,VALUE(RIGHT(C$1,1))),0) -> 16.110581 | D9: =IFERROR(SUMIFS(Base_linha_a_linha!$H:$H,Base_linha_a_linha!$B:$B,$A9,Base_linha_a_linha!$E:$E,VALUE(RIGHT(D$1,1)))/1000/SUMIFS(Base_linha_a_linha!$F:$F,Base_linha_a_linha!$B:$B,$A9,Base_linha_a_linha!$E:$E,VALUE(RIGHT(D$1,1))),0) -> 0 | E9: =IFERROR(SUMIFS(Base_linha_a_linha!$H:$H,Base_linha_a_linha!$B:$B,$A9,Base_linha_a_linha!$E:$E,VALUE(RIGHT(E$1,1)))/1000/SUMIFS(Base_linha_a_linha!$F:$F,Base_linha_a_linha!$B:$B,$A9,Base_linha_a_linha!$E:$E,VALUE(RIGHT(E$1,1))),0) -> 0 | F9: =IFERROR(SUMIFS(Base_linha_a_linha!$H:$H,Base_linha_a_linha!$B:$B,$A9,Base_linha_a_linha!$E:$E,VALUE(RIGHT(F$1,1)))/1000/SUMIFS(Base_linha_a_linha!$F:$F,Base_linha_a_linha!$B:$B,$A9,Base_linha_a_linha!$E:$E,VALUE(RIGHT(F$1,1))),0) -> 0 | G9: =IFERROR(SUMIFS(Base_linha_a_linha!$H:$H,Base_linha_a_linha!$B:$B,$A9,Base_linha_a_linha!$E:$E,VALUE(RIGHT(G$1,1)))/1000/SUMIFS(Base_linha_a_linha!$F:$F,Base_linha_a_linha!$B:$B,$A9,Base_linha_a_linha!$E:$E,VALUE(RIGHT(G$1,1))),0) -> 0 | H9: =IFERROR(SUMIFS(Base_linha_a_linha!$H:$H,Base_linha_a_linha!$B:$B,$A9,Base_linha_a_linha!$E:$E,VALUE(RIGHT(H$1,1)))/1000/SUMIFS(Base_linha_a_linha!$F:$F,Base_linha_a_linha!$B:$B,$A9,Base_linha_a_linha!$E:$E,VALUE(RIGHT(H$1,1))),0) -> 0 | I9: =IFERROR(AVERAGEIF(B9:H9,">0"),0) -> 14.816688 | J9: =COUNTIF(B9:H9,">0") -> 2 | K9: =SUMIFS(Base_linha_a_linha!$F:$F,Base_linha_a_linha!$B:$B,$A9) -> 356.12 | L9: =IFERROR(SUMIFS(Base_linha_a_linha!$H:$H,Base_linha_a_linha!$B:$B,$A9)/1000/SUMIFS(Base_linha_a_linha!$F:$F,Base_linha_a_linha!$B:$B,$A9),0) -> 14.818504
A10: Sitio São Pedro | B10: =IFERROR(SUMIFS(Base_linha_a_linha!$H:$H,Base_linha_a_linha!$B:$B,$A10,Base_linha_a_linha!$E:$E,VALUE(RIGHT(B$1,1)))/1000/SUMIFS(Base_linha_a_linha!$F:$F,Base_linha_a_linha!$B:$B,$A10,Base_linha_a_linha!$E:$E,VALUE(RIGHT(B$1,1))),0) -> 18.209465 | C10: =IFERROR(SUMIFS(Base_linha_a_linha!$H:$H,Base_linha_a_linha!$B:$B,$A10,Base_linha_a_linha!$E:$E,VALUE(RIGHT(C$1,1)))/1000/SUMIFS(Base_linha_a_linha!$F:$F,Base_linha_a_linha!$B:$B,$A10,Base_linha_a_linha!$E:$E,VALUE(RIGHT(C$1,1))),0) -> 14.169026 | D10: =IFERROR(SUMIFS(Base_linha_a_linha!$H:$H,Base_linha_a_linha!$B:$B,$A10,Base_linha_a_linha!$E:$E,VALUE(RIGHT(D$1,1)))/1000/SUMIFS(Base_linha_a_linha!$F:$F,Base_linha_a_linha!$B:$B,$A10,Base_linha_a_linha!$E:$E,VALUE(RIGHT(D$1,1))),0) -> 11.767303 | E10: =IFERROR(SUMIFS(Base_linha_a_linha!$H:$H,Base_linha_a_linha!$B:$B,$A10,Base_linha_a_linha!$E:$E,VALUE(RIGHT(E$1,1)))/1000/SUMIFS(Base_linha_a_linha!$F:$F,Base_linha_a_linha!$B:$B,$A10,Base_linha_a_linha!$E:$E,VALUE(RIGHT(E$1,1))),0) -> 0 | F10: =IFERROR(SUMIFS(Base_linha_a_linha!$H:$H,Base_linha_a_linha!$B:$B,$A10,Base_linha_a_linha!$E:$E,VALUE(RIGHT(F$1,1)))/1000/SUMIFS(Base_linha_a_linha!$F:$F,Base_linha_a_linha!$B:$B,$A10,Base_linha_a_linha!$E:$E,VALUE(RIGHT(F$1,1))),0) -> 0 | G10: =IFERROR(SUMIFS(Base_linha_a_linha!$H:$H,Base_linha_a_linha!$B:$B,$A10,Base_linha_a_linha!$E:$E,VALUE(RIGHT(G$1,1)))/1000/SUMIFS(Base_linha_a_linha!$F:$F,Base_linha_a_linha!$B:$B,$A10,Base_linha_a_linha!$E:$E,VALUE(RIGHT(G$1,1))),0) -> 0 | H10: =IFERROR(SUMIFS(Base_linha_a_linha!$H:$H,Base_linha_a_linha!$B:$B,$A10,Base_linha_a_linha!$E:$E,VALUE(RIGHT(H$1,1)))/1000/SUMIFS(Base_linha_a_linha!$F:$F,Base_linha_a_linha!$B:$B,$A10,Base_linha_a_linha!$E:$E,VALUE(RIGHT(H$1,1))),0) -> 0 | I10: =IFERROR(AVERAGEIF(B10:H10,">0"),0) -> 14.715265 | J10: =COUNTIF(B10:H10,">0") -> 3 | K10: =SUMIFS(Base_linha_a_linha!$F:$F,Base_linha_a_linha!$B:$B,$A10) -> 48.55 | L10: =IFERROR(SUMIFS(Base_linha_a_linha!$H:$H,Base_linha_a_linha!$B:$B,$A10)/1000/SUMIFS(Base_linha_a_linha!$F:$F,Base_linha_a_linha!$B:$B,$A10),0) -> 14.674961
A11: Sitio Boa Esperanca | B11: =IFERROR(SUMIFS(Base_linha_a_linha!$H:$H,Base_linha_a_linha!$B:$B,$A11,Base_linha_a_linha!$E:$E,VALUE(RIGHT(B$1,1)))/1000/SUMIFS(Base_linha_a_linha!$F:$F,Base_linha_a_linha!$B:$B,$A11,Base_linha_a_linha!$E:$E,VALUE(RIGHT(B$1,1))),0) -> 0 | C11: =IFERROR(SUMIFS(Base_linha_a_linha!$H:$H,Base_linha_a_linha!$B:$B,$A11,Base_linha_a_linha!$E:$E,VALUE(RIGHT(C$1,1)))/1000/SUMIFS(Base_linha_a_linha!$F:$F,Base_linha_a_linha!$B:$B,$A11,Base_linha_a_linha!$E:$E,VALUE(RIGHT(C$1,1))),0) -> 22.492043 | D11: =IFERROR(SUMIFS(Base_linha_a_linha!$H:$H,Base_linha_a_linha!$B:$B,$A11,Base_linha_a_linha!$E:$E,VALUE(RIGHT(D$1,1)))/1000/SUMIFS(Base_linha_a_linha!$F:$F,Base_linha_a_linha!$B:$B,$A11,Base_linha_a_linha!$E:$E,VALUE(RIGHT(D$1,1))),0) -> 11.526461 | E11: =IFERROR(SUMIFS(Base_linha_a_linha!$H:$H,Base_linha_a_linha!$B:$B,$A11,Base_linha_a_linha!$E:$E,VALUE(RIGHT(E$1,1)))/1000/SUMIFS(Base_linha_a_linha!$F:$F,Base_linha_a_linha!$B:$B,$A11,Base_linha_a_linha!$E:$E,VALUE(RIGHT(E$1,1))),0) -> 9.8620132 | F11: =IFERROR(SUMIFS(Base_linha_a_linha!$H:$H,Base_linha_a_linha!$B:$B,$A11,Base_linha_a_linha!$E:$E,VALUE(RIGHT(F$1,1)))/1000/SUMIFS(Base_linha_a_linha!$F:$F,Base_linha_a_linha!$B:$B,$A11,Base_linha_a_linha!$E:$E,VALUE(RIGHT(F$1,1))),0) -> 0 | G11: =IFERROR(SUMIFS(Base_linha_a_linha!$H:$H,Base_linha_a_linha!$B:$B,$A11,Base_linha_a_linha!$E:$E,VALUE(RIGHT(G$1,1)))/1000/SUMIFS(Base_linha_a_linha!$F:$F,Base_linha_a_linha!$B:$B,$A11,Base_linha_a_linha!$E:$E,VALUE(RIGHT(G$1,1))),0) -> 0 | H11: =IFERROR(SUMIFS(Base_linha_a_linha!$H:$H,Base_linha_a_linha!$B:$B,$A11,Base_linha_a_linha!$E:$E,VALUE(RIGHT(H$1,1)))/1000/SUMIFS(Base_linha_a_linha!$F:$F,Base_linha_a_linha!$B:$B,$A11,Base_linha_a_linha!$E:$E,VALUE(RIGHT(H$1,1))),0) -> 0 | I11: =IFERROR(AVERAGEIF(B11:H11,">0"),0) -> 14.626839 | J11: =COUNTIF(B11:H11,">0") -> 3 | K11: =SUMIFS(Base_linha_a_linha!$F:$F,Base_linha_a_linha!$B:$B,$A11) -> 91.99 | L11: =IFERROR(SUMIFS(Base_linha_a_linha!$H:$H,Base_linha_a_linha!$B:$B,$A11)/1000/SUMIFS(Base_linha_a_linha!$F:$F,Base_linha_a_linha!$B:$B,$A11),0) -> 13.976784
A12: Fazenda Santa Terezinha - GbA e B | B12: =IFERROR(SUMIFS(Base_linha_a_linha!$H:$H,Base_linha_a_linha!$B:$B,$A12,Base_linha_a_linha!$E:$E,VALUE(RIGHT(B$1,1)))/1000/SUMIFS(Base_linha_a_linha!$F:$F,Base_linha_a_linha!$B:$B,$A12,Base_linha_a_linha!$E:$E,VALUE(RIGHT(B$1,1))),0) -> 14.477235 | C12: =IFERROR(SUMIFS(Base_linha_a_linha!$H:$H,Base_linha_a_linha!$B:$B,$A12,Base_linha_a_linha!$E:$E,VALUE(RIGHT(C$1,1)))/1000/SUMIFS(Base_linha_a_linha!$F:$F,Base_linha_a_linha!$B:$B,$A12,Base_linha_a_linha!$E:$E,VALUE(RIGHT(C$1,1))),0) -> 0 | D12: =IFERROR(SUMIFS(Base_linha_a_linha!$H:$H,Base_linha_a_linha!$B:$B,$A12,Base_linha_a_linha!$E:$E,VALUE(RIGHT(D$1,1)))/1000/SUMIFS(Base_linha_a_linha!$F:$F,Base_linha_a_linha!$B:$B,$A12,Base_linha_a_linha!$E:$E,VALUE(RIGHT(D$1,1))),0) -> 0 | E12: =IFERROR(SUMIFS(Base_linha_a_linha!$H:$H,Base_linha_a_linha!$B:$B,$A12,Base_linha_a_linha!$E:$E,VALUE(RIGHT(E$1,1)))/1000/SUMIFS(Base_linha_a_linha!$F:$F,Base_linha_a_linha!$B:$B,$A12,Base_linha_a_linha!$E:$E,VALUE(RIGHT(E$1,1))),0) -> 0 | F12: =IFERROR(SUMIFS(Base_linha_a_linha!$H:$H,Base_linha_a_linha!$B:$B,$A12,Base_linha_a_linha!$E:$E,VALUE(RIGHT(F$1,1)))/1000/SUMIFS(Base_linha_a_linha!$F:$F,Base_linha_a_linha!$B:$B,$A12,Base_linha_a_linha!$E:$E,VALUE(RIGHT(F$1,1))),0) -> 0 | G12: =IFERROR(SUMIFS(Base_linha_a_linha!$H:$H,Base_linha_a_linha!$B:$B,$A12,Base_linha_a_linha!$E:$E,VALUE(RIGHT(G$1,1)))/1000/SUMIFS(Base_linha_a_linha!$F:$F,Base_linha_a_linha!$B:$B,$A12,Base_linha_a_linha!$E:$E,VALUE(RIGHT(G$1,1))),0) -> 0 | H12: =IFERROR(SUMIFS(Base_linha_a_linha!$H:$H,Base_linha_a_linha!$B:$B,$A12,Base_linha_a_linha!$E:$E,VALUE(RIGHT(H$1,1)))/1000/SUMIFS(Base_linha_a_linha!$F:$F,Base_linha_a_linha!$B:$B,$A12,Base_linha_a_linha!$E:$E,VALUE(RIGHT(H$1,1))),0) -> 0 | I12: =IFERROR(AVERAGEIF(B12:H12,">0"),0) -> 14.477235 | J12: =COUNTIF(B12:H12,">0") -> 1 | K12: =SUMIFS(Base_linha_a_linha!$F:$F,Base_linha_a_linha!$B:$B,$A12) -> 147.61 | L12: =IFERROR(SUMIFS(Base_linha_a_linha!$H:$H,Base_linha_a_linha!$B:$B,$A12)/1000/SUMIFS(Base_linha_a_linha!$F:$F,Base_linha_a_linha!$B:$B,$A12),0) -> 14.477235
A13: Fazenda Laranjeiras 3 | B13: =IFERROR(SUMIFS(Base_linha_a_linha!$H:$H,Base_linha_a_linha!$B:$B,$A13,Base_linha_a_linha!$E:$E,VALUE(RIGHT(B$1,1)))/1000/SUMIFS(Base_linha_a_linha!$F:$F,Base_linha_a_linha!$B:$B,$A13,Base_linha_a_linha!$E:$E,VALUE(RIGHT(B$1,1))),0) -> 16.326018 | C13: =IFERROR(SUMIFS(Base_linha_a_linha!$H:$H,Base_linha_a_linha!$B:$B,$A13,Base_linha_a_linha!$E:$E,VALUE(RIGHT(C$1,1)))/1000/SUMIFS(Base_linha_a_linha!$F:$F,Base_linha_a_linha!$B:$B,$A13,Base_linha_a_linha!$E:$E,VALUE(RIGHT(C$1,1))),0) -> 12.307497 | D13: =IFERROR(SUMIFS(Base_linha_a_linha!$H:$H,Base_linha_a_linha!$B:$B,$A13,Base_linha_a_linha!$E:$E,VALUE(RIGHT(D$1,1)))/1000/SUMIFS(Base_linha_a_linha!$F:$F,Base_linha_a_linha!$B:$B,$A13,Base_linha_a_linha!$E:$E,VALUE(RIGHT(D$1,1))),0) -> 14.720279 | E13: =IFERROR(SUMIFS(Base_linha_a_linha!$H:$H,Base_linha_a_linha!$B:$B,$A13,Base_linha_a_linha!$E:$E,VALUE(RIGHT(E$1,1)))/1000/SUMIFS(Base_linha_a_linha!$F:$F,Base_linha_a_linha!$B:$B,$A13,Base_linha_a_linha!$E:$E,VALUE(RIGHT(E$1,1))),0) -> 0 | F13: =IFERROR(SUMIFS(Base_linha_a_linha!$H:$H,Base_linha_a_linha!$B:$B,$A13,Base_linha_a_linha!$E:$E,VALUE(RIGHT(F$1,1)))/1000/SUMIFS(Base_linha_a_linha!$F:$F,Base_linha_a_linha!$B:$B,$A13,Base_linha_a_linha!$E:$E,VALUE(RIGHT(F$1,1))),0) -> 0 | G13: =IFERROR(SUMIFS(Base_linha_a_linha!$H:$H,Base_linha_a_linha!$B:$B,$A13,Base_linha_a_linha!$E:$E,VALUE(RIGHT(G$1,1)))/1000/SUMIFS(Base_linha_a_linha!$F:$F,Base_linha_a_linha!$B:$B,$A13,Base_linha_a_linha!$E:$E,VALUE(RIGHT(G$1,1))),0) -> 0 | H13: =IFERROR(SUMIFS(Base_linha_a_linha!$H:$H,Base_linha_a_linha!$B:$B,$A13,Base_linha_a_linha!$E:$E,VALUE(RIGHT(H$1,1)))/1000/SUMIFS(Base_linha_a_linha!$F:$F,Base_linha_a_linha!$B:$B,$A13,Base_linha_a_linha!$E:$E,VALUE(RIGHT(H$1,1))),0) -> 0 | I13: =IFERROR(AVERAGEIF(B13:H13,">0"),0) -> 14.451265 | J13: =COUNTIF(B13:H13,">0") -> 3 | K13: =SUMIFS(Base_linha_a_linha!$F:$F,Base_linha_a_linha!$B:$B,$A13) -> 275.98 | L13: =IFERROR(SUMIFS(Base_linha_a_linha!$H:$H,Base_linha_a_linha!$B:$B,$A13)/1000/SUMIFS(Base_linha_a_linha!$F:$F,Base_linha_a_linha!$B:$B,$A13),0) -> 14.463356
... A205: Lote 2 - Quadra E | B205: =IFERROR(SUMIFS(Base_linha_a_linha!$H:$H,Base_linha_a_linha!$B:$B,$A205,Base_linha_a_linha!$E:$E,VALUE(RIGHT(B$1,1)))/1000/SUMIFS(Base_linha_a_linha!$F:$F,Base_linha_a_linha!$B:$B,$A205,Base_linha_a_linha!$E:$E,VALUE(RIGHT(B$1,1))),0) -> 0 | C205: =IFERROR(SUMIFS(Base_linha_a_linha!$H:$H,Base_linha_a_linha!$B:$B,$A205,Base_linha_a_linha!$E:$E,VALUE(RIGHT(C$1,1)))/1000/SUMIFS(Base_linha_a_linha!$F:$F,Base_linha_a_linha!$B:$B,$A205,Base_linha_a_linha!$E:$E,VALUE(RIGHT(C$1,1))),0) -> 0 | D205: =IFERROR(SUMIFS(Base_linha_a_linha!$H:$H,Base_linha_a_linha!$B:$B,$A205,Base_linha_a_linha!$E:$E,VALUE(RIGHT(D$1,1)))/1000/SUMIFS(Base_linha_a_linha!$F:$F,Base_linha_a_linha!$B:$B,$A205,Base_linha_a_linha!$E:$E,VALUE(RIGHT(D$1,1))),0) -> 0 | E205: =IFERROR(SUMIFS(Base_linha_a_linha!$H:$H,Base_linha_a_linha!$B:$B,$A205,Base_linha_a_linha!$E:$E,VALUE(RIGHT(E$1,1)))/1000/SUMIFS(Base_linha_a_linha!$F:$F,Base_linha_a_linha!$B:$B,$A205,Base_linha_a_linha!$E:$E,VALUE(RIGHT(E$1,1))),0) -> 1.4740545 | F205: =IFERROR(SUMIFS(Base_linha_a_linha!$H:$H,Base_linha_a_linha!$B:$B,$A205,Base_linha_a_linha!$E:$E,VALUE(RIGHT(F$1,1)))/1000/SUMIFS(Base_linha_a_linha!$F:$F,Base_linha_a_linha!$B:$B,$A205,Base_linha_a_linha!$E:$E,VALUE(RIGHT(F$1,1))),0) -> 0 | G205: =IFERROR(SUMIFS(Base_linha_a_linha!$H:$H,Base_linha_a_linha!$B:$B,$A205,Base_linha_a_linha!$E:$E,VALUE(RIGHT(G$1,1)))/1000/SUMIFS(Base_linha_a_linha!$F:$F,Base_linha_a_linha!$B:$B,$A205,Base_linha_a_linha!$E:$E,VALUE(RIGHT(G$1,1))),0) -> 0 | H205: =IFERROR(SUMIFS(Base_linha_a_linha!$H:$H,Base_linha_a_linha!$B:$B,$A205,Base_linha_a_linha!$E:$E,VALUE(RIGHT(H$1,1)))/1000/SUMIFS(Base_linha_a_linha!$F:$F,Base_linha_a_linha!$B:$B,$A205,Base_linha_a_linha!$E:$E,VALUE(RIGHT(H$1,1))),0) -> 0 | I205: =IFERROR(AVERAGEIF(B205:H205,">0"),0) -> 1.4740545 | J205: =COUNTIF(B205:H205,">0") -> 1 | K205: =SUMIFS(Base_linha_a_linha!$F:$F,Base_linha_a_linha!$B:$B,$A205) -> 16.04 | L205: =IFERROR(SUMIFS(Base_linha_a_linha!$H:$H,Base_linha_a_linha!$B:$B,$A205)/1000/SUMIFS(Base_linha_a_linha!$F:$F,Base_linha_a_linha!$B:$B,$A205),0) -> 1.4740545

Sheet Mapa_Varietal_Ideal
A1: AMBIENTE | B1: RANK | C1: VARIEDADE | D1: AREA_HA | E1: TCH | F1: ATR | G1: TAH | H1: CORTES_COM_DADO | I1: OBS
A2: A Definir | B2: 1 | C2: RB975201 | D2: 53.23 | E2: 110.69224 | F2: 132.92002 | G2: 14.713215 | H2: 2 | I2: Variedade vetada RB975242 excluída da recomendação
A3: A Definir | B3: 2 | C3: RB985476 | D3: 73.06 | E3: 94.997947 | F3: 142.15927 | G3: 13.504838 | H3: 2
A4: A Definir | B4: 3 | C4: CV0470 | D4: 138.58 | E4: 89.882884 | F4: 135.6397 | G4: 12.191687 | H4: 2
A5: A Definir | B5: 4 | C5: RB966928 | D5: 368.08 | E5: 86.178692 | F5: 139.23936 | G5: 11.999466 | H5: 5
A6: A Definir | B6: 5 | C6: IAC87-3396 | D6: 296.86 | E6: 82.323429 | F6: 143.77119 | G6: 11.835737 | H6: 6
A7: Ambiente A | B7: 1 | C7: RB975201 | D7: 96.41 | E7: 121.10519 | F7: 153.00144 | G7: 18.529268 | H7: 1 | I7: Variedade vetada RB975242 excluída da recomendação
A8: Ambiente A | B8: 2 | C8: RB988082 | D8: 50.74 | E8: 119.4435 | F8: 138.773 | G8: 16.575532 | H8: 1
A9: Ambiente A | B9: 3 | C9: CTC9007 | D9: 45.46 | E9: 129.69844 | F9: 122.72812 | G9: 15.917646 | H9: 2
A10: Ambiente A | B10: 4 | C10: CTC9001 | D10: 85.16 | E10: 104.0302 | F10: 144.94804 | G10: 15.078974 | H10: 4
A11: Ambiente A | B11: 5 | C11: CTC9001BT | D11: 106.96 | E11: 98.034873 | F11: 145.47079 | G11: 14.26121 | H11: 4
A12: Ambiente B | B12: 1 | C12: CTC2994 | D12: 13.47 | E12: 133.00846 | F12: 129.92456 | G12: 17.281066 | H12: 1 | I12: Variedade vetada RB975242 excluída da recomendação
A13: Ambiente B | B13: 2 | C13: RB988082 | D13: 43.34 | E13: 129.4509 | F13: 125.74383 | G13: 16.277652 | H13: 1
A14: Ambiente B | B14: 3 | C14: RB975201 | D14: 89.86 | E14: 118.77666 | F14: 127.51152 | G14: 15.145393 | H14: 1
A15: Ambiente B | B15: 4 | C15: RB975952 | D15: 90.82 | E15: 102.70762 | F15: 132.22251 | G15: 13.580259 | H15: 2
A16: Ambiente B | B16: 5 | C16: CTC9007 | D16: 537.48 | E16: 99.511156 | F16: 133.28717 | G16: 13.26356 | H16: 4
A17: Ambiente C | B17: 1 | C17: CTC9003BT | D17: 39.39 | E17: 152.45735 | F17: 121.80169 | G17: 18.569563 | H17: 1 | I17: Variedade vetada RB975242 excluída da recomendação
A18: Ambiente C | B18: 2 | C18: RB988082 | D18: 167.71 | E18: 114.3178 | F18: 131.83382 | G18: 15.070952 | H18: 3
A19: Ambiente C | B19: 3 | C19: IACSP04-6007 | D19: 40.2 | E19: 98.22893 | F19: 145.28194 | G19: 14.270889 | H19: 2
A20: Ambiente C | B20: 4 | C20: CTC9003 | D20: 334.69 | E20: 107.81289 | F20: 130.90537 | G20: 14.113285 | H20: 4
