Workbook
Name SegmentaçãodeDados_DE_FORNEC: #N/A
Name SegmentaçãodeDados_DE_FORNEC1: #N/A
Name SegmentaçãodeDados_GEADA: #N/A
Name SegmentaçãodeDados_GEADA1: #N/A
Name SegmentaçãodeDados_IRRIG_DESCARTE: #N/A
Name SegmentaçãodeDados_TP_CANA: #N/A
Name SegmentaçãodeDados_TP_CANA1: #N/A

Sheet GEADA
A1: CHV | B1: COD | C1: FAZENDA | D1: TL | E1: NOTA
A2: =VALUE(B2&TEXT(D2,"0000")) -> 100050001 | B2: 10005 | C2: Fazenda Laranjeiras 2 | D2: 1 | E2: 1
A3: =VALUE(B3&TEXT(D3,"0000")) -> 100050002 | B3: 10005 | C3: Fazenda Laranjeiras 2 | D3: 2 | E3: 1
A4: =VALUE(B4&TEXT(D4,"0000")) -> 101000001 | B4: 10100 | C4: Sítio Jataí II | D4: 1 | E4: 1
A5: =VALUE(B5&TEXT(D5,"0000")) -> 101000002 | B5: 10100 | C5: Sítio Jataí II | D5: 2 | E5: 1
A6: =VALUE(B6&TEXT(D6,"0000")) -> 103100002 | B6: 10310 | C6: Fazenda Sao Jorge | D6: 2 | E6: 1
A7: =VALUE(B7&TEXT(D7,"0000")) -> 103100003 | B7: 10310 | C7: Fazenda Sao Jorge | D7: 3 | E7: 1
A8: =VALUE(B8&TEXT(D8,"0000")) -> 103100004 | B8: 10310 | C8: Fazenda Sao Jorge | D8: 4 | E8: 1
A9: =VALUE(B9&TEXT(D9,"0000")) -> 103100005 | B9: 10310 | C9: Fazenda Sao Jorge | D9: 5 | E9: 1
A10: =VALUE(B10&TEXT(D10,"0000")) -> 103100006 | B10: 10310 | C10: Fazenda Sao Jorge | D10: 6 | E10: 1
A11: =VALUE(B11&TEXT(D11,"0000")) -> 103100007 | B11: 10310 | C11: Fazenda Sao Jorge | D11: 7 | E11: 1
A12: =VALUE(B12&TEXT(D12,"0000")) -> 103110007 | B12: 10311 | C12: Fazenda Santo Antônio | D12: 7 | E12: 1
A13: =VALUE(B13&TEXT(D13,"0000")) -> 103110008 | B13: 10311 | C13: Fazenda Santo Antônio | D13: 8 | E13: 2
... A180: =VALUE(B180&TEXT(D180,"0000")) -> 206310021 | B180: 20631 | C180: Fazenda Renascer | D180: 21 | E180: 1

Sheet IRRIGADO
A1: Operação | B1: Operação | C1: Fazenda | D1: Fazenda | E1: Talhão | F1: Talhão | G1: Vazão (mm) | H1: Produção | I1: Unid | J1: Mês Aplicado | R1: CD_OPERACAO | S1: CD_UPNIVEL1 | T1: FIMMES | U1: CD_UPNIVEL3 | V1: HORAS | W1: M3 | X1: AREA | Y1: MM | AF1: CD_OPERACAO | AG1: FIMMES | AH1: CD_UPNIVEL1 | AI1: CD_UPNIVEL3 | AJ1: MM_TOTAL | AK1: AREA | AL1: MM
A2: 2805 | B2: IRRIGACAO ASPERCAO | C2: 20305 | D2: Fazenda Vista Bonita | F2: =382 -> 382 | H2: 25.17 | I2: HA | J2: =IF(MAX(_xlfn.MAXIFS(T:T,S:S,C2,U:U,E2),_xlfn.MAXIFS(AG:AG,AH:AH,C2,AI:AI,E2))=0,"",MAX(_xlfn.MAXIFS(T:T,S:S,C2,U:U,E2),_xlfn.MAXIFS(AG:AG,AH:AH,C2,AI:AI,E2))) | K2: =COUNTIFS(TABELA!A:A,C2,TABELA!C:C,E2) -> 0 | L2: =SUMIFS(TABELA!M:M,TABELA!A:A,C2,TABELA!C:C,E2) -> 0 | M2: =IF(L2>0,H2-L2,0) -> 0 | N2: =SUMIFS(X:X,S:S,C2,U:U,E2)+SUMIFS(AK:AK,AH:AH,C2,AI:AI,E2) -> 0 | O2: =SUMIFS(W:W,S:S,C2)/SUMIFS(X:X,S:S,C2)/10 -> #DIV/0! | R2: 2805 | S2: 20314 | T2: 45535 | U2: 135 | V2: 115 | W2: 23000 | X2: 41.34 | Y2: 55.64 | AF2: 2720 | AG2: 45626 | AH2: 20305 | AI2: 189 | AJ2: 301.6 | AK2: 15.08 | AL2: 20
A3: 2805 | B3: IRRIGACAO ASPERCAO | C3: 20305 | D3: Fazenda Vista Bonita | F3: =404 -> 404 | H3: 30 | I3: HA | J3: =IF(MAX(_xlfn.MAXIFS(T:T,S:S,C3,U:U,E3),_xlfn.MAXIFS(AG:AG,AH:AH,C3,AI:AI,E3))=0,"",MAX(_xlfn.MAXIFS(T:T,S:S,C3,U:U,E3),_xlfn.MAXIFS(AG:AG,AH:AH,C3,AI:AI,E3))) | K3: =COUNTIFS(TABELA!A:A,C3,TABELA!C:C,E3) -> 0 | L3: =SUMIFS(TABELA!M:M,TABELA!A:A,C3,TABELA!C:C,E3) -> 0 | M3: =IF(L3>0,H3-L3,0) -> 0 | N3: =SUMIFS(X:X,S:S,C3,U:U,E3)+SUMIFS(AK:AK,AH:AH,C3,AI:AI,E3) -> 0 | O3: =SUMIFS(W:W,S:S,C3)/SUMIFS(X:X,S:S,C3)/10 -> #DIV/0! | R3: 2805 | S3: 20314 | U3: 135 | AF3: 2720 | AG3: 45626 | AH3: 20305 | AI3: 190 | AJ3: 829 | AK3: 41.45 | AL3: 20
A4: 2805 | B4: IRRIGACAO ASPERCAO | C4: 20314 | D4: Fazenda Agua Mansa | E4: 135 | F4: 135 | G4: 34 | H4: 41.34 | I4: HA | J4: =IF(MAX(_xlfn.MAXIFS(T:T,S:S,C4,U:U,E4),_xlfn.MAXIFS(AG:AG,AH:AH,C4,AI:AI,E4))=0,"",MAX(_xlfn.MAXIFS(T:T,S:S,C4,U:U,E4),_xlfn.MAXIFS(AG:AG,AH:AH,C4,AI:AI,E4))) -> 45535 | K4: =COUNTIFS(TABELA!A:A,C4,TABELA!C:C,E4) -> 1 | L4: =SUMIFS(TABELA!M:M,TABELA!A:A,C4,TABELA!C:C,E4) -> 50.74 | M4: =IF(L4>0,H4-L4,0) -> -9.4 | N4: =SUMIFS(X:X,S:S,C4,U:U,E4)+SUMIFS(AK:AK,AH:AH,C4,AI:AI,E4) -> 41.34 | O4: =SUMIFS(W:W,S:S,C4)/SUMIFS(X:X,S:S,C4)/10 -> 33.402727 | R4: 2805 | S4: 20314 | T4: 45535 | U4: 136 | V4: 23 | W4: 4600 | X4: 59.17 | Y4: 7.77 | AF4: 2720 | AG4: 45626 | AH4: 20305 | AI4: 191 | AJ4: 952.6 | AK4: 47.63 | AL4: 20
A5: 2805 | B5: IRRIGACAO ASPERCAO | C5: 20314 | D5: Fazenda Agua Mansa | E5: 136 | F5: 136 | G5: 34 | H5: 59.17 | I5: HA | J5: =IF(MAX(_xlfn.MAXIFS(T:T,S:S,C5,U:U,E5),_xlfn.MAXIFS(AG:AG,AH:AH,C5,AI:AI,E5))=0,"",MAX(_xlfn.MAXIFS(T:T,S:S,C5,U:U,E5),_xlfn.MAXIFS(AG:AG,AH:AH,C5,AI:AI,E5))) -> 45535 | K5: =COUNTIFS(TABELA!A:A,C5,TABELA!C:C,E5) -> 1 | L5: =SUMIFS(TABELA!M:M,TABELA!A:A,C5,TABELA!C:C,E5) -> 68.88 | M5: =IF(L5>0,H5-L5,0) -> -9.71 | N5: =SUMIFS(X:X,S:S,C5,U:U,E5)+SUMIFS(AK:AK,AH:AH,C5,AI:AI,E5) -> 59.17 | O5: =SUMIFS(W:W,S:S,C5)/SUMIFS(X:X,S:S,C5)/10 -> 33.402727 | R5: 2805 | S5: 20314 | U5: 136 | AF5: 2720 | AG5: 45626 | AH5: 20305 | AI5: 192 | AJ5: 536.8 | AK5: 26.84 | AL5: 20
A6: 2805 | B6: IRRIGACAO ASPERCAO | C6: 20314 | D6: Fazenda Agua Mansa | E6: 138 | F6: 138 | G6: 34 | H6: 37.79 | I6: HA | J6: =IF(MAX(_xlfn.MAXIFS(T:T,S:S,C6,U:U,E6),_xlfn.MAXIFS(AG:AG,AH:AH,C6,AI:AI,E6))=0,"",MAX(_xlfn.MAXIFS(T:T,S:S,C6,U:U,E6),_xlfn.MAXIFS(AG:AG,AH:AH,C6,AI:AI,E6))) -> 45535 | K6: =COUNTIFS(TABELA!A:A,C6,TABELA!C:C,E6) -> 1 | L6: =SUMIFS(TABELA!M:M,TABELA!A:A,C6,TABELA!C:C,E6) -> 43.34 | M6: =IF(L6>0,H6-L6,0) -> -5.55 | N6: =SUMIFS(X:X,S:S,C6,U:U,E6)+SUMIFS(AK:AK,AH:AH,C6,AI:AI,E6) -> 37.79 | O6: =SUMIFS(W:W,S:S,C6)/SUMIFS(X:X,S:S,C6)/10 -> 33.402727 | R6: 2805 | S6: 20314 | U6: 137 | AF6: 2720 | AG6: 45596 | AH6: 20322 | AI6: 1 | AJ6: 142.74 | AK6: 5.49 | AL6: 26
A7: 2805 | B7: IRRIGACAO ASPERCAO | C7: 20314 | D7: Fazenda Agua Mansa | E7: 139 | F7: 139 | G7: 34 | H7: 32.33 | I7: HA | J7: =IF(MAX(_xlfn.MAXIFS(T:T,S:S,C7,U:U,E7),_xlfn.MAXIFS(AG:AG,AH:AH,C7,AI:AI,E7))=0,"",MAX(_xlfn.MAXIFS(T:T,S:S,C7,U:U,E7),_xlfn.MAXIFS(AG:AG,AH:AH,C7,AI:AI,E7))) -> 45535 | K7: =COUNTIFS(TABELA!A:A,C7,TABELA!C:C,E7) -> 1 | L7: =SUMIFS(TABELA!M:M,TABELA!A:A,C7,TABELA!C:C,E7) -> 39.66 | M7: =IF(L7>0,H7-L7,0) -> -7.33 | N7: =SUMIFS(X:X,S:S,C7,U:U,E7)+SUMIFS(AK:AK,AH:AH,C7,AI:AI,E7) -> 32.33 | O7: =SUMIFS(W:W,S:S,C7)/SUMIFS(X:X,S:S,C7)/10 -> 33.402727 | R7: 2805 | S7: 20314 | T7: 45535 | U7: 138 | V7: 12 | W7: 2400 | X7: 37.79 | Y7: 6.35 | AF7: 2720 | AG7: 45596 | AH7: 20322 | AI7: 2 | AJ7: 99.32 | AK7: 3.82 | AL7: 26
A8: 2805 | B8: IRRIGACAO ASPERCAO | C8: 20314 | D8: Fazenda Agua Mansa | E8: 388 | F8: 388 | G8: 34 | H8: 21.26 | I8: HA | J8: =IF(MAX(_xlfn.MAXIFS(T:T,S:S,C8,U:U,E8),_xlfn.MAXIFS(AG:AG,AH:AH,C8,AI:AI,E8))=0,"",MAX(_xlfn.MAXIFS(T:T,S:S,C8,U:U,E8),_xlfn.MAXIFS(AG:AG,AH:AH,C8,AI:AI,E8))) -> 45504 | K8: =COUNTIFS(TABELA!A:A,C8,TABELA!C:C,E8) -> 1 | L8: =SUMIFS(TABELA!M:M,TABELA!A:A,C8,TABELA!C:C,E8) -> 0 | M8: =IF(L8>0,H8-L8,0) -> 0 | N8: =SUMIFS(X:X,S:S,C8,U:U,E8)+SUMIFS(AK:AK,AH:AH,C8,AI:AI,E8) -> 21.26 | O8: =SUMIFS(W:W,S:S,C8)/SUMIFS(X:X,S:S,C8)/10 -> 33.402727 | R8: 2805 | S8: 20314 | U8: 138 | AF8: 2720 | AG8: 45596 | AH8: 20322 | AI8: 3 | AJ8: 96.72 | AK8: 3.72 | AL8: 26
A9: 2805 | B9: IRRIGACAO ASPERCAO | C9: 20314 | D9: Fazenda Agua Mansa | E9: 389 | F9: 389 | G9: 34 | H9: 29.82 | I9: HA | J9: =IF(MAX(_xlfn.MAXIFS(T:T,S:S,C9,U:U,E9),_xlfn.MAXIFS(AG:AG,AH:AH,C9,AI:AI,E9))=0,"",MAX(_xlfn.MAXIFS(T:T,S:S,C9,U:U,E9),_xlfn.MAXIFS(AG:AG,AH:AH,C9,AI:AI,E9))) -> 45504 | K9: =COUNTIFS(TABELA!A:A,C9,TABELA!C:C,E9) -> 1 | L9: =SUMIFS(TABELA!M:M,TABELA!A:A,C9,TABELA!C:C,E9) -> 0 | M9: =IF(L9>0,H9-L9,0) -> 0 | N9: =SUMIFS(X:X,S:S,C9,U:U,E9)+SUMIFS(AK:AK,AH:AH,C9,AI:AI,E9) -> 29.82 | O9: =SUMIFS(W:W,S:S,C9)/SUMIFS(X:X,S:S,C9)/10 -> 33.402727 | R9: 2805 | S9: 20314 | T9: 45535 | U9: 139 | V9: 45 | W9: 9000 | X9: 32.33 | Y9: 27.84 | AF9: 2720 | AG9: 45596 | AH9: 20322 | AI9: 4 | AJ9: 102.18 | AK9: 3.93 | AL9: 26
A10: 2805 | B10: IRRIGACAO ASPERCAO | C10: 20314 | D10: Fazenda Agua Mansa | E10: 392 | F10: 392 | G10: 34 | H10: 35.07 | I10: HA | J10: =IF(MAX(_xlfn.MAXIFS(T:T,S:S,C10,U:U,E10),_xlfn.MAXIFS(AG:AG,AH:AH,C10,AI:AI,E10))=0,"",MAX(_xlfn.MAXIFS(T:T,S:S,C10,U:U,E10),_xlfn.MAXIFS(AG:AG,AH:AH,C10,AI:AI,E10))) -> 45504 | K10: =COUNTIFS(TABELA!A:A,C10,TABELA!C:C,E10) -> 1 | L10: =SUMIFS(TABELA!M:M,TABELA!A:A,C10,TABELA!C:C,E10) -> 0 | M10: =IF(L10>0,H10-L10,0) -> 0 | N10: =SUMIFS(X:X,S:S,C10,U:U,E10)+SUMIFS(AK:AK,AH:AH,C10,AI:AI,E10) -> 35.07 | O10: =SUMIFS(W:W,S:S,C10)/SUMIFS(X:X,S:S,C10)/10 -> 33.402727 | R10: 2805 | S10: 20314 | U10: 139 | AF10: 2720 | AG10: 45596 | AH10: 20322 | AI10: 5 | AJ10: 114.66 | AK10: 4.41 | AL10: 26
A11: 2805 | B11: IRRIGACAO ASPERCAO | C11: 20314 | D11: Fazenda Agua Mansa | F11: =393 -> 393 | H11: 2.3 | I11: HA | J11: =IF(MAX(_xlfn.MAXIFS(T:T,S:S,C11,U:U,E11),_xlfn.MAXIFS(AG:AG,AH:AH,C11,AI:AI,E11))=0,"",MAX(_xlfn.MAXIFS(T:T,S:S,C11,U:U,E11),_xlfn.MAXIFS(AG:AG,AH:AH,C11,AI:AI,E11))) | K11: =COUNTIFS(TABELA!A:A,C11,TABELA!C:C,E11) -> 0 | L11: =SUMIFS(TABELA!M:M,TABELA!A:A,C11,TABELA!C:C,E11) -> 0 | M11: =IF(L11>0,H11-L11,0) -> 0 | N11: =SUMIFS(X:X,S:S,C11,U:U,E11)+SUMIFS(AK:AK,AH:AH,C11,AI:AI,E11) -> 0 | O11: =SUMIFS(W:W,S:S,C11)/SUMIFS(X:X,S:S,C11)/10 -> 33.402727 | R11: 2805 | S11: 20314 | U11: 385 | AF11: 2720 | AG11: 45596 | AH11: 20322 | AI11: 6 | AJ11: 90.48 | AK11: 3.48 | AL11: 26
A12: 2805 | B12: IRRIGACAO ASPERCAO | C12: 20314 | D12: Fazenda Agua Mansa | E12: 394 | F12: 394 | G12: 34 | H12: 19.93 | I12: HA | J12: =IF(MAX(_xlfn.MAXIFS(T:T,S:S,C12,U:U,E12),_xlfn.MAXIFS(AG:AG,AH:AH,C12,AI:AI,E12))=0,"",MAX(_xlfn.MAXIFS(T:T,S:S,C12,U:U,E12),_xlfn.MAXIFS(AG:AG,AH:AH,C12,AI:AI,E12))) -> 45504 | K12: =COUNTIFS(TABELA!A:A,C12,TABELA!C:C,E12) -> 1 | L12: =SUMIFS(TABELA!M:M,TABELA!A:A,C12,TABELA!C:C,E12) -> 0 | M12: =IF(L12>0,H12-L12,0) -> 0 | N12: =SUMIFS(X:X,S:S,C12,U:U,E12)+SUMIFS(AK:AK,AH:AH,C12,AI:AI,E12) -> 19.93 | O12: =SUMIFS(W:W,S:S,C12)/SUMIFS(X:X,S:S,C12)/10 -> 33.402727 | R12: 2805 | S12: 20314 | U12: 386 | AF12: 2720 | AG12: 45596 | AH12: 20322 | AI12: 7 | AJ12: 72.8 | AK12: 2.8 | AL12: 26
A13: 2805 | B13: IRRIGACAO ASPERCAO | C13: 20314 | D13: Fazenda Agua Mansa | F13: =395 -> 395 | H13: 7.1 | I13: HA | J13: =IF(MAX(_xlfn.MAXIFS(T:T,S:S,C13,U:U,E13),_xlfn.MAXIFS(AG:AG,AH:AH,C13,AI:AI,E13))=0,"",MAX(_xlfn.MAXIFS(T:T,S:S,C13,U:U,E13),_xlfn.MAXIFS(AG:AG,AH:AH,C13,AI:AI,E13))) | K13: =COUNTIFS(TABELA!A:A,C13,TABELA!C:C,E13) -> 0 | L13: =SUMIFS(TABELA!M:M,TABELA!A:A,C13,TABELA!C:C,E13) -> 0 | M13: =IF(L13>0,H13-L13,0) -> 0 | N13: =SUMIFS(X:X,S:S,C13,U:U,E13)+SUMIFS(AK:AK,AH:AH,C13,AI:AI,E13) -> 0 | O13: =SUMIFS(W:W,S:S,C13)/SUMIFS(X:X,S:S,C13)/10 -> 33.402727 | R13: 2805 | S13: 20314 | U13: 387 | AF13: 2720 | AG13: 45596 | AH13: 20322 | AI13: 8 | AJ13: 99.32 | AK13: 3.82 | AL13: 26
A14: 2805 | B14: IRRIGACAO ASPERCAO | C14: 20314 | D14: Fazenda Agua Mansa | F14: 396 | H14: 7.6 | I14: HA | J14: =IF(MAX(_xlfn.MAXIFS(T:T,S:S,C14,U:U,E14),_xlfn.MAXIFS(AG:AG,AH:AH,C14,AI:AI,E14))=0,"",MAX(_xlfn.MAXIFS(T:T,S:S,C14,U:U,E14),_xlfn.MAXIFS(AG:AG,AH:AH,C14,AI:AI,E14))) | K14: =COUNTIFS(TABELA!A:A,C14,TABELA!C:C,E14) -> 0 | L14: =SUMIFS(TABELA!M:M,TABELA!A:A,C14,TABELA!C:C,E14) -> 0 | M14: =IF(L14>0,H14-L14,0) -> 0 | N14: =SUMIFS(X:X,S:S,C14,U:U,E14)+SUMIFS(AK:AK,AH:AH,C14,AI:AI,E14) -> 0 | O14: =SUMIFS(W:W,S:S,C14)/SUMIFS(X:X,S:S,C14)/10 -> 33.402727 | R14: 2805 | S14: 20314 | T14: 45443 | U14: 388 | V14: 115 | W14: 23000 | X14: 6.9 | Y14: 333.33 | AF14: 2720 | AG14: 45626 | AH14: 20323 | AI14: 1 | AJ14: 50.2 | AK14: 2.51 | AL14: 20
A15: 2805 | B15: IRRIGACAO ASPERCAO | C15: 20314 | D15: Fazenda Agua Mansa | F15: 397 | H15: 7 | I15: HA | J15: =IF(MAX(_xlfn.MAXIFS(T:T,S:S,C15,U:U,E15),_xlfn.MAXIFS(AG:AG,AH:AH,C15,AI:AI,E15))=0,"",MAX(_xlfn.MAXIFS(T:T,S:S,C15,U:U,E15),_xlfn.MAXIFS(AG:AG,AH:AH,C15,AI:AI,E15))) | K15: =COUNTIFS(TABELA!A:A,C15,TABELA!C:C,E15) -> 0 | L15: =SUMIFS(TABELA!M:M,TABELA!A:A,C15,TABELA!C:C,E15) -> 0 | M15: =IF(L15>0,H15-L15,0) -> 0 | N15: =SUMIFS(X:X,S:S,C15,U:U,E15)+SUMIFS(AK:AK,AH:AH,C15,AI:AI,E15) -> 0 | O15: =SUMIFS(W:W,S:S,C15)/SUMIFS(X:X,S:S,C15)/10 -> 33.402727 | R15: 2805 | S15: 20314 | T15: 45504 | U15: 388 | X15: 14.36 | AF15: 2720 | AG15: 45626 | AH15: 20323 | AI15: 2 | AJ15: 251.6 | AK15: 12.58 | AL15: 20
A16: 2805 | B16: IRRIGACAO ASPERCAO | C16: 20314 | D16: Fazenda Agua Mansa | E16: 501 | F16: 501 | G16: 34 | H16: 26 | I16: HA | J16: =IF(MAX(_xlfn.MAXIFS(T:T,S:S,C16,U:U,E16),_xlfn.MAXIFS(AG:AG,AH:AH,C16,AI:AI,E16))=0,"",MAX(_xlfn.MAXIFS(T:T,S:S,C16,U:U,E16),_xlfn.MAXIFS(AG:AG,AH:AH,C16,AI:AI,E16))) -> 45565 | K16: =COUNTIFS(TABELA!A:A,C16,TABELA!C:C,E16) -> 1 | L16: =SUMIFS(TABELA!M:M,TABELA!A:A,C16,TABELA!C:C,E16) -> 0 | M16: =IF(L16>0,H16-L16,0) -> 0 | N16: =SUMIFS(X:X,S:S,C16,U:U,E16)+SUMIFS(AK:AK,AH:AH,C16,AI:AI,E16) -> 26 | O16: =SUMIFS(W:W,S:S,C16)/SUMIFS(X:X,S:S,C16)/10 -> 33.402727 | R16: 2805 | S16: 20314 | U16: 388 | AF16: 2720 | AG16: 45626 | AH16: 20323 | AI16: 3 | AJ16: 498.2 | AK16: 24.91 | AL16: 20
A17: 2805 | B17: IRRIGACAO ASPERCAO | C17: 20314 | D17: Fazenda Agua Mansa | E17: 502 | F17: 502 | G17: 34 | H17: 23.84 | I17: HA | J17: =IF(MAX(_xlfn.MAXIFS(T:T,S:S,C17,U:U,E17),_xlfn.MAXIFS(AG:AG,AH:AH,C17,AI:AI,E17))=0,"",MAX(_xlfn.MAXIFS(T:T,S:S,C17,U:U,E17),_xlfn.MAXIFS(AG:AG,AH:AH,C17,AI:AI,E17))) -> 45535 | K17: =COUNTIFS(TABELA!A:A,C17,TABELA!C:C,E17) -> 1 | L17: =SUMIFS(TABELA!M:M,TABELA!A:A,C17,TABELA!C:C,E17) -> 0 | M17: =IF(L17>0,H17-L17,0) -> 0 | N17: =SUMIFS(X:X,S:S,C17,U:U,E17)+SUMIFS(AK:AK,AH:AH,C17,AI:AI,E17) -> 23.84 | O17: =SUMIFS(W:W,S:S,C17)/SUMIFS(X:X,S:S,C17)/10 -> 33.402727 | R17: 2805 | S17: 20314 | T17: 45443 | U17: 389 | X17: 6.9 | AF17: 2720 | AG17: 45626 | AH17: 20323 | AI17: 4 | AJ17: 366 | AK17: 18.3 | AL17: 20
A18: 2805 | B18: IRRIGACAO ASPERCAO | C18: 20314 | D18: Fazenda Agua Mansa | E18: 503 | F18: 503 | G18: 34 | H18: 28.93 | I18: HA | J18: =IF(MAX(_xlfn.MAXIFS(T:T,S:S,C18,U:U,E18),_xlfn.MAXIFS(AG:AG,AH:AH,C18,AI:AI,E18))=0,"",MAX(_xlfn.MAXIFS(T:T,S:S,C18,U:U,E18),_xlfn.MAXIFS(AG:AG,AH:AH,C18,AI:AI,E18))) -> 45535 | K18: =COUNTIFS(TABELA!A:A,C18,TABELA!C:C,E18) -> 1 | L18: =SUMIFS(TABELA!M:M,TABELA!A:A,C18,TABELA!C:C,E18) -> 0 | M18: =IF(L18>0,H18-L18,0) -> 0 | N18: =SUMIFS(X:X,S:S,C18,U:U,E18)+SUMIFS(AK:AK,AH:AH,C18,AI:AI,E18) -> 28.93 | O18: =SUMIFS(W:W,S:S,C18)/SUMIFS(X:X,S:S,C18)/10 -> 33.402727 | R18: 2805 | S18: 20314 | T18: 45504 | U18: 389 | X18: 22.92 | AF18: 2720 | AG18: 45626 | AH18: 20323 | AI18: 5 | AJ18: 137.4 | AK18: 6.87 | AL18: 20
A19: 2805 | B19: IRRIGACAO ASPERCAO | C19: 20314 | D19: Fazenda Agua Mansa | E19: 507 | F19: 507 | G19: 34 | H19: 29.75 | I19: HA | J19: =IF(MAX(_xlfn.MAXIFS(T:T,S:S,C19,U:U,E19),_xlfn.MAXIFS(AG:AG,AH:AH,C19,AI:AI,E19))=0,"",MAX(_xlfn.MAXIFS(T:T,S:S,C19,U:U,E19),_xlfn.MAXIFS(AG:AG,AH:AH,C19,AI:AI,E19))) -> 45535 | K19: =COUNTIFS(TABELA!A:A,C19,TABELA!C:C,E19) -> 1 | L19: =SUMIFS(TABELA!M:M,TABELA!A:A,C19,TABELA!C:C,E19) -> 0 | M19: =IF(L19>0,H19-L19,0) -> 0 | N19: =SUMIFS(X:X,S:S,C19,U:U,E19)+SUMIFS(AK:AK,AH:AH,C19,AI:AI,E19) -> 29.75 | O19: =SUMIFS(W:W,S:S,C19)/SUMIFS(X:X,S:S,C19)/10 -> 33.402727 | R19: 2805 | S19: 20314 | U19: 389 | AF19: 2720 | AG19: 45626 | AH19: 20323 | AI19: 6 | AJ19: 226.2 | AK19: 11.31 | AL19: 20
A20: 2805 | B20: IRRIGACAO ASPERCAO | C20: 20314 | D20: Fazenda Agua Mansa | E20: 508 | F20: 508 | G20: 34 | H20: 18.28 | I20: HA | J20: =IF(MAX(_xlfn.MAXIFS(T:T,S:S,C20,U:U,E20),_xlfn.MAXIFS(AG:AG,AH:AH,C20,AI:AI,E20))=0,"",MAX(_xlfn.MAXIFS(T:T,S:S,C20,U:U,E20),_xlfn.MAXIFS(AG:AG,AH:AH,C20,AI:AI,E20))) -> 45565 | K20: =COUNTIFS(TABELA!A:A,C20,TABELA!C:C,E20) -> 1 | L20: =SUMIFS(TABELA!M:M,TABELA!A:A,C20,TABELA!C:C,E20) -> 0 | M20: =IF(L20>0,H20-L20,0) -> 0 | N20: =SUMIFS(X:X,S:S,C20,U:U,E20)+SUMIFS(AK:AK,AH:AH,C20,AI:AI,E20) -> 18.28 | O20: =SUMIFS(W:W,S:S,C20)/SUMIFS(X:X,S:S,C20)/10 -> 33.402727 | R20: 2805 | S20: 20314 | U20: 391 | AF20: 2720 | AG20: 45626 | AH20: 20325 | AI20: 1 | AJ20: 718.4 | AK20: 35.92 | AL20: 20
A21: 2805 | B21: IRRIGACAO ASPERCAO | C21: 20315 | D21: Fazenda Taquarussu | F21: 7 | H21: 57.84 | I21: HA | J21: =IF(MAX(_xlfn.MAXIFS(T:T,S:S,C21,U:U,E21),_xlfn.MAXIFS(AG:AG,AH:AH,C21,AI:AI,E21))=0,"",MAX(_xlfn.MAXIFS(T:T,S:S,C21,U:U,E21),_xlfn.MAXIFS(AG:AG,AH:AH,C21,AI:AI,E21))) | K21: =COUNTIFS(TABELA!A:A,C21,TABELA!C:C,E21) -> 0 | L21: =SUMIFS(TABELA!M:M,TABELA!A:A,C21,TABELA!C:C,E21) -> 0 | M21: =IF(L21>0,H21-L21,0) -> 0 | N21: =SUMIFS(X:X,S:S,C21,U:U,E21)+SUMIFS(AK:AK,AH:AH,C21,AI:AI,E21) -> 0 | O21: =SUMIFS(W:W,S:S,C21)/SUMIFS(X:X,S:S,C21)/10 -> #DIV/0! | R21: 2805 | S21: 20314 | T21: 45443 | U21: 392 | X21: 25.07 | AF21: 2720 | AG21: 45626 | AH21: 20325 | AI21: 2 | AJ21: 615.2 | AK21: 30.76 | AL21: 20
A22: 2805 | B22: IRRIGACAO ASPERCAO | C22: 20315 | D22: Fazenda Taquarussu | F22: 8 | H22: 35.27 | I22: HA | J22: =IF(MAX(_xlfn.MAXIFS(T:T,S:S,C22,U:U,E22),_xlfn.MAXIFS(AG:AG,AH:AH,C22,AI:AI,E22))=0,"",MAX(_xlfn.MAXIFS(T:T,S:S,C22,U:U,E22),_xlfn.MAXIFS(AG:AG,AH:AH,C22,AI:AI,E22))) | K22: =COUNTIFS(TABELA!A:A,C22,TABELA!C:C,E22) -> 0 | L22: =SUMIFS(TABELA!M:M,TABELA!A:A,C22,TABELA!C:C,E22) -> 0 | M22: =IF(L22>0,H22-L22,0) -> 0 | N22: =SUMIFS(X:X,S:S,C22,U:U,E22)+SUMIFS(AK:AK,AH:AH,C22,AI:AI,E22) -> 0 | O22: =SUMIFS(W:W,S:S,C22)/SUMIFS(X:X,S:S,C22)/10 -> #DIV/0! | R22: 2805 | S22: 20314 | T22: 45504 | U22: 392 | X22: 10 | AF22: 2720 | AG22: 45626 | AH22: 20325 | AI22: 3 | AJ22: 462.2 | AK22: 23.11 | AL22: 20
A23: 2805 | B23: IRRIGACAO ASPERCAO | C23: 20431 | D23: Fazenda Estância Fernanda | E23: 3 | F23: 3 | G23: 20 | H23: 10.08 | I23: HA | J23: =IF(MAX(_xlfn.MAXIFS(T:T,S:S,C23,U:U,E23),_xlfn.MAXIFS(AG:AG,AH:AH,C23,AI:AI,E23))=0,"",MAX(_xlfn.MAXIFS(T:T,S:S,C23,U:U,E23),_xlfn.MAXIFS(AG:AG,AH:AH,C23,AI:AI,E23))) -> 45443 | K23: =COUNTIFS(TABELA!A:A,C23,TABELA!C:C,E23) -> 1 | L23: =SUMIFS(TABELA!M:M,TABELA!A:A,C23,TABELA!C:C,E23) -> 0 | M23: =IF(L23>0,H23-L23,0) -> 0 | N23: =SUMIFS(X:X,S:S,C23,U:U,E23)+SUMIFS(AK:AK,AH:AH,C23,AI:AI,E23) -> 10.08 | O23: =SUMIFS(W:W,S:S,C23)/SUMIFS(X:X,S:S,C23)/10 -> 20.833333 | R23: 2805 | S23: 20314 | U23: 392 | AF23: 2720 | AG23: 45626 | AH23: 20325 | AI23: 4 | AJ23: 104.4 | AK23: 5.22 | AL23: 20
A24: 2805 | B24: IRRIGACAO ASPERCAO | C24: 20431 | D24: Fazenda Estância Fernanda | E24: 4 | F24: 4 | G24: 20 | H24: 10.08 | I24: HA | J24: =IF(MAX(_xlfn.MAXIFS(T:T,S:S,C24,U:U,E24),_xlfn.MAXIFS(AG:AG,AH:AH,C24,AI:AI,E24))=0,"",MAX(_xlfn.MAXIFS(T:T,S:S,C24,U:U,E24),_xlfn.MAXIFS(AG:AG,AH:AH,C24,AI:AI,E24))) -> 45443 | K24: =COUNTIFS(TABELA!A:A,C24,TABELA!C:C,E24) -> 1 | L24: =SUMIFS(TABELA!M:M,TABELA!A:A,C24,TABELA!C:C,E24) -> 0 | M24: =IF(L24>0,H24-L24,0) -> 0 | N24: =SUMIFS(X:X,S:S,C24,U:U,E24)+SUMIFS(AK:AK,AH:AH,C24,AI:AI,E24) -> 10.08 | O24: =SUMIFS(W:W,S:S,C24)/SUMIFS(X:X,S:S,C24)/10 -> 20.833333 | R24: 2805 | S24: 20314 | T24: 45443 | U24: 393 | X24: 2.3 | AF24: 2720 | AG24: 45626 | AH24: 20325 | AI24: 5 | AJ24: 989.4 | AK24: 49.47 | AL24: 20
A25: 2805 | B25: IRRIGACAO ASPERCAO | C25: 20431 | D25: Fazenda Estância Fernanda | E25: 15 | F25: 15 | G25: 20 | H25: 10.08 | I25: HA | J25: =IF(MAX(_xlfn.MAXIFS(T:T,S:S,C25,U:U,E25),_xlfn.MAXIFS(AG:AG,AH:AH,C25,AI:AI,E25))=0,"",MAX(_xlfn.MAXIFS(T:T,S:S,C25,U:U,E25),_xlfn.MAXIFS(AG:AG,AH:AH,C25,AI:AI,E25))) -> 45443 | K25: =COUNTIFS(TABELA!A:A,C25,TABELA!C:C,E25) -> 1 | L25: =SUMIFS(TABELA!M:M,TABELA!A:A,C25,TABELA!C:C,E25) -> 0 | M25: =IF(L25>0,H25-L25,0) -> 0 | N25: =SUMIFS(X:X,S:S,C25,U:U,E25)+SUMIFS(AK:AK,AH:AH,C25,AI:AI,E25) -> 10.08 | O25: =SUMIFS(W:W,S:S,C25)/SUMIFS(X:X,S:S,C25)/10 -> 20.833333 | R25: 2805 | S25: 20314 | U25: 393 | AF25: 2720 | AG25: 45596 | AH25: 20340 | AI25: 1 | AJ25: 640.12 | AK25: 24.62 | AL25: 26
A26: 2805 | B26: IRRIGACAO ASPERCAO | C26: 20431 | D26: Fazenda Estância Fernanda | E26: 16 | F26: 16 | G26: 20 | H26: 10.08 | I26: HA | J26: =IF(MAX(_xlfn.MAXIFS(T:T,S:S,C26,U:U,E26),_xlfn.MAXIFS(AG:AG,AH:AH,C26,AI:AI,E26))=0,"",MAX(_xlfn.MAXIFS(T:T,S:S,C26,U:U,E26),_xlfn.MAXIFS(AG:AG,AH:AH,C26,AI:AI,E26))) -> 45443 | K26: =COUNTIFS(TABELA!A:A,C26,TABELA!C:C,E26) -> 1 | L26: =SUMIFS(TABELA!M:M,TABELA!A:A,C26,TABELA!C:C,E26) -> 0 | M26: =IF(L26>0,H26-L26,0) -> 0 | N26: =SUMIFS(X:X,S:S,C26,U:U,E26)+SUMIFS(AK:AK,AH:AH,C26,AI:AI,E26) -> 10.08 | O26: =SUMIFS(W:W,S:S,C26)/SUMIFS(X:X,S:S,C26)/10 -> 20.833333 | R26: 2805 | S26: 20314 | T26: 45443 | U26: 394 | X26: 12.32 | AF26: 2720 | AG26: 45596 | AH26: 20340 | AI26: 2 | AJ26: 264.42 | AK26: 10.17 | AL26: 26
A27: 2805 | B27: IRRIGACAO ASPERCAO | C27: 20432 | D27: Fazenda Vista Bonita | E27: 190 | F27: 190 | G27: 28 | H27: 5.11 | I27: HA | J27: =IF(MAX(_xlfn.MAXIFS(T:T,S:S,C27,U:U,E27),_xlfn.MAXIFS(AG:AG,AH:AH,C27,AI:AI,E27))=0,"",MAX(_xlfn.MAXIFS(T:T,S:S,C27,U:U,E27),_xlfn.MAXIFS(AG:AG,AH:AH,C27,AI:AI,E27))) -> 45504 | K27: =COUNTIFS(TABELA!A:A,C27,TABELA!C:C,E27) -> 1 | L27: =SUMIFS(TABELA!M:M,TABELA!A:A,C27,TABELA!C:C,E27) -> 0 | M27: =IF(L27>0,H27-L27,0) -> 0 | N27: =SUMIFS(X:X,S:S,C27,U:U,E27)+SUMIFS(AK:AK,AH:AH,C27,AI:AI,E27) -> 5.11 | O27: =SUMIFS(W:W,S:S,C27)/SUMIFS(X:X,S:S,C27)/10 -> 28.158577 | R27: 2805 | S27: 20314 | T27: 45504 | U27: 394 | X27: 7.61 | AF27: 2720 | AG27: 45596 | AH27: 20340 | AI27: 3 | AJ27: 175.76 | AK27: 6.76 | AL27: 26
A28: 2805 | B28: IRRIGACAO ASPERCAO | C28: 20432 | D28: Fazenda Vista Bonita | E28: 191 | F28: 191 | G28: 28 | H28: 8.21 | I28: HA | J28: =IF(MAX(_xlfn.MAXIFS(T:T,S:S,C28,U:U,E28),_xlfn.MAXIFS(AG:AG,AH:AH,C28,AI:AI,E28))=0,"",MAX(_xlfn.MAXIFS(T:T,S:S,C28,U:U,E28),_xlfn.MAXIFS(AG:AG,AH:AH,C28,AI:AI,E28))) -> 45504 | K28: =COUNTIFS(TABELA!A:A,C28,TABELA!C:C,E28) -> 1 | L28: =SUMIFS(TABELA!M:M,TABELA!A:A,C28,TABELA!C:C,E28) -> 0 | M28: =IF(L28>0,H28-L28,0) -> 0 | N28: =SUMIFS(X:X,S:S,C28,U:U,E28)+SUMIFS(AK:AK,AH:AH,C28,AI:AI,E28) -> 8.21 | O28: =SUMIFS(W:W,S:S,C28)/SUMIFS(X:X,S:S,C28)/10 -> 28.158577 | R28: 2805 | S28: 20314 | U28: 394 | AF28: 2720 | AG28: 45596 | AH28: 20345 | AI28: 1 | AJ28: 638.82 | AK28: 24.57 | AL28: 26
A29: 2805 | B29: IRRIGACAO ASPERCAO | C29: 20432 | D29: Fazenda Vista Bonita | E29: 194 | F29: 194 | G29: 28 | H29: 13.67 | I29: HA | J29: =IF(MAX(_xlfn.MAXIFS(T:T,S:S,C29,U:U,E29),_xlfn.MAXIFS(AG:AG,AH:AH,C29,AI:AI,E29))=0,"",MAX(_xlfn.MAXIFS(T:T,S:S,C29,U:U,E29),_xlfn.MAXIFS(AG:AG,AH:AH,C29,AI:AI,E29))) -> 45504 | K29: =COUNTIFS(TABELA!A:A,C29,TABELA!C:C,E29) -> 1 | L29: =SUMIFS(TABELA!M:M,TABELA!A:A,C29,TABELA!C:C,E29) -> 0 | M29: =IF(L29>0,H29-L29,0) -> 0 | N29: =SUMIFS(X:X,S:S,C29,U:U,E29)+SUMIFS(AK:AK,AH:AH,C29,AI:AI,E29) -> 13.67 | O29: =SUMIFS(W:W,S:S,C29)/SUMIFS(X:X,S:S,C29)/10 -> 28.158577 | R29: 2805 | S29: 20314 | T29: 45443 | U29: 395 | X29: 7.1 | AF29: 2720 | AG29: 45596 | AH29: 20345 | AI29: 2 | AJ29: 605.8 | AK29: 23.3 | AL29: 26
A30: 2805 | B30: IRRIGACAO ASPERCAO | C30: 20439 | D30: Fazenda Ipezal | E30: 3 | F30: 3 | G30: 60 | H30: 43.01 | I30: HA | J30: =IF(MAX(_xlfn.MAXIFS(T:T,S:S,C30,U:U,E30),_xlfn.MAXIFS(AG:AG,AH:AH,C30,AI:AI,E30))=0,"",MAX(_xlfn.MAXIFS(T:T,S:S,C30,U:U,E30),_xlfn.MAXIFS(AG:AG,AH:AH,C30,AI:AI,E30))) -> 45565 | K30: =COUNTIFS(TABELA!A:A,C30,TABELA!C:C,E30) -> 1 | L30: =SUMIFS(TABELA!M:M,TABELA!A:A,C30,TABELA!C:C,E30) -> 43.01 | M30: =IF(L30>0,H30-L30,0) -> 0 | N30: =SUMIFS(X:X,S:S,C30,U:U,E30)+SUMIFS(AK:AK,AH:AH,C30,AI:AI,E30) -> 43.01 | O30: =SUMIFS(W:W,S:S,C30)/SUMIFS(X:X,S:S,C30)/10 -> 59.521522 | R30: 2805 | S30: 20314 | U30: 395 | AF30: 2720 | AG30: 45596 | AH30: 20345 | AI30: 3 | AJ30: 654.42 | AK30: 25.17 | AL30: 26
A31: 2805 | B31: IRRIGACAO ASPERCAO | C31: 20439 | D31: Fazenda Ipezal | E31: 5 | F31: 5 | G31: 60 | H31: 37.72 | I31: HA | J31: =IF(MAX(_xlfn.MAXIFS(T:T,S:S,C31,U:U,E31),_xlfn.MAXIFS(AG:AG,AH:AH,C31,AI:AI,E31))=0,"",MAX(_xlfn.MAXIFS(T:T,S:S,C31,U:U,E31),_xlfn.MAXIFS(AG:AG,AH:AH,C31,AI:AI,E31))) -> 45565 | K31: =COUNTIFS(TABELA!A:A,C31,TABELA!C:C,E31) -> 1 | L31: =SUMIFS(TABELA!M:M,TABELA!A:A,C31,TABELA!C:C,E31) -> 37.72 | M31: =IF(L31>0,H31-L31,0) -> 0 | N31: =SUMIFS(X:X,S:S,C31,U:U,E31)+SUMIFS(AK:AK,AH:AH,C31,AI:AI,E31) -> 37.72 | O31: =SUMIFS(W:W,S:S,C31)/SUMIFS(X:X,S:S,C31)/10 -> 59.521522 | R31: 2805 | S31: 20314 | T31: 45443 | U31: 396 | X31: 7.6 | AF31: 2720 | AG31: 45596 | AH31: 20345 | AI31: 4 | AJ31: 551.46 | AK31: 21.21 | AL31: 26
A32: 2805 | B32: IRRIGACAO ASPERCAO | C32: 20439 | D32: Fazenda Ipezal | E32: 7 | F32: 7 | G32: 60 | H32: 23.35 | I32: HA | J32: =IF(MAX(_xlfn.MAXIFS(T:T,S:S,C32,U:U,E32),_xlfn.MAXIFS(AG:AG,AH:AH,C32,AI:AI,E32))=0,"",MAX(_xlfn.MAXIFS(T:T,S:S,C32,U:U,E32),_xlfn.MAXIFS(AG:AG,AH:AH,C32,AI:AI,E32))) -> 45626 | K32: =COUNTIFS(TABELA!A:A,C32,TABELA!C:C,E32) -> 1 | L32: =SUMIFS(TABELA!M:M,TABELA!A:A,C32,TABELA!C:C,E32) -> 23.35 | M32: =IF(L32>0,H32-L32,0) -> 0 | N32: =SUMIFS(X:X,S:S,C32,U:U,E32)+SUMIFS(AK:AK,AH:AH,C32,AI:AI,E32) -> 46.7 | O32: =SUMIFS(W:W,S:S,C32)/SUMIFS(X:X,S:S,C32)/10 -> 59.521522 | R32: 2805 | S32: 20314 | U32: 396 | AF32: 2720 | AG32: 45596 | AH32: 20345 | AI32: 5 | AJ32: 331.76 | AK32: 12.76 | AL32: 26
A33: 2805 | B33: IRRIGACAO ASPERCAO | C33: 20450 | D33: Fazenda Ouro Branco | E33: 2 | F33: 2 | G33: 60 | H33: 11.92 | I33: HA | J33: =IF(MAX(_xlfn.MAXIFS(T:T,S:S,C33,U:U,E33),_xlfn.MAXIFS(AG:AG,AH:AH,C33,AI:AI,E33))=0,"",MAX(_xlfn.MAXIFS(T:T,S:S,C33,U:U,E33),_xlfn.MAXIFS(AG:AG,AH:AH,C33,AI:AI,E33))) -> 45565 | K33: =COUNTIFS(TABELA!A:A,C33,TABELA!C:C,E33) -> 1 | L33: =SUMIFS(TABELA!M:M,TABELA!A:A,C33,TABELA!C:C,E33) -> 0.92 | M33: =IF(L33>0,H33-L33,0) -> 11 | N33: =SUMIFS(X:X,S:S,C33,U:U,E33)+SUMIFS(AK:AK,AH:AH,C33,AI:AI,E33) -> 11.92 | O33: =SUMIFS(W:W,S:S,C33)/SUMIFS(X:X,S:S,C33)/10 -> 157.61543 | R33: 2805 | S33: 20314 | T33: 45443 | U33: 397 | X33: 7 | AF33: 2720 | AG33: 45596 | AH33: 20346 | AI33: 1 | AJ33: 330.46 | AK33: 12.71 | AL33: 26
A34: 2805 | B34: IRRIGACAO ASPERCAO | C34: 20450 | D34: Fazenda Ouro Branco | E34: 3 | F34: 3 | G34: 60 | H34: 14.76 | I34: HA | J34: =IF(MAX(_xlfn.MAXIFS(T:T,S:S,C34,U:U,E34),_xlfn.MAXIFS(AG:AG,AH:AH,C34,AI:AI,E34))=0,"",MAX(_xlfn.MAXIFS(T:T,S:S,C34,U:U,E34),_xlfn.MAXIFS(AG:AG,AH:AH,C34,AI:AI,E34))) -> 45565 | K34: =COUNTIFS(TABELA!A:A,C34,TABELA!C:C,E34) -> 1 | L34: =SUMIFS(TABELA!M:M,TABELA!A:A,C34,TABELA!C:C,E34) -> 4.64 | M34: =IF(L34>0,H34-L34,0) -> 10.12 | N34: =SUMIFS(X:X,S:S,C34,U:U,E34)+SUMIFS(AK:AK,AH:AH,C34,AI:AI,E34) -> 14.76 | O34: =SUMIFS(W:W,S:S,C34)/SUMIFS(X:X,S:S,C34)/10 -> 157.61543 | R34: 2805 | S34: 20314 | U34: 397 | AF34: 2720 | AG34: 45596 | AH34: 20346 | AI34: 2 | AJ34: 289.9 | AK34: 11.15 | AL34: 26
A35: 2805 | B35: IRRIGACAO ASPERCAO | C35: 20450 | D35: Fazenda Ouro Branco | E35: 4 | F35: 4 | G35: 60 | H35: 11.37 | I35: HA | J35: =IF(MAX(_xlfn.MAXIFS(T:T,S:S,C35,U:U,E35),_xlfn.MAXIFS(AG:AG,AH:AH,C35,AI:AI,E35))=0,"",MAX(_xlfn.MAXIFS(T:T,S:S,C35,U:U,E35),_xlfn.MAXIFS(AG:AG,AH:AH,C35,AI:AI,E35))) -> 45565 | K35: =COUNTIFS(TABELA!A:A,C35,TABELA!C:C,E35) -> 1 | L35: =SUMIFS(TABELA!M:M,TABELA!A:A,C35,TABELA!C:C,E35) -> 7.87 | M35: =IF(L35>0,H35-L35,0) -> 3.5 | N35: =SUMIFS(X:X,S:S,C35,U:U,E35)+SUMIFS(AK:AK,AH:AH,C35,AI:AI,E35) -> 11.37 | O35: =SUMIFS(W:W,S:S,C35)/SUMIFS(X:X,S:S,C35)/10 -> 157.61543 | R35: 2805 | S35: 20314 | U35: 500 | AF35: 2720 | AG35: 45596 | AH35: 20346 | AI35: 3 | AJ35: 359.84 | AK35: 13.84 | AL35: 26
A36: 2805 | B36: IRRIGACAO ASPERCAO | C36: 20450 | D36: Fazenda Ouro Branco | E36: 5 | F36: 5 | G36: 60 | H36: 13.88 | I36: HA | J36: =IF(MAX(_xlfn.MAXIFS(T:T,S:S,C36,U:U,E36),_xlfn.MAXIFS(AG:AG,AH:AH,C36,AI:AI,E36))=0,"",MAX(_xlfn.MAXIFS(T:T,S:S,C36,U:U,E36),_xlfn.MAXIFS(AG:AG,AH:AH,C36,AI:AI,E36))) -> 45565 | K36: =COUNTIFS(TABELA!A:A,C36,TABELA!C:C,E36) -> 1 | L36: =SUMIFS(TABELA!M:M,TABELA!A:A,C36,TABELA!C:C,E36) -> 13.88 | M36: =IF(L36>0,H36-L36,0) -> 0 | N36: =SUMIFS(X:X,S:S,C36,U:U,E36)+SUMIFS(AK:AK,AH:AH,C36,AI:AI,E36) -> 13.88 | O36: =SUMIFS(W:W,S:S,C36)/SUMIFS(X:X,S:S,C36)/10 -> 157.61543 | R36: 2805 | S36: 20314 | T36: 45535 | U36: 501 | X36: 26 | AF36: 2720 | AG36: 45626 | AH36: 20439 | AI36: 7 | AJ36: 467 | AK36: 23.35 | AL36: 20
A37: 2805 | B37: IRRIGACAO ASPERCAO | C37: 20450 | D37: Fazenda Ouro Branco | E37: 6 | F37: 6 | G37: 60 | H37: 33.62 | I37: HA | J37: =IF(MAX(_xlfn.MAXIFS(T:T,S:S,C37,U:U,E37),_xlfn.MAXIFS(AG:AG,AH:AH,C37,AI:AI,E37))=0,"",MAX(_xlfn.MAXIFS(T:T,S:S,C37,U:U,E37),_xlfn.MAXIFS(AG:AG,AH:AH,C37,AI:AI,E37))) -> 45565 | K37: =COUNTIFS(TABELA!A:A,C37,TABELA!C:C,E37) -> 1 | L37: =SUMIFS(TABELA!M:M,TABELA!A:A,C37,TABELA!C:C,E37) -> 31.62 | M37: =IF(L37>0,H37-L37,0) -> 2 | N37: =SUMIFS(X:X,S:S,C37,U:U,E37)+SUMIFS(AK:AK,AH:AH,C37,AI:AI,E37) -> 33.62 | O37: =SUMIFS(W:W,S:S,C37)/SUMIFS(X:X,S:S,C37)/10 -> 157.61543 | R37: 2805 | S37: 20314 | T37: 45565 | U37: 501 | V37: 9 | W37: 3600 | AF37: 2720 | AG37: 45626 | AH37: 20465 | AI37: 1 | AJ37: 475.8 | AK37: 23.79 | AL37: 20
A38: 2805 | B38: IRRIGACAO ASPERCAO | C38: 20463 | D38: Fazenda Ouro Branco I | E38: 3 | F38: 3 | G38: 60 | H38: 39.58 | I38: HA | J38: =IF(MAX(_xlfn.MAXIFS(T:T,S:S,C38,U:U,E38),_xlfn.MAXIFS(AG:AG,AH:AH,C38,AI:AI,E38))=0,"",MAX(_xlfn.MAXIFS(T:T,S:S,C38,U:U,E38),_xlfn.MAXIFS(AG:AG,AH:AH,C38,AI:AI,E38))) -> 45565 | K38: =COUNTIFS(TABELA!A:A,C38,TABELA!C:C,E38) -> 1 | L38: =SUMIFS(TABELA!M:M,TABELA!A:A,C38,TABELA!C:C,E38) -> 39.58 | M38: =IF(L38>0,H38-L38,0) -> 0 | N38: =SUMIFS(X:X,S:S,C38,U:U,E38)+SUMIFS(AK:AK,AH:AH,C38,AI:AI,E38) -> 39.58 | O38: =SUMIFS(W:W,S:S,C38)/SUMIFS(X:X,S:S,C38)/10 -> 93.048359 | R38: 2805 | S38: 20314 | U38: 501 | AF38: 2720 | AG38: 45626 | AH38: 20465 | AI38: 2 | AJ38: 140.4 | AK38: 7.02 | AL38: 20
A39: 2805 | B39: IRRIGACAO ASPERCAO | C39: 20463 | D39: Fazenda Ouro Branco I | E39: 4 | F39: 4 | G39: 60 | H39: 29.9 | I39: HA | J39: =IF(MAX(_xlfn.MAXIFS(T:T,S:S,C39,U:U,E39),_xlfn.MAXIFS(AG:AG,AH:AH,C39,AI:AI,E39))=0,"",MAX(_xlfn.MAXIFS(T:T,S:S,C39,U:U,E39),_xlfn.MAXIFS(AG:AG,AH:AH,C39,AI:AI,E39))) -> 45565 | K39: =COUNTIFS(TABELA!A:A,C39,TABELA!C:C,E39) -> 1 | L39: =SUMIFS(TABELA!M:M,TABELA!A:A,C39,TABELA!C:C,E39) -> 29.9 | M39: =IF(L39>0,H39-L39,0) -> 0 | N39: =SUMIFS(X:X,S:S,C39,U:U,E39)+SUMIFS(AK:AK,AH:AH,C39,AI:AI,E39) -> 29.9 | O39: =SUMIFS(W:W,S:S,C39)/SUMIFS(X:X,S:S,C39)/10 -> 93.048359 | R39: 2805 | S39: 20314 | T39: 45535 | U39: 502 | X39: 23.84 | AF39: 2720 | AG39: 45626 | AH39: 20465 | AI39: 3 | AJ39: 801 | AK39: 40.05 | AL39: 20
A40: 2805 | B40: IRRIGACAO ASPERCAO | C40: 20592 | D40: Fazenda Morada do Sol | E40: 3 | F40: 3 | G40: 16 | H40: 12.39 | I40: HA | J40: =IF(MAX(_xlfn.MAXIFS(T:T,S:S,C40,U:U,E40),_xlfn.MAXIFS(AG:AG,AH:AH,C40,AI:AI,E40))=0,"",MAX(_xlfn.MAXIFS(T:T,S:S,C40,U:U,E40),_xlfn.MAXIFS(AG:AG,AH:AH,C40,AI:AI,E40))) -> 45626 | K40: =COUNTIFS(TABELA!A:A,C40,TABELA!C:C,E40) -> 1 | L40: =SUMIFS(TABELA!M:M,TABELA!A:A,C40,TABELA!C:C,E40) -> 16.49 | M40: =IF(L40>0,H40-L40,0) -> -4.1 | N40: =SUMIFS(X:X,S:S,C40,U:U,E40)+SUMIFS(AK:AK,AH:AH,C40,AI:AI,E40) -> 12.39 | O40: =SUMIFS(W:W,S:S,C40)/SUMIFS(X:X,S:S,C40)/10 -> 16.14205 | R40: 2805 | S40: 20314 | U40: 502 | AF40: 2720 | AG40: 45626 | AH40: 20465 | AI40: 4 | AJ40: 854.8 | AK40: 42.74 | AL40: 20
...

Sheet TABELA
A1: CD_UPNIVEL1 | B1: DE_UPNIVEL1 | C1: CD_UPNIVEL3 | D1: NO_CORTE | E1: DA_ESTAGIO | F1: AMB_PRD | G1: TP_CANA | H1: DE_SIST_CULT | I1: DE_VARIED | J1: CD_TP_PROPR | K1: QT_AREA_EST | L1: QT_AREA_REST1 | M1: QT_AREA_REST2 | N1: QT_AREA_REAL | O1: QT_CANA_EST | P1: QT_CANA_REST1 | Q1: QT_CANA_REST2 | R1: QT_CANA_REAL | S1: DE_FORNEC | T1: DT_ENC_SEM | U1: STATUS | V1: TP_REST1 | W1: TP_REST2 | X1: AREA_EST | Y1: AREA_REST1 | Z1: AREA_REST2 | AA1: VOL_EST | AB1: VOL_REST1 | AC1: VOL_REST2 | AD1: PROJ_VOLEST | AE1: PROJ_VOLREST1 | AF1: PROJ_VOLREST2 | AG1: GEADA | AH1: TP_CULTIVO | AI1: MÊS_IRRIG | AJ1: MM_TOTAL | AK1: IRRIG_DESCARTE
A2: 10005 | B2: Fazenda Laranjeiras 2 | C2: 1 | D2: 6 | E2: 6ºC | F2: B | H2: Mineral | I2: RB92579 | J2: 1 - Própria | K2: 15.85 | L2: 15.85 | M2: 15.85 | N2: 15.85 | O2: 475.5 | P2: 317 | Q2: 396.25 | R2: 649.24 | S2: UMOE | T2: 45977 | U2: =IF(ESTIMATIVA[[#This Row],[QT_AREA_REAL]]>0,"1- Colhido","2- à Colher") -> 1- Colhido | V2: =IF(ESTIMATIVA[[#This Row],[QT_AREA_REST1]]>0,"Reestimativa 1",IF(ESTIMATIVA[[#This Row],[QT_AREA_REAL]]=0,"Reestimativa 1","Realizado")) -> Reestimativa 1 | W2: =IF(ESTIMATIVA[[#This Row],[QT_AREA_REST2]]>0,"Reestimativa 2",IF(ESTIMATIVA[[#This Row],[QT_AREA_REAL]]=0,"Reestimativa 2","Realizado")) -> Reestimativa 2 | X2: =ESTIMATIVA[[#This Row],[QT_AREA_EST]] -> 15.85 | Y2: =IF(ESTIMATIVA[[#This Row],[QT_AREA_REST1]]>0,ESTIMATIVA[[#This Row],[QT_AREA_REST1]], IF(ESTIMATIVA[[#This Row],[QT_AREA_REAL]]>0,ESTIMATIVA[[#This Row],[QT_AREA_REAL]],ESTIMATIVA[[#This Row],[QT_AREA_EST]])) -> 15.85 | Z2: =IF(ESTIMATIVA[[#This Row],[QT_AREA_REST2]]>0,ESTIMATIVA[[#This Row],[QT_AREA_REST2]], IF(ESTIMATIVA[[#This Row],[QT_AREA_REAL]]>0,ESTIMATIVA[[#This Row],[QT_AREA_REAL]], IF(ESTIMATIVA[[#This Row],[QT_AREA_REST1]]>0,ESTIMATIVA[[#This Row],[QT_AREA_REST1]],ESTIMATIVA[[#This Row],[QT_AREA_EST]]))) -> 15.85 | AA2: =ESTIMATIVA[[#This Row],[QT_CANA_EST]] -> 475.5 | AB2: =IF(ESTIMATIVA[[#This Row],[QT_CANA_REST1]]>0,ESTIMATIVA[[#This Row],[QT_CANA_REST1]], IF(ESTIMATIVA[[#This Row],[QT_CANA_REAL]]>0,ESTIMATIVA[[#This Row],[QT_CANA_REAL]],ESTIMATIVA[[#This Row],[QT_CANA_EST]])) -> 317 | AC2: =IF(ESTIMATIVA[[#This Row],[QT_CANA_REST2]]>0,ESTIMATIVA[[#This Row],[QT_CANA_REST2]], IF(ESTIMATIVA[[#This Row],[QT_CANA_REAL]]>0,ESTIMATIVA[[#This Row],[QT_CANA_REAL]], IF(ESTIMATIVA[[#This Row],[QT_CANA_REST1]]>0,ESTIMATIVA[[#This Row],[QT_CANA_REST1]],ESTIMATIVA[[#This Row],[QT_CANA_EST]]))) -> 396.25 | AD2: =IF(ESTIMATIVA[[#This Row],[QT_AREA_REAL]]>0,ESTIMATIVA[[#This Row],[QT_CANA_REAL]],ESTIMATIVA[[#This Row],[QT_CANA_EST]]) -> 649.24 | AE2: =IF(ESTIMATIVA[[#This Row],[QT_AREA_REAL]]>0,ESTIMATIVA[[#This Row],[QT_CANA_REAL]],ESTIMATIVA[[#This Row],[QT_CANA_REST1]]) -> 649.24 | AF2: =IF(ESTIMATIVA[[#This Row],[QT_AREA_REAL]]>0,ESTIMATIVA[[#This Row],[QT_CANA_REAL]],ESTIMATIVA[[#This Row],[QT_CANA_REST2]]) -> 649.24 | AG2: =IF(COUNTIFS(GEADA!A:A,VALUE(ESTIMATIVA[[#This Row],[CD_UPNIVEL1]]&TEXT(ESTIMATIVA[[#This Row],[CD_UPNIVEL3]],"0000")))>0,"S","N") -> S | AH2: =IF(COUNTIFS(IRRIGADO!C:C,ESTIMATIVA[[#This Row],[CD_UPNIVEL1]],IRRIGADO!E:E,ESTIMATIVA[[#This Row],[CD_UPNIVEL3]])>0,"Irrigado",IF(ESTIMATIVA[[#This Row],[DE_SIST_CULT]]="Mineral","Sequeiro",ESTIMATIVA[[#This Row],[DE_SIST_CULT]])) -> Sequeiro | AI2: =IF(ESTIMATIVA[[#This Row],[TP_CULTIVO]]="Irrigado",_xlfn.MAXIFS(IRRIGADO!J:J,IRRIGADO!C:C,ESTIMATIVA[[#This Row],[CD_UPNIVEL1]],IRRIGADO!E:E,ESTIMATIVA[[#This Row],[CD_UPNIVEL3]]),"") | AJ2: =IF(ESTIMATIVA[[#This Row],[TP_CULTIVO]]<>"Irrigado",0,AVERAGEIFS(IRRIGADO!G:G,IRRIGADO!C:C,ESTIMATIVA[[#This Row],[CD_UPNIVEL1]],IRRIGADO!E:E,ESTIMATIVA[[#This Row],[CD_UPNIVEL3]])*ESTIMATIVA[[#This Row],[QT_AREA_REAL]]) -> 0 | AK2: =COUNTIFS(Apresentação!$E$23:$E$29,ESTIMATIVA[[#This Row],[CD_UPNIVEL1]]) -> 0
A3: 10005 | B3: Fazenda Laranjeiras 2 | C3: 2 | D3: 6 | E3: 6ºC | F3: B | H3: Mineral | I3: RB92579 | J3: 1 - Própria | K3: 16.17 | L3: 16.17 | M3: 16.17 | N3: 16.17 | O3: 485.1 | P3: 485.1 | Q3: 501.27 | R3: 821.4 | S3: UMOE | T3: 45977 | U3: =IF(ESTIMATIVA[[#This Row],[QT_AREA_REAL]]>0,"1- Colhido","2- à Colher") -> 1- Colhido | V3: =IF(ESTIMATIVA[[#This Row],[QT_AREA_REST1]]>0,"Reestimativa 1",IF(ESTIMATIVA[[#This Row],[QT_AREA_REAL]]=0,"Reestimativa 1","Realizado")) -> Reestimativa 1 | W3: =IF(ESTIMATIVA[[#This Row],[QT_AREA_REST2]]>0,"Reestimativa 2",IF(ESTIMATIVA[[#This Row],[QT_AREA_REAL]]=0,"Reestimativa 2","Realizado")) -> Reestimativa 2 | X3: =ESTIMATIVA[[#This Row],[QT_AREA_EST]] -> 16.17 | Y3: =IF(ESTIMATIVA[[#This Row],[QT_AREA_REST1]]>0,ESTIMATIVA[[#This Row],[QT_AREA_REST1]], IF(ESTIMATIVA[[#This Row],[QT_AREA_REAL]]>0,ESTIMATIVA[[#This Row],[QT_AREA_REAL]],ESTIMATIVA[[#This Row],[QT_AREA_EST]])) -> 16.17 | Z3: =IF(ESTIMATIVA[[#This Row],[QT_AREA_REST2]]>0,ESTIMATIVA[[#This Row],[QT_AREA_REST2]], IF(ESTIMATIVA[[#This Row],[QT_AREA_REAL]]>0,ESTIMATIVA[[#This Row],[QT_AREA_REAL]], IF(ESTIMATIVA[[#This Row],[QT_AREA_REST1]]>0,ESTIMATIVA[[#This Row],[QT_AREA_REST1]],ESTIMATIVA[[#This Row],[QT_AREA_EST]]))) -> 16.17 | AA3: =ESTIMATIVA[[#This Row],[QT_CANA_EST]] -> 485.1 | AB3: =IF(ESTIMATIVA[[#This Row],[QT_CANA_REST1]]>0,ESTIMATIVA[[#This Row],[QT_CANA_REST1]], IF(ESTIMATIVA[[#This Row],[QT_CANA_REAL]]>0,ESTIMATIVA[[#This Row],[QT_CANA_REAL]],ESTIMATIVA[[#This Row],[QT_CANA_EST]])) -> 485.1 | AC3: =IF(ESTIMATIVA[[#This Row],[QT_CANA_REST2]]>0,ESTIMATIVA[[#This Row],[QT_CANA_REST2]], IF(ESTIMATIVA[[#This Row],[QT_CANA_REAL]]>0,ESTIMATIVA[[#This Row],[QT_CANA_REAL]], IF(ESTIMATIVA[[#This Row],[QT_CANA_REST1]]>0,ESTIMATIVA[[#This Row],[QT_CANA_REST1]],ESTIMATIVA[[#This Row],[QT_CANA_EST]]))) -> 501.27 | AD3: =IF(ESTIMATIVA[[#This Row],[QT_AREA_REAL]]>0,ESTIMATIVA[[#This Row],[QT_CANA_REAL]],ESTIMATIVA[[#This Row],[QT_CANA_EST]]) -> 821.4 | AE3: =IF(ESTIMATIVA[[#This Row],[QT_AREA_REAL]]>0,ESTIMATIVA[[#This Row],[QT_CANA_REAL]],ESTIMATIVA[[#This Row],[QT_CANA_REST1]]) -> 821.4 | AF3: =IF(ESTIMATIVA[[#This Row],[QT_AREA_REAL]]>0,ESTIMATIVA[[#This Row],[QT_CANA_REAL]],ESTIMATIVA[[#This Row],[QT_CANA_REST2]]) -> 821.4 | AG3: =IF(COUNTIFS(GEADA!A:A,VALUE(ESTIMATIVA[[#This Row],[CD_UPNIVEL1]]&TEXT(ESTIMATIVA[[#This Row],[CD_UPNIVEL3]],"0000")))>0,"S","N") -> S | AH3: =IF(COUNTIFS(IRRIGADO!C:C,ESTIMATIVA[[#This Row],[CD_UPNIVEL1]],IRRIGADO!E:E,ESTIMATIVA[[#This Row],[CD_UPNIVEL3]])>0,"Irrigado",IF(ESTIMATIVA[[#This Row],[DE_SIST_CULT]]="Mineral","Sequeiro",ESTIMATIVA[[#This Row],[DE_SIST_CULT]])) -> Sequeiro | AI3: =IF(ESTIMATIVA[[#This Row],[TP_CULTIVO]]="Irrigado",_xlfn.MAXIFS(IRRIGADO!J:J,IRRIGADO!C:C,ESTIMATIVA[[#This Row],[CD_UPNIVEL1]],IRRIGADO!E:E,ESTIMATIVA[[#This Row],[CD_UPNIVEL3]]),"") | AJ3: =IF(ESTIMATIVA[[#This Row],[TP_CULTIVO]]<>"Irrigado",0,AVERAGEIFS(IRRIGADO!G:G,IRRIGADO!C:C,ESTIMATIVA[[#This Row],[CD_UPNIVEL1]],IRRIGADO!E:E,ESTIMATIVA[[#This Row],[CD_UPNIVEL3]])*ESTIMATIVA[[#This Row],[QT_AREA_REAL]]) -> 0 | AK3: =COUNTIFS(Apresentação!$E$23:$E$29,ESTIMATIVA[[#This Row],[CD_UPNIVEL1]]) -> 0
A4: 10005 | B4: Fazenda Laranjeiras 2 | C4: 3 | D4: 6 | E4: 6ºC | F4: B | H4: Mineral | I4: RB92579 | J4: 1 - Própria | K4: 16.93 | L4: 16.93 | M4: 16.93 | N4: 16.93 | O4: 507.9 | P4: 507.9 | Q4: 524.83 | R4: 860.85 | S4: UMOE | T4: 45977 | U4: =IF(ESTIMATIVA[[#This Row],[QT_AREA_REAL]]>0,"1- Colhido","2- à Colher") -> 1- Colhido | V4: =IF(ESTIMATIVA[[#This Row],[QT_AREA_REST1]]>0,"Reestimativa 1",IF(ESTIMATIVA[[#This Row],[QT_AREA_REAL]]=0,"Reestimativa 1","Realizado")) -> Reestimativa 1 | W4: =IF(ESTIMATIVA[[#This Row],[QT_AREA_REST2]]>0,"Reestimativa 2",IF(ESTIMATIVA[[#This Row],[QT_AREA_REAL]]=0,"Reestimativa 2","Realizado")) -> Reestimativa 2 | X4: =ESTIMATIVA[[#This Row],[QT_AREA_EST]] -> 16.93 | Y4: =IF(ESTIMATIVA[[#This Row],[QT_AREA_REST1]]>0,ESTIMATIVA[[#This Row],[QT_AREA_REST1]], IF(ESTIMATIVA[[#This Row],[QT_AREA_REAL]]>0,ESTIMATIVA[[#This Row],[QT_AREA_REAL]],ESTIMATIVA[[#This Row],[QT_AREA_EST]])) -> 16.93 | Z4: =IF(ESTIMATIVA[[#This Row],[QT_AREA_REST2]]>0,ESTIMATIVA[[#This Row],[QT_AREA_REST2]], IF(ESTIMATIVA[[#This Row],[QT_AREA_REAL]]>0,ESTIMATIVA[[#This Row],[QT_AREA_REAL]], IF(ESTIMATIVA[[#This Row],[QT_AREA_REST1]]>0,ESTIMATIVA[[#This Row],[QT_AREA_REST1]],ESTIMATIVA[[#This Row],[QT_AREA_EST]]))) -> 16.93 | AA4: =ESTIMATIVA[[#This Row],[QT_CANA_EST]] -> 507.9 | AB4: =IF(ESTIMATIVA[[#This Row],[QT_CANA_REST1]]>0,ESTIMATIVA[[#This Row],[QT_CANA_REST1]], IF(ESTIMATIVA[[#This Row],[QT_CANA_REAL]]>0,ESTIMATIVA[[#This Row],[QT_CANA_REAL]],ESTIMATIVA[[#This Row],[QT_CANA_EST]])) -> 507.9 | AC4: =IF(ESTIMATIVA[[#This Row],[QT_CANA_REST2]]>0,ESTIMATIVA[[#This Row],[QT_CANA_REST2]], IF(ESTIMATIVA[[#This Row],[QT_CANA_REAL]]>0,ESTIMATIVA[[#This Row],[QT_CANA_REAL]], IF(ESTIMATIVA[[#This Row],[QT_CANA_REST1]]>0,ESTIMATIVA[[#This Row],[QT_CANA_REST1]],ESTIMATIVA[[#This Row],[QT_CANA_EST]]))) -> 524.83 | AD4: =IF(ESTIMATIVA[[#This Row],[QT_AREA_REAL]]>0,ESTIMATIVA[[#This Row],[QT_CANA_REAL]],ESTIMATIVA[[#This Row],[QT_CANA_EST]]) -> 860.85 | AE4: =IF(ESTIMATIVA[[#This Row],[QT_AREA_REAL]]>0,ESTIMATIVA[[#This Row],[QT_CANA_REAL]],ESTIMATIVA[[#This Row],[QT_CANA_REST1]]) -> 860.85 | AF4: =IF(ESTIMATIVA[[#This Row],[QT_AREA_REAL]]>0,ESTIMATIVA[[#This Row],[QT_CANA_REAL]],ESTIMATIVA[[#This Row],[QT_CANA_REST2]]) -> 860.85 | AG4: =IF(COUNTIFS(GEADA!A:A,VALUE(ESTIMATIVA[[#This Row],[CD_UPNIVEL1]]&TEXT(ESTIMATIVA[[#This Row],[CD_UPNIVEL3]],"0000")))>0,"S","N") -> N | AH4: =IF(COUNTIFS(IRRIGADO!C:C,ESTIMATIVA[[#This Row],[CD_UPNIVEL1]],IRRIGADO!E:E,ESTIMATIVA[[#This Row],[CD_UPNIVEL3]])>0,"Irrigado",IF(ESTIMATIVA[[#This Row],[DE_SIST_CULT]]="Mineral","Sequeiro",ESTIMATIVA[[#This Row],[DE_SIST_CULT]])) -> Sequeiro | AI4: =IF(ESTIMATIVA[[#This Row],[TP_CULTIVO]]="Irrigado",_xlfn.MAXIFS(IRRIGADO!J:J,IRRIGADO!C:C,ESTIMATIVA[[#This Row],[CD_UPNIVEL1]],IRRIGADO!E:E,ESTIMATIVA[[#This Row],[CD_UPNIVEL3]]),"") | AJ4: =IF(ESTIMATIVA[[#This Row],[TP_CULTIVO]]<>"Irrigado",0,AVERAGEIFS(IRRIGADO!G:G,IRRIGADO!C:C,ESTIMATIVA[[#This Row],[CD_UPNIVEL1]],IRRIGADO!E:E,ESTIMATIVA[[#This Row],[CD_UPNIVEL3]])*ESTIMATIVA[[#This Row],[QT_AREA_REAL]]) -> 0 | AK4: =COUNTIFS(Apresentação!$E$23:$E$29,ESTIMATIVA[[#This Row],[CD_UPNIVEL1]]) -> 0
A5: 10100 | B5: Sítio Jataí II | C5: 1 | D5: 8 | E5: 8ºC | F5: A | H5: Mineral | I5: RB92579 | J5: 2 - Arrendamento | K5: 8.14 | L5: 8.14 | M5: 8.14 | N5: 8.14 | O5: 293.04 | P5: 203.5 | Q5: 284.9 | R5: 314.89 | S5: UMOE | T5: 45984 | U5: =IF(ESTIMATIVA[[#This Row],[QT_AREA_REAL]]>0,"1- Colhido","2- à Colher") -> 1- Colhido | V5: =IF(ESTIMATIVA[[#This Row],[QT_AREA_REST1]]>0,"Reestimativa 1",IF(ESTIMATIVA[[#This Row],[QT_AREA_REAL]]=0,"Reestimativa 1","Realizado")) -> Reestimativa 1 | W5: =IF(ESTIMATIVA[[#This Row],[QT_AREA_REST2]]>0,"Reestimativa 2",IF(ESTIMATIVA[[#This Row],[QT_AREA_REAL]]=0,"Reestimativa 2","Realizado")) -> Reestimativa 2 | X5: =ESTIMATIVA[[#This Row],[QT_AREA_EST]] -> 8.14 | Y5: =IF(ESTIMATIVA[[#This Row],[QT_AREA_REST1]]>0,ESTIMATIVA[[#This Row],[QT_AREA_REST1]], IF(ESTIMATIVA[[#This Row],[QT_AREA_REAL]]>0,ESTIMATIVA[[#This Row],[QT_AREA_REAL]],ESTIMATIVA[[#This Row],[QT_AREA_EST]])) -> 8.14 | Z5: =IF(ESTIMATIVA[[#This Row],[QT_AREA_REST2]]>0,ESTIMATIVA[[#This Row],[QT_AREA_REST2]], IF(ESTIMATIVA[[#This Row],[QT_AREA_REAL]]>0,ESTIMATIVA[[#This Row],[QT_AREA_REAL]], IF(ESTIMATIVA[[#This Row],[QT_AREA_REST1]]>0,ESTIMATIVA[[#This Row],[QT_AREA_REST1]],ESTIMATIVA[[#This Row],[QT_AREA_EST]]))) -> 8.14 | AA5: =ESTIMATIVA[[#This Row],[QT_CANA_EST]] -> 293.04 | AB5: =IF(ESTIMATIVA[[#This Row],[QT_CANA_REST1]]>0,ESTIMATIVA[[#This Row],[QT_CANA_REST1]], IF(ESTIMATIVA[[#This Row],[QT_CANA_REAL]]>0,ESTIMATIVA[[#This Row],[QT_CANA_REAL]],ESTIMATIVA[[#This Row],[QT_CANA_EST]])) -> 203.5 | AC5: =IF(ESTIMATIVA[[#This Row],[QT_CANA_REST2]]>0,ESTIMATIVA[[#This Row],[QT_CANA_REST2]], IF(ESTIMATIVA[[#This Row],[QT_CANA_REAL]]>0,ESTIMATIVA[[#This Row],[QT_CANA_REAL]], IF(ESTIMATIVA[[#This Row],[QT_CANA_REST1]]>0,ESTIMATIVA[[#This Row],[QT_CANA_REST1]],ESTIMATIVA[[#This Row],[QT_CANA_EST]]))) -> 284.9 | AD5: =IF(ESTIMATIVA[[#This Row],[QT_AREA_REAL]]>0,ESTIMATIVA[[#This Row],[QT_CANA_REAL]],ESTIMATIVA[[#This Row],[QT_CANA_EST]]) -> 314.89 | AE5: =IF(ESTIMATIVA[[#This Row],[QT_AREA_REAL]]>0,ESTIMATIVA[[#This Row],[QT_CANA_REAL]],ESTIMATIVA[[#This Row],[QT_CANA_REST1]]) -> 314.89 | AF5: =IF(ESTIMATIVA[[#This Row],[QT_AREA_REAL]]>0,ESTIMATIVA[[#This Row],[QT_CANA_REAL]],ESTIMATIVA[[#This Row],[QT_CANA_REST2]]) -> 314.89 | AG5: =IF(COUNTIFS(GEADA!A:A,VALUE(ESTIMATIVA[[#This Row],[CD_UPNIVEL1]]&TEXT(ESTIMATIVA[[#This Row],[CD_UPNIVEL3]],"0000")))>0,"S","N") -> S | AH5: =IF(COUNTIFS(IRRIGADO!C:C,ESTIMATIVA[[#This Row],[CD_UPNIVEL1]],IRRIGADO!E:E,ESTIMATIVA[[#This Row],[CD_UPNIVEL3]])>0,"Irrigado",IF(ESTIMATIVA[[#This Row],[DE_SIST_CULT]]="Mineral","Sequeiro",ESTIMATIVA[[#This Row],[DE_SIST_CULT]])) -> Sequeiro | AI5: =IF(ESTIMATIVA[[#This Row],[TP_CULTIVO]]="Irrigado",_xlfn.MAXIFS(IRRIGADO!J:J,IRRIGADO!C:C,ESTIMATIVA[[#This Row],[CD_UPNIVEL1]],IRRIGADO!E:E,ESTIMATIVA[[#This Row],[CD_UPNIVEL3]]),"") | AJ5: =IF(ESTIMATIVA[[#This Row],[TP_CULTIVO]]<>"Irrigado",0,AVERAGEIFS(IRRIGADO!G:G,IRRIGADO!C:C,ESTIMATIVA[[#This Row],[CD_UPNIVEL1]],IRRIGADO!E:E,ESTIMATIVA[[#This Row],[CD_UPNIVEL3]])*ESTIMATIVA[[#This Row],[QT_AREA_REAL]]) -> 0 | AK5: =COUNTIFS(Apresentação!$E$23:$E$29,ESTIMATIVA[[#This Row],[CD_UPNIVEL1]]) -> 0
A6: 10100 | B6: Sítio Jataí II | C6: 2 | D6: 8 | E6: 8ºC | F6: A | H6: Mineral | I6: RB92579 | J6: 2 - Arrendamento | K6: 5.58 | L6: 5.58 | M6: 5.58 | N6: 5.58 | O6: 200.88 | P6: 139.5 | Q6: 195.3 | R6: 215.46 | S6: UMOE | T6: 45984 | U6: =IF(ESTIMATIVA[[#This Row],[QT_AREA_REAL]]>0,"1- Colhido","2- à Colher") -> 1- Colhido | V6: =IF(ESTIMATIVA[[#This Row],[QT_AREA_REST1]]>0,"Reestimativa 1",IF(ESTIMATIVA[[#This Row],[QT_AREA_REAL]]=0,"Reestimativa 1","Realizado")) -> Reestimativa 1 | W6: =IF(ESTIMATIVA[[#This Row],[QT_AREA_REST2]]>0,"Reestimativa 2",IF(ESTIMATIVA[[#This Row],[QT_AREA_REAL]]=0,"Reestimativa 2","Realizado")) -> Reestimativa 2 | X6: =ESTIMATIVA[[#This Row],[QT_AREA_EST]] -> 5.58 | Y6: =IF(ESTIMATIVA[[#This Row],[QT_AREA_REST1]]>0,ESTIMATIVA[[#This Row],[QT_AREA_REST1]], IF(ESTIMATIVA[[#This Row],[QT_AREA_REAL]]>0,ESTIMATIVA[[#This Row],[QT_AREA_REAL]],ESTIMATIVA[[#This Row],[QT_AREA_EST]])) -> 5.58 | Z6: =IF(ESTIMATIVA[[#This Row],[QT_AREA_REST2]]>0,ESTIMATIVA[[#This Row],[QT_AREA_REST2]], IF(ESTIMATIVA[[#This Row],[QT_AREA_REAL]]>0,ESTIMATIVA[[#This Row],[QT_AREA_REAL]], IF(ESTIMATIVA[[#This Row],[QT_AREA_REST1]]>0,ESTIMATIVA[[#This Row],[QT_AREA_REST1]],ESTIMATIVA[[#This Row],[QT_AREA_EST]]))) -> 5.58 | AA6: =ESTIMATIVA[[#This Row],[QT_CANA_EST]] -> 200.88 | AB6: =IF(ESTIMATIVA[[#This Row],[QT_CANA_REST1]]>0,ESTIMATIVA[[#This Row],[QT_CANA_REST1]], IF(ESTIMATIVA[[#This Row],[QT_CANA_REAL]]>0,ESTIMATIVA[[#This Row],[QT_CANA_REAL]],ESTIMATIVA[[#This Row],[QT_CANA_EST]])) -> 139.5 | AC6: =IF(ESTIMATIVA[[#This Row],[QT_CANA_REST2]]>0,ESTIMATIVA[[#This Row],[QT_CANA_REST2]], IF(ESTIMATIVA[[#This Row],[QT_CANA_REAL]]>0,ESTIMATIVA[[#This Row],[QT_CANA_REAL]], IF(ESTIMATIVA[[#This Row],[QT_CANA_REST1]]>0,ESTIMATIVA[[#This Row],[QT_CANA_REST1]],ESTIMATIVA[[#This Row],[QT_CANA_EST]]))) -> 195.3 | AD6: =IF(ESTIMATIVA[[#This Row],[QT_AREA_REAL]]>0,ESTIMATIVA[[#This Row],[QT_CANA_REAL]],ESTIMATIVA[[#This Row],[QT_CANA_EST]]) -> 215.46 | AE6: =IF(ESTIMATIVA[[#This Row],[QT_AREA_REAL]]>0,ESTIMATIVA[[#This Row],[QT_CANA_REAL]],ESTIMATIVA[[#This Row],[QT_CANA_REST1]]) -> 215.46 | AF6: =IF(ESTIMATIVA[[#This Row],[QT_AREA_REAL]]>0,ESTIMATIVA[[#This Row],[QT_CANA_REAL]],ESTIMATIVA[[#This Row],[QT_CANA_REST2]]) -> 215.46 | AG6: =IF(COUNTIFS(GEADA!A:A,VALUE(ESTIMATIVA[[#This Row],[CD_UPNIVEL1]]&TEXT(ESTIMATIVA[[#This Row],[CD_UPNIVEL3]],"0000")))>0,"S","N") -> S | AH6: =IF(COUNTIFS(IRRIGADO!C:C,ESTIMATIVA[[#This Row],[CD_UPNIVEL1]],IRRIGADO!E:E,ESTIMATIVA[[#This Row],[CD_UPNIVEL3]])>0,"Irrigado",IF(ESTIMATIVA[[#This Row],[DE_SIST_CULT]]="Mineral","Sequeiro",ESTIMATIVA[[#This Row],[DE_SIST_CULT]])) -> Sequeiro | AI6: =IF(ESTIMATIVA[[#This Row],[TP_CULTIVO]]="Irrigado",_xlfn.MAXIFS(IRRIGADO!J:J,IRRIGADO!C:C,ESTIMATIVA[[#This Row],[CD_UPNIVEL1]],IRRIGADO!E:E,ESTIMATIVA[[#This Row],[CD_UPNIVEL3]]),"") | AJ6: =IF(ESTIMATIVA[[#This Row],[TP_CULTIVO]]<>"Irrigado",0,AVERAGEIFS(IRRIGADO!G:G,IRRIGADO!C:C,ESTIMATIVA[[#This Row],[CD_UPNIVEL1]],IRRIGADO!E:E,ESTIMATIVA[[#This Row],[CD_UPNIVEL3]])*ESTIMATIVA[[#This Row],[QT_AREA_REAL]]) -> 0 | AK6: =COUNTIFS(Apresentação!$E$23:$E$29,ESTIMATIVA[[#This Row],[CD_UPNIVEL1]]) -> 0
A7: 10310 | B7: Fazenda Sao Jorge | C7: 1 | D7: 3 | E7: 3ºC | F7: E | H7: Mineral | I7: SP83-2847 | J7: 3 - Parceria | K7: 9.09 | L7: 9.09 | M7: 9.09 | N7: 9.09 | O7: 618.12 | P7: 545.4 | Q7: 545.4 | R7: 437.97 | S7: UMOE | T7: 45935 | U7: =IF(ESTIMATIVA[[#This Row],[QT_AREA_REAL]]>0,"1- Colhido","2- à Colher") -> 1- Colhido | V7: =IF(ESTIMATIVA[[#This Row],[QT_AREA_REST1]]>0,"Reestimativa 1",IF(ESTIMATIVA[[#This Row],[QT_AREA_REAL]]=0,"Reestimativa 1","Realizado")) -> Reestimativa 1 | W7: =IF(ESTIMATIVA[[#This Row],[QT_AREA_REST2]]>0,"Reestimativa 2",IF(ESTIMATIVA[[#This Row],[QT_AREA_REAL]]=0,"Reestimativa 2","Realizado")) -> Reestimativa 2 | X7: =ESTIMATIVA[[#This Row],[QT_AREA_EST]] -> 9.09 | Y7: =IF(ESTIMATIVA[[#This Row],[QT_AREA_REST1]]>0,ESTIMATIVA[[#This Row],[QT_AREA_REST1]], IF(ESTIMATIVA[[#This Row],[QT_AREA_REAL]]>0,ESTIMATIVA[[#This Row],[QT_AREA_REAL]],ESTIMATIVA[[#This Row],[QT_AREA_EST]])) -> 9.09 | Z7: =IF(ESTIMATIVA[[#This Row],[QT_AREA_REST2]]>0,ESTIMATIVA[[#This Row],[QT_AREA_REST2]], IF(ESTIMATIVA[[#This Row],[QT_AREA_REAL]]>0,ESTIMATIVA[[#This Row],[QT_AREA_REAL]], IF(ESTIMATIVA[[#This Row],[QT_AREA_REST1]]>0,ESTIMATIVA[[#This Row],[QT_AREA_REST1]],ESTIMATIVA[[#This Row],[QT_AREA_EST]]))) -> 9.09 | AA7: =ESTIMATIVA[[#This Row],[QT_CANA_EST]] -> 618.12 | AB7: =IF(ESTIMATIVA[[#This Row],[QT_CANA_REST1]]>0,ESTIMATIVA[[#This Row],[QT_CANA_REST1]], IF(ESTIMATIVA[[#This Row],[QT_CANA_REAL]]>0,ESTIMATIVA[[#This Row],[QT_CANA_REAL]],ESTIMATIVA[[#This Row],[QT_CANA_EST]])) -> 545.4 | AC7: =IF(ESTIMATIVA[[#This Row],[QT_CANA_REST2]]>0,ESTIMATIVA[[#This Row],[QT_CANA_REST2]], IF(ESTIMATIVA[[#This Row],[QT_CANA_REAL]]>0,ESTIMATIVA[[#This Row],[QT_CANA_REAL]], IF(ESTIMATIVA[[#This Row],[QT_CANA_REST1]]>0,ESTIMATIVA[[#This Row],[QT_CANA_REST1]],ESTIMATIVA[[#This Row],[QT_CANA_EST]]))) -> 545.4 | AD7: =IF(ESTIMATIVA[[#This Row],[QT_AREA_REAL]]>0,ESTIMATIVA[[#This Row],[QT_CANA_REAL]],ESTIMATIVA[[#This Row],[QT_CANA_EST]]) -> 437.97 | AE7: =IF(ESTIMATIVA[[#This Row],[QT_AREA_REAL]]>0,ESTIMATIVA[[#This Row],[QT_CANA_REAL]],ESTIMATIVA[[#This Row],[QT_CANA_REST1]]) -> 437.97 | AF7: =IF(ESTIMATIVA[[#This Row],[QT_AREA_REAL]]>0,ESTIMATIVA[[#This Row],[QT_CANA_REAL]],ESTIMATIVA[[#This Row],[QT_CANA_REST2]]) -> 437.97 | AG7: =IF(COUNTIFS(GEADA!A:A,VALUE(ESTIMATIVA[[#This Row],[CD_UPNIVEL1]]&TEXT(ESTIMATIVA[[#This Row],[CD_UPNIVEL3]],"0000")))>0,"S","N") -> N | AH7: =IF(COUNTIFS(IRRIGADO!C:C,ESTIMATIVA[[#This Row],[CD_UPNIVEL1]],IRRIGADO!E:E,ESTIMATIVA[[#This Row],[CD_UPNIVEL3]])>0,"Irrigado",IF(ESTIMATIVA[[#This Row],[DE_SIST_CULT]]="Mineral","Sequeiro",ESTIMATIVA[[#This Row],[DE_SIST_CULT]])) -> Sequeiro | AI7: =IF(ESTIMATIVA[[#This Row],[TP_CULTIVO]]="Irrigado",_xlfn.MAXIFS(IRRIGADO!J:J,IRRIGADO!C:C,ESTIMATIVA[[#This Row],[CD_UPNIVEL1]],IRRIGADO!E:E,ESTIMATIVA[[#This Row],[CD_UPNIVEL3]]),"") | AJ7: =IF(ESTIMATIVA[[#This Row],[TP_CULTIVO]]<>"Irrigado",0,AVERAGEIFS(IRRIGADO!G:G,IRRIGADO!C:C,ESTIMATIVA[[#This Row],[CD_UPNIVEL1]],IRRIGADO!E:E,ESTIMATIVA[[#This Row],[CD_UPNIVEL3]])*ESTIMATIVA[[#This Row],[QT_AREA_REAL]]) -> 0 | AK7: =COUNTIFS(Apresentação!$E$23:$E$29,ESTIMATIVA[[#This Row],[CD_UPNIVEL1]]) -> 0
A8: 10310 | B8: Fazenda Sao Jorge | C8: 2 | D8: 3 | E8: 3ºC | F8: E | H8: Mineral | I8: SP83-2847 | J8: 3 - Parceria | K8: 18.97 | L8: 18.97 | M8: 18.97 | N8: 18.97 | O8: 1289.96 | P8: 948.5 | Q8: 948.5 | R8: 762.67 | S8: UMOE | T8: 45935 | U8: =IF(ESTIMATIVA[[#This Row],[QT_AREA_REAL]]>0,"1- Colhido","2- à Colher") -> 1- Colhido | V8: =IF(ESTIMATIVA[[#This Row],[QT_AREA_REST1]]>0,"Reestimativa 1",IF(ESTIMATIVA[[#This Row],[QT_AREA_REAL]]=0,"Reestimativa 1","Realizado")) -> Reestimativa 1 | W8: =IF(ESTIMATIVA[[#This Row],[QT_AREA_REST2]]>0,"Reestimativa 2",IF(ESTIMATIVA[[#This Row],[QT_AREA_REAL]]=0,"Reestimativa 2","Realizado")) -> Reestimativa 2 | X8: =ESTIMATIVA[[#This Row],[QT_AREA_EST]] -> 18.97 | Y8: =IF(ESTIMATIVA[[#This Row],[QT_AREA_REST1]]>0,ESTIMATIVA[[#This Row],[QT_AREA_REST1]], IF(ESTIMATIVA[[#This Row],[QT_AREA_REAL]]>0,ESTIMATIVA[[#This Row],[QT_AREA_REAL]],ESTIMATIVA[[#This Row],[QT_AREA_EST]])) -> 18.97 | Z8: =IF(ESTIMATIVA[[#This Row],[QT_AREA_REST2]]>0,ESTIMATIVA[[#This Row],[QT_AREA_REST2]], IF(ESTIMATIVA[[#This Row],[QT_AREA_REAL]]>0,ESTIMATIVA[[#This Row],[QT_AREA_REAL]], IF(ESTIMATIVA[[#This Row],[QT_AREA_REST1]]>0,ESTIMATIVA[[#This Row],[QT_AREA_REST1]],ESTIMATIVA[[#This Row],[QT_AREA_EST]]))) -> 18.97 | AA8: =ESTIMATIVA[[#This Row],[QT_CANA_EST]] -> 1289.96 | AB8: =IF(ESTIMATIVA[[#This Row],[QT_CANA_REST1]]>0,ESTIMATIVA[[#This Row],[QT_CANA_REST1]], IF(ESTIMATIVA[[#This Row],[QT_CANA_REAL]]>0,ESTIMATIVA[[#This Row],[QT_CANA_REAL]],ESTIMATIVA[[#This Row],[QT_CANA_EST]])) -> 948.5 | AC8: =IF(ESTIMATIVA[[#This Row],[QT_CANA_REST2]]>0,ESTIMATIVA[[#This Row],[QT_CANA_REST2]], IF(ESTIMATIVA[[#This Row],[QT_CANA_REAL]]>0,ESTIMATIVA[[#This Row],[QT_CANA_REAL]], IF(ESTIMATIVA[[#This Row],[QT_CANA_REST1]]>0,ESTIMATIVA[[#This Row],[QT_CANA_REST1]],ESTIMATIVA[[#This Row],[QT_CANA_EST]]))) -> 948.5 | AD8: =IF(ESTIMATIVA[[#This Row],[QT_AREA_REAL]]>0,ESTIMATIVA[[#This Row],[QT_CANA_REAL]],ESTIMATIVA[[#This Row],[QT_CANA_EST]]) -> 762.67 | AE8: =IF(ESTIMATIVA[[#This Row],[QT_AREA_REAL]]>0,ESTIMATIVA[[#This Row],[QT_CANA_REAL]],ESTIMATIVA[[#This Row],[QT_CANA_REST1]]) -> 762.67 | AF8: =IF(ESTIMATIVA[[#This Row],[QT_AREA_REAL]]>0,ESTIMATIVA[[#This Row],[QT_CANA_REAL]],ESTIMATIVA[[#This Row],[QT_CANA_REST2]]) -> 762.67 | AG8: =IF(COUNTIFS(GEADA!A:A,VALUE(ESTIMATIVA[[#This Row],[CD_UPNIVEL1]]&TEXT(ESTIMATIVA[[#This Row],[CD_UPNIVEL3]],"0000")))>0,"S","N") -> S | AH8: =IF(COUNTIFS(IRRIGADO!C:C,ESTIMATIVA[[#This Row],[CD_UPNIVEL1]],IRRIGADO!E:E,ESTIMATIVA[[#This Row],[CD_UPNIVEL3]])>0,"Irrigado",IF(ESTIMATIVA[[#This Row],[DE_SIST_CULT]]="Mineral","Sequeiro",ESTIMATIVA[[#This Row],[DE_SIST_CULT]])) -> Sequeiro | AI8: =IF(ESTIMATIVA[[#This Row],[TP_CULTIVO]]="Irrigado",_xlfn.MAXIFS(IRRIGADO!J:J,IRRIGADO!C:C,ESTIMATIVA[[#This Row],[CD_UPNIVEL1]],IRRIGADO!E:E,ESTIMATIVA[[#This Row],[CD_UPNIVEL3]]),"") | AJ8: =IF(ESTIMATIVA[[#This Row],[TP_CULTIVO]]<>"Irrigado",0,AVERAGEIFS(IRRIGADO!G:G,IRRIGADO!C:C,ESTIMATIVA[[#This Row],[CD_UPNIVEL1]],IRRIGADO!E:E,ESTIMATIVA[[#This Row],[CD_UPNIVEL3]])*ESTIMATIVA[[#This Row],[QT_AREA_REAL]]) -> 0 | AK8: =COUNTIFS(Apresentação!$E$23:$E$29,ESTIMATIVA[[#This Row],[CD_UPNIVEL1]]) -> 0
A9: 10310 | B9: Fazenda Sao Jorge | C9: 3 | D9: 3 | E9: 3ºC | F9: E | H9: Mineral | I9: SP83-2847 | J9: 3 - Parceria | K9: 16.47 | L9: 16.47 | M9: 16.47 | N9: 16.47 | O9: 1119.96 | P9: 823.5 | Q9: 823.5 | R9: 662.2 | S9: UMOE | T9: 45935 | U9: =IF(ESTIMATIVA[[#This Row],[QT_AREA_REAL]]>0,"1- Colhido","2- à Colher") -> 1- Colhido | V9: =IF(ESTIMATIVA[[#This Row],[QT_AREA_REST1]]>0,"Reestimativa 1",IF(ESTIMATIVA[[#This Row],[QT_AREA_REAL]]=0,"Reestimativa 1","Realizado")) -> Reestimativa 1 | W9: =IF(ESTIMATIVA[[#This Row],[QT_AREA_REST2]]>0,"Reestimativa 2",IF(ESTIMATIVA[[#This Row],[QT_AREA_REAL]]=0,"Reestimativa 2","Realizado")) -> Reestimativa 2 | X9: =ESTIMATIVA[[#This Row],[QT_AREA_EST]] -> 16.47 | Y9: =IF(ESTIMATIVA[[#This Row],[QT_AREA_REST1]]>0,ESTIMATIVA[[#This Row],[QT_AREA_REST1]], IF(ESTIMATIVA[[#This Row],[QT_AREA_REAL]]>0,ESTIMATIVA[[#This Row],[QT_AREA_REAL]],ESTIMATIVA[[#This Row],[QT_AREA_EST]])) -> 16.47 | Z9: =IF(ESTIMATIVA[[#This Row],[QT_AREA_REST2]]>0,ESTIMATIVA[[#This Row],[QT_AREA_REST2]], IF(ESTIMATIVA[[#This Row],[QT_AREA_REAL]]>0,ESTIMATIVA[[#This Row],[QT_AREA_REAL]], IF(ESTIMATIVA[[#This Row],[QT_AREA_REST1]]>0,ESTIMATIVA[[#This Row],[QT_AREA_REST1]],ESTIMATIVA[[#This Row],[QT_AREA_EST]]))) -> 16.47 | AA9: =ESTIMATIVA[[#This Row],[QT_CANA_EST]] -> 1119.96 | AB9: =IF(ESTIMATIVA[[#This Row],[QT_CANA_REST1]]>0,ESTIMATIVA[[#This Row],[QT_CANA_REST1]], IF(ESTIMATIVA[[#This Row],[QT_CANA_REAL]]>0,ESTIMATIVA[[#This Row],[QT_CANA_REAL]],ESTIMATIVA[[#This Row],[QT_CANA_EST]])) -> 823.5 | AC9: =IF(ESTIMATIVA[[#This Row],[QT_CANA_REST2]]>0,ESTIMATIVA[[#This Row],[QT_CANA_REST2]], IF(ESTIMATIVA[[#This Row],[QT_CANA_REAL]]>0,ESTIMATIVA[[#This Row],[QT_CANA_REAL]], IF(ESTIMATIVA[[#This Row],[QT_CANA_REST1]]>0,ESTIMATIVA[[#This Row],[QT_CANA_REST1]],ESTIMATIVA[[#This Row],[QT_CANA_EST]]))) -> 823.5 | AD9: =IF(ESTIMATIVA[[#This Row],[QT_AREA_REAL]]>0,ESTIMATIVA[[#This Row],[QT_CANA_REAL]],ESTIMATIVA[[#This Row],[QT_CANA_EST]]) -> 662.2 | AE9: =IF(ESTIMATIVA[[#This Row],[QT_AREA_REAL]]>0,ESTIMATIVA[[#This Row],[QT_CANA_REAL]],ESTIMATIVA[[#This Row],[QT_CANA_REST1]]) -> 662.2 | AF9: =IF(ESTIMATIVA[[#This Row],[QT_AREA_REAL]]>0,ESTIMATIVA[[#This Row],[QT_CANA_REAL]],ESTIMATIVA[[#This Row],[QT_CANA_REST2]]) -> 662.2 | AG9: =IF(COUNTIFS(GEADA!A:A,VALUE(ESTIMATIVA[[#This Row],[CD_UPNIVEL1]]&TEXT(ESTIMATIVA[[#This Row],[CD_UPNIVEL3]],"0000")))>0,"S","N") -> S | AH9: =IF(COUNTIFS(IRRIGADO!C:C,ESTIMATIVA[[#This Row],[CD_UPNIVEL1]],IRRIGADO!E:E,ESTIMATIVA[[#This Row],[CD_UPNIVEL3]])>0,"Irrigado",IF(ESTIMATIVA[[#This Row],[DE_SIST_CULT]]="Mineral","Sequeiro",ESTIMATIVA[[#This Row],[DE_SIST_CULT]])) -> Sequeiro | AI9: =IF(ESTIMATIVA[[#This Row],[TP_CULTIVO]]="Irrigado",_xlfn.MAXIFS(IRRIGADO!J:J,IRRIGADO!C:C,ESTIMATIVA[[#This Row],[CD_UPNIVEL1]],IRRIGADO!E:E,ESTIMATIVA[[#This Row],[CD_UPNIVEL3]]),"") | AJ9: =IF(ESTIMATIVA[[#This Row],[TP_CULTIVO]]<>"Irrigado",0,AVERAGEIFS(IRRIGADO!G:G,IRRIGADO!C:C,ESTIMATIVA[[#This Row],[CD_UPNIVEL1]],IRRIGADO!E:E,ESTIMATIVA[[#This Row],[CD_UPNIVEL3]])*ESTIMATIVA[[#This Row],[QT_AREA_REAL]]) -> 0 | AK9: =COUNTIFS(Apresentação!$E$23:$E$29,ESTIMATIVA[[#This Row],[CD_UPNIVEL1]]) -> 0
A10: 10310 | B10: Fazenda Sao Jorge | C10: 4 | D10: 3 | E10: 3ºC | F10: E | H10: Mineral | I10: SP83-2847 | J10: 3 - Parceria | K10: 16.52 | L10: 16.52 | M10: 16.52 | N10: 16.52 | O10: 1123.36 | P10: 826 | Q10: 826 | R10: 663.81 | S10: UMOE | T10: 45935 | U10: =IF(ESTIMATIVA[[#This Row],[QT_AREA_REAL]]>0,"1- Colhido","2- à Colher") -> 1- Colhido | V10: =IF(ESTIMATIVA[[#This Row],[QT_AREA_REST1]]>0,"Reestimativa 1",IF(ESTIMATIVA[[#This Row],[QT_AREA_REAL]]=0,"Reestimativa 1","Realizado")) -> Reestimativa 1 | W10: =IF(ESTIMATIVA[[#This Row],[QT_AREA_REST2]]>0,"Reestimativa 2",IF(ESTIMATIVA[[#This Row],[QT_AREA_REAL]]=0,"Reestimativa 2","Realizado")) -> Reestimativa 2 | X10: =ESTIMATIVA[[#This Row],[QT_AREA_EST]] -> 16.52 | Y10: =IF(ESTIMATIVA[[#This Row],[QT_AREA_REST1]]>0,ESTIMATIVA[[#This Row],[QT_AREA_REST1]], IF(ESTIMATIVA[[#This Row],[QT_AREA_REAL]]>0,ESTIMATIVA[[#This Row],[QT_AREA_REAL]],ESTIMATIVA[[#This Row],[QT_AREA_EST]])) -> 16.52 | Z10: =IF(ESTIMATIVA[[#This Row],[QT_AREA_REST2]]>0,ESTIMATIVA[[#This Row],[QT_AREA_REST2]], IF(ESTIMATIVA[[#This Row],[QT_AREA_REAL]]>0,ESTIMATIVA[[#This Row],[QT_AREA_REAL]], IF(ESTIMATIVA[[#This Row],[QT_AREA_REST1]]>0,ESTIMATIVA[[#This Row],[QT_AREA_REST1]],ESTIMATIVA[[#This Row],[QT_AREA_EST]]))) -> 16.52 | AA10: =ESTIMATIVA[[#This Row],[QT_CANA_EST]] -> 1123.36 | AB10: =IF(ESTIMATIVA[[#This Row],[QT_CANA_REST1]]>0,ESTIMATIVA[[#This Row],[QT_CANA_REST1]], IF(ESTIMATIVA[[#This Row],[QT_CANA_REAL]]>0,ESTIMATIVA[[#This Row],[QT_CANA_REAL]],ESTIMATIVA[[#This Row],[QT_CANA_EST]])) -> 826 | AC10: =IF(ESTIMATIVA[[#This Row],[QT_CANA_REST2]]>0,ESTIMATIVA[[#This Row],[QT_CANA_REST2]], IF(ESTIMATIVA[[#This Row],[QT_CANA_REAL]]>0,ESTIMATIVA[[#This Row],[QT_CANA_REAL]], IF(ESTIMATIVA[[#This Row],[QT_CANA_REST1]]>0,ESTIMATIVA[[#This Row],[QT_CANA_REST1]],ESTIMATIVA[[#This Row],[QT_CANA_EST]]))) -> 826 | AD10: =IF(ESTIMATIVA[[#This Row],[QT_AREA_REAL]]>0,ESTIMATIVA[[#This Row],[QT_CANA_REAL]],ESTIMATIVA[[#This Row],[QT_CANA_EST]]) -> 663.81 | AE10: =IF(ESTIMATIVA[[#This Row],[QT_AREA_REAL]]>0,ESTIMATIVA[[#This Row],[QT_CANA_REAL]],ESTIMATIVA[[#This Row],[QT_CANA_REST1]]) -> 663.81 | AF10: =IF(ESTIMATIVA[[#This Row],[QT_AREA_REAL]]>0,ESTIMATIVA[[#This Row],[QT_CANA_REAL]],ESTIMATIVA[[#This Row],[QT_CANA_REST2]]) -> 663.81 | AG10: =IF(COUNTIFS(GEADA!A:A,VALUE(ESTIMATIVA[[#This Row],[CD_UPNIVEL1]]&TEXT(ESTIMATIVA[[#This Row],[CD_UPNIVEL3]],"0000")))>0,"S","N") -> S | AH10: =IF(COUNTIFS(IRRIGADO!C:C,ESTIMATIVA[[#This Row],[CD_UPNIVEL1]],IRRIGADO!E:E,ESTIMATIVA[[#This Row],[CD_UPNIVEL3]])>0,"Irrigado",IF(ESTIMATIVA[[#This Row],[DE_SIST_CULT]]="Mineral","Sequeiro",ESTIMATIVA[[#This Row],[DE_SIST_CULT]])) -> Sequeiro | AI10: =IF(ESTIMATIVA[[#This Row],[TP_CULTIVO]]="Irrigado",_xlfn.MAXIFS(IRRIGADO!J:J,IRRIGADO!C:C,ESTIMATIVA[[#This Row],[CD_UPNIVEL1]],IRRIGADO!E:E,ESTIMATIVA[[#This Row],[CD_UPNIVEL3]]),"") | AJ10: =IF(ESTIMATIVA[[#This Row],[TP_CULTIVO]]<>"Irrigado",0,AVERAGEIFS(IRRIGADO!G:G,IRRIGADO!C:C,ESTIMATIVA[[#This Row],[CD_UPNIVEL1]],IRRIGADO!E:E,ESTIMATIVA[[#This Row],[CD_UPNIVEL3]])*ESTIMATIVA[[#This Row],[QT_AREA_REAL]]) -> 0 | AK10: =COUNTIFS(Apresentação!$E$23:$E$29,ESTIMATIVA[[#This Row],[CD_UPNIVEL1]]) -> 0
