Workbook

Sheet Apresentação Gerencial
A1: 📊 APRESENTAÇÃO GERENCIAL | MATRIZ ORGANOGRAMA EXECUTIVA
A2: Análise Consolidada de Headcount | Agrícola + Manutenção Automotiva | Reduções Possível e Recomendada
A4: 1️⃣ RESUMO GERAL DO ORGANOGRAMA
A5: INDICADOR | B5: AGRÍCOLA | C5: MANUTENÇÃO | D5: TOTAL | E5: % TOTAL | G5: CRITICIDADE | H5: HC | I5: % TOTAL
A6: HC Total | B6: ='[1]Matriz Organograma'!R4 -> 754 | C6: ='[1]Matriz Organograma'!S4 -> 213 | D6: ='[1]Matriz Organograma'!T4 -> 967 | E6: =D6/D6 -> 1 | G6: 🟢 Crítica | H6: ='[1]Matriz Organograma'!J182 -> 732 | I6: =H6/$D$6 -> 0.75698035
A7: HC Crítico | B7: ='[1]Matriz Organograma'!R5 -> 568 | C7: ='[1]Matriz Organograma'!S5 -> 164 | D7: ='[1]Matriz Organograma'!T5 -> 732 | E7: =D7/D6 -> 0.75698035 | G7: 🟡 Alto | H7: ='[1]Matriz Organograma'!J183 -> 142 | I7: =H7/$D$6 -> 0.14684592
A8: HC Vinc. Equipamento | B8: ='[1]Matriz Organograma'!R6 -> 491 | C8: ='[1]Matriz Organograma'!S6 -> 163 | D8: ='[1]Matriz Organograma'!T6 -> 654 | E8: =D8/D6 -> 0.67631851 | G8: 🟠 Média | H8: ='[1]Matriz Organograma'!J184 -> 30 | I8: =H8/$D$6 -> 0.031023785
A9: Redução Possível | B9: ='[1]Matriz Organograma'!R7 -> 87 | C9: ='[1]Matriz Organograma'!S7 -> 18 | D9: ='[1]Matriz Organograma'!T7 -> 105 | E9: =D9/D6 -> 0.10858325 | G9: ⚪ Baixa | H9: ='[1]Matriz Organograma'!J185 -> 63 | I9: =H9/$D$6 -> 0.065149948
A10: Redução Recomendada | B10: 36 | C10: ='[1]Matriz Organograma'!S8 -> 5 | D10: 41 | E10: 4,2% | G10: TOTAL | H10: =SUM(H6:H9) -> 967 | I10: =H10/$D$6 -> 1
A11: HC Pós Redução Recom. | B11: 718 | C11: ='[1]Matriz Organograma'!S9 -> 208 | D11: 926 | E11: 95,8%
A13: 2️⃣ RESUMO POR SETOR E RESPONSÁVEL
A14: SETOR | B14: RESPONSÁVEL | C14: HC | D14: HC CRÍTICO | E14: HC VINC. EQUIP. | F14: RED. POSSÍVEL | G14: RED. RECOM. | H14: % HC
A15: Agrícola | B15: Flávio | C15: ='[1]Matriz Organograma'!C191 -> 243 | D15: ='[1]Matriz Organograma'!D191 -> 243 | E15: ='[1]Matriz Organograma'!E191 -> 202 | F15: ='[1]Matriz Organograma'!F191 -> 26 | G15: ='[1]Matriz Organograma'!G191 -> 7 | H15: =C15/$D$6 -> 0.25129266
A16: Agrícola | B16: Elias | C16: ='[1]Matriz Organograma'!C192 -> 182 | D16: ='[1]Matriz Organograma'!D192 -> 98 | E16: ='[1]Matriz Organograma'!E192 -> 98 | F16: ='[1]Matriz Organograma'!F192 -> 2 | G16: ='[1]Matriz Organograma'!G192 -> 2 | H16: =C16/$D$6 -> 0.18821096
A17: Agrícola | B17: Rogério | C17: ='[1]Matriz Organograma'!C193 -> 123 | D17: ='[1]Matriz Organograma'!D193 -> 87 | E17: ='[1]Matriz Organograma'!E193 -> 87 | F17: ='[1]Matriz Organograma'!F193 -> 19 | G17: ='[1]Matriz Organograma'!G193 -> 16 | H17: =C17/$D$6 -> 0.12719752
A18: Agrícola | B18: Ronaldo | C18: ='[1]Matriz Organograma'!C194 -> 120 | D18: ='[1]Matriz Organograma'!D194 -> 118 | E18: ='[1]Matriz Organograma'!E194 -> 84 | F18: ='[1]Matriz Organograma'!F194 -> 3 | G18: ='[1]Matriz Organograma'!G194 -> 1 | H18: =C18/$D$6 -> 0.12409514
A19: Agrícola | B19: Helena | C19: ='[1]Matriz Organograma'!C195 -> 34 | D19: ='[1]Matriz Organograma'!D195 -> 4 | E19: ='[1]Matriz Organograma'!E195 -> 2 | F19: ='[1]Matriz Organograma'!F195 -> 26 | G19: ='[1]Matriz Organograma'!G195 -> 1 | H19: =C19/$D$6 -> 0.03516029
A20: Agrícola | B20: Laércio | C20: ='[1]Matriz Organograma'!C196 -> 32 | D20: ='[1]Matriz Organograma'!D196 -> 18 | E20: ='[1]Matriz Organograma'!E196 -> 18 | F20: ='[1]Matriz Organograma'!F196 -> 9 | G20: ='[1]Matriz Organograma'!G196 -> 7 | H20: =C20/$D$6 -> 0.033092037
A21: Agrícola | B21: Pedro | C21: ='[1]Matriz Organograma'!C197 -> 12 | D21: ='[1]Matriz Organograma'!D197 -> 0 | E21: ='[1]Matriz Organograma'!E197 -> 0 | F21: ='[1]Matriz Organograma'!F197 -> 1 | G21: ='[1]Matriz Organograma'!G197 -> 1 | H21: =C21/$D$6 -> 0.012409514
A22: Agrícola | B22: Everton | C22: ='[1]Matriz Organograma'!C198 -> 7 | D22: ='[1]Matriz Organograma'!D198 -> 0 | E22: ='[1]Matriz Organograma'!E198 -> 0 | F22: ='[1]Matriz Organograma'!F198 -> 1 | G22: ='[1]Matriz Organograma'!G198 -> 1 | H22: =C22/$D$6 -> 0.0072388831
A23: Agrícola | B23: Devanir | C23: ='[1]Matriz Organograma'!C199 -> 1 | D23: ='[1]Matriz Organograma'!D199 -> 0 | E23: ='[1]Matriz Organograma'!E199 -> 0 | F23: ='[1]Matriz Organograma'!F199 -> 0 | G23: ='[1]Matriz Organograma'!G199 -> 0 | H23: =C23/$D$6 -> 0.0010341262
A24: Manutenção | B24: Paulo | C24: ='[1]Matriz Organograma'!C200 -> 76 | D24: ='[1]Matriz Organograma'!D200 -> 69 | E24: ='[1]Matriz Organograma'!E200 -> 66 | F24: ='[1]Matriz Organograma'!F200 -> 2 | G24: ='[1]Matriz Organograma'!G200 -> 0 | H24: =C24/$D$6 -> 0.078593588
A25: Manutenção | B25: Adriano | C25: ='[1]Matriz Organograma'!C201 -> 60 | D25: ='[1]Matriz Organograma'!D201 -> 33 | E25: ='[1]Matriz Organograma'!E201 -> 36 | F25: ='[1]Matriz Organograma'!F201 -> 9 | G25: ='[1]Matriz Organograma'!G201 -> 4 | H25: =C25/$D$6 -> 0.06204757
A26: Manutenção | B26: Hugo | C26: ='[1]Matriz Organograma'!C202 -> 50 | D26: ='[1]Matriz Organograma'!D202 -> 39 | E26: ='[1]Matriz Organograma'!E202 -> 39 | F26: ='[1]Matriz Organograma'!F202 -> 6 | G26: ='[1]Matriz Organograma'!G202 -> 1 | H26: =C26/$D$6 -> 0.051706308
A27: Manutenção | B27: Luiz Jr. | C27: ='[1]Matriz Organograma'!C203 -> 27 | D27: ='[1]Matriz Organograma'!D203 -> 23 | E27: ='[1]Matriz Organograma'!E203 -> 22 | F27: ='[1]Matriz Organograma'!F203 -> 1 | G27: ='[1]Matriz Organograma'!G203 -> 0 | H27: =C27/$D$6 -> 0.027921406
A28: TOTAL | B28: - | C28: =SUM(C15:C27) -> 967 | D28: =SUM(D15:D27) -> 732 | E28: =SUM(E15:E27) -> 654 | F28: =SUM(F15:F27) -> 105 | G28: =SUM(G15:G27) -> 41 | H28: =C28/$D$6 -> 1
A31: 3️⃣ RESUMO EXECUTIVO | REDUÇÃO POR FUNÇÃO
A32: FUNÇÃO | B32: HC TOTAL | C32: % HC | D32: RED. POSSÍVEL | E32: % POSS. | F32: RED. RECOM. | G32: % RECOM. | H32: OBS/JUSTIFICATIVA
A33: Coordenação | B33: 14 | C33: 1,4% | D33: 0 | E33: 0,0% | F33: 0 | G33: 0,0% | H33: Função estratégica - NÃO reduzir | K33: Função | L33: Possível | M33: Recomendada
A34: Gestor | B34: 7 | C34: 0,7% | D34: 2 | E34: 28,6% | F34: 0 | G34: 0,0% | H34: Gestão operacional crítica | K34: =A33 -> Coordenação | L34: =D33 -> 0 | M34: =F33 -> 0
A35: Trainee | B35: 3 | C35: 0,3% | D35: 3 | E35: 1 | F35: 2 | G35: 66,7% | H35: Formação de líderes - avaliar necessidade | K35: =A34 -> Gestor | L35: =D34 -> 2 | M35: =F34 -> 0
A36: Líder | B36: 68 | C36: 7,0% | D36: 18 | E36: 26,5% | F36: 13 | G36: 19,1% | H36: Supervisão direta - reduzir com cautela | K36: =A35 -> Trainee | L36: =D35 -> 3 | M36: =F35 -> 2
A37: Operador | B37: 287 | C37: 29,7% | D37: 32 | E37: 11,1% | F37: 0 | G37: 0,0% | H37: 🔒 PROTEGIDO - Operação direta equipamentos | K37: =A36 -> Líder | L37: =D36 -> 18 | M37: =F36 -> 13
A38: Motorista | B38: 89 | C38: 9,2% | D38: 8 | E38: 9,0% | F38: 0 | G38: 0,0% | H38: 🔒 PROTEGIDO - Logística essencial | K38: =A37 -> Operador | L38: =D37 -> 32 | M38: =F37 -> 0
A39: Mecânico | B39: 98 | C39: 10,1% | D39: 12 | E39: 12,2% | F39: 0 | G39: 0,0% | H39: 🔒 PROTEGIDO - Manutenção equipamentos | K39: =A38 -> Motorista | L39: =D38 -> 8 | M39: =F38 -> 0
A40: Eletricista | B40: 24 | C40: 2,5% | D40: 4 | E40: 16,7% | F40: 0 | G40: 0,0% | H40: 🔒 PROTEGIDO - Suporte elétrico crítico | K40: =A39 -> Mecânico | L40: =D39 -> 12 | M40: =F39 -> 0
A41: Auxiliar | B41: 42 | C41: 4,3% | D41: 8 | E41: 19,0% | F41: 9 | G41: 21,4% | H41: Apoio administrativo - pode otimizar | K41: =A40 -> Eletricista | L41: =D40 -> 4 | M41: =F40 -> 0
A42: Analista | B42: 12 | C42: 1,2% | D42: 4 | E42: 33,3% | F42: 4 | G42: 33,3% | H42: Funções analíticas - avaliar automação | K42: =A41 -> Auxiliar | L42: =D41 -> 8 | M42: =F41 -> 9
A43: Rurais | B43: 156 | C43: 16,1% | D43: 6 | E43: 3,8% | F43: 6 | G43: 3,8% | H43: Mão de obra direta campo | K43: =A42 -> Analista | L43: =D42 -> 4 | M43: =F42 -> 4
A44: Brigada | B44: 45 | C44: 4,7% | D44: 3 | E44: 6,7% | F44: 0 | G44: 0,0% | H44: 🔒 PROTEGIDO - Segurança/incêndio | K44: =A43 -> Rurais | L44: =D43 -> 6 | M44: =F43 -> 6
...

Sheet 🎯 Dashboard
B2: DASHBOARD EXECUTIVO
B3: Reestruturação de Headcount & Custos | Agrícola + Manutenção Automotiva
B5: HEADCOUNT TOTAL | E5: REDUÇÃO RECOMENDADA | H5: ECONOMIA ANUAL RH | K5: CUSTOS EVITADOS — INICIATIVAS
B6: ='Apresentação Gerencial'!D6 -> 967 | E6: ='Apresentação Gerencial'!D10 -> 41 | H6: =-'Apresentação Gerencial'!J84 -> 3442598.8 | K6: ='Apresentação Gerencial'!C127 -> 10145966
B7: colaboradores (Agrícola + Manutenção) | E7: ='Apresentação Gerencial'!D10/'Apresentação Gerencial'!D6 -> 0.042399173 | H7: custo evitado líquido (salários − indenizações) | K7: agrícola + automotiva
B10: HEADCOUNT POR RESPONSÁVEL | H10: ECONOMIA ANUAL DE RH POR FUNÇÃO (R$)
B30: REDUÇÃO POR FUNÇÃO: POSSÍVEL vs RECOMENDADA | H30: COMPOSIÇÃO DO HEADCOUNT
B40: _dados: HC por responsável | E40: _dados: economia RH por função | H40: _dados: redução por função
B41: Responsável | C41: HC | E41: Função | F41: Economia (R$) | H41: Função | I41: Possível | J41: Recomendada
B42: ='Apresentação Gerencial'!A52 -> Flávio | C42: ='Apresentação Gerencial'!C52 -> 243 | E42: ='Apresentação Gerencial'!A70 -> Coordenação | F42: =-'Apresentação Gerencial'!J70 -> 0 | H42: ='Apresentação Gerencial'!A70 -> Coordenação | I42: ='Apresentação Gerencial'!D70 -> 0 | J42: ='Apresentação Gerencial'!F70 -> 0
B43: ='Apresentação Gerencial'!A53 -> Elias | C43: ='Apresentação Gerencial'!C53 -> 182 | E43: ='Apresentação Gerencial'!A71 -> Gestor | F43: =-'Apresentação Gerencial'!J71 -> 121341.46 | H43: ='Apresentação Gerencial'!A71 -> Gestor | I43: ='Apresentação Gerencial'!D71 -> 2 | J43: ='Apresentação Gerencial'!F71 -> 0
B44: ='Apresentação Gerencial'!A54 -> Rogério | C44: ='Apresentação Gerencial'!C54 -> 123 | E44: ='Apresentação Gerencial'!A72 -> Trainee | F44: =-'Apresentação Gerencial'!J72 -> 219660.86 | H44: ='Apresentação Gerencial'!A72 -> Trainee | I44: ='Apresentação Gerencial'!D72 -> 3 | J44: ='Apresentação Gerencial'!F72 -> 2
B45: ='Apresentação Gerencial'!A55 -> Ronaldo | C45: ='Apresentação Gerencial'!C55 -> 120 | E45: ='Apresentação Gerencial'!A73 -> Líder | F45: =-'Apresentação Gerencial'!J73 -> 311121.15 | H45: ='Apresentação Gerencial'!A73 -> Líder | I45: ='Apresentação Gerencial'!D73 -> 18 | J45: ='Apresentação Gerencial'!F73 -> 13
B46: ='Apresentação Gerencial'!A56 -> Helena | C46: ='Apresentação Gerencial'!C56 -> 34 | E46: ='Apresentação Gerencial'!A74 -> Operador | F46: =-'Apresentação Gerencial'!J74 -> 0 | H46: ='Apresentação Gerencial'!A74 -> Operador | I46: ='Apresentação Gerencial'!D74 -> 32 | J46: ='Apresentação Gerencial'!F74 -> 0
B47: ='Apresentação Gerencial'!A57 -> Laércio | C47: ='Apresentação Gerencial'!C57 -> 32 | E47: ='Apresentação Gerencial'!A75 -> Motorista | F47: =-'Apresentação Gerencial'!J75 -> 0 | H47: ='Apresentação Gerencial'!A75 -> Motorista | I47: ='Apresentação Gerencial'!D75 -> 8 | J47: ='Apresentação Gerencial'!F75 -> 0
B48: ='Apresentação Gerencial'!A58 -> Pedro | C48: ='Apresentação Gerencial'!C58 -> 12 | E48: ='Apresentação Gerencial'!A76 -> Mecânico | F48: =-'Apresentação Gerencial'!J76 -> 0 | H48: ='Apresentação Gerencial'!A76 -> Mecânico | I48: ='Apresentação Gerencial'!D76 -> 12 | J48: ='Apresentação Gerencial'!F76 -> 0
B49: ='Apresentação Gerencial'!A59 -> Everton | C49: ='Apresentação Gerencial'!C59 -> 7 | E49: ='Apresentação Gerencial'!A77 -> Eletricista | F49: =-'Apresentação Gerencial'!J77 -> 0 | H49: ='Apresentação Gerencial'!A77 -> Eletricista | I49: ='Apresentação Gerencial'!D77 -> 4 | J49: ='Apresentação Gerencial'!F77 -> 0
B50: ='Apresentação Gerencial'!A60 -> Devanir | C50: ='Apresentação Gerencial'!C60 -> 1 | E50: ='Apresentação Gerencial'!A78 -> Auxiliar | F50: =-'Apresentação Gerencial'!J78 -> 643106.11 | H50: ='Apresentação Gerencial'!A78 -> Auxiliar | I50: ='Apresentação Gerencial'!D78 -> 8 | J50: ='Apresentação Gerencial'!F78 -> 9
B51: ='Apresentação Gerencial'!A61 -> Paulo | C51: ='Apresentação Gerencial'!C61 -> 76 | E51: ='Apresentação Gerencial'!A79 -> Analista | F51: =-'Apresentação Gerencial'!J79 -> 118060.7 | H51: ='Apresentação Gerencial'!A79 -> Analista | I51: ='Apresentação Gerencial'!D79 -> 4 | J51: ='Apresentação Gerencial'!F79 -> 4
B52: ='Apresentação Gerencial'!A62 -> Adriano | C52: ='Apresentação Gerencial'!C62 -> 60 | E52: ='Apresentação Gerencial'!A80 -> Rurais | F52: =-'Apresentação Gerencial'!J80 -> 477535.2 | H52: ='Apresentação Gerencial'!A80 -> Rurais | I52: ='Apresentação Gerencial'!D80 -> 6 | J52: ='Apresentação Gerencial'!F80 -> 6
B53: ='Apresentação Gerencial'!A63 -> Hugo | C53: ='Apresentação Gerencial'!C63 -> 50 | E53: ='Apresentação Gerencial'!A81 -> Brigada | F53: =-'Apresentação Gerencial'!J81 -> 0 | H53: ='Apresentação Gerencial'!A81 -> Brigada | I53: ='Apresentação Gerencial'!D81 -> 3 | J53: ='Apresentação Gerencial'!F81 -> 0
B54: ='Apresentação Gerencial'!A64 -> Luiz Jr. | C54: ='Apresentação Gerencial'!C64 -> 27 | E54: ='Apresentação Gerencial'!A82 -> Qualidade | F54: =-'Apresentação Gerencial'!J82 -> 0 | H54: ='Apresentação Gerencial'!A82 -> Qualidade | I54: ='Apresentação Gerencial'!D82 -> 0 | J54: ='Apresentação Gerencial'!F82 -> 0
E55: ='Apresentação Gerencial'!A83 -> Outros | F55: =-'Apresentação Gerencial'!J83 -> 434561.89 | H55: ='Apresentação Gerencial'!A83 -> Outros | I55: ='Apresentação Gerencial'!D83 -> 5 | J55: ='Apresentação Gerencial'!F83 -> 7
E57: _comp HC
E58: Pós-redução recomendada | F58: ='Apresentação Gerencial'!D11 -> 926
E59: Redução recomendada | F59: ='Apresentação Gerencial'!D10 -> 41
E60: Redução adicional possível | F60: ='Apresentação Gerencial'!D9-'Apresentação Gerencial'!D10 -> 64

Sheet 📑 Resumo Diretoria
B2: RESUMO PARA DIRETORIA
B3: Reestruturação Agrícola + Manutenção Automotiva | Síntese e Recomendação
B5: CONTEXTO | E5: DECISÃO RECOMENDADA
B6: Análise consolidada de 967 colaboradores (754 Agrícola + 213 Manutenção). Do total, 732 são HC crítico (75,7%) e 654 estão vinculados a equipamentos. A proposta combina otimização de headcount com iniciativas agronômicas e automotivas de redução de custo. | E6: Aprovar a redução recomendada de 41 posições (4,2% do HC), preservando 100% das funções protegidas (Operador, Motorista, Mecânico, Eletricista, Brigada, Qualidade) ligadas à operação direta de equipamentos. Maior potencial concentrado em Rogério (16) e nas funções Líder e Auxiliar. Avançar com as iniciativas agronômicas e de frota em paralelo.
B8: IMPACTO FINANCEIRO CONSOLIDADO | E8: NÚMEROS-CHAVE DE HEADCOUNT
B9: Frente | C9: Valor Anual (R$) | D9: Tipo | E9: HC total | F9: ='Apresentação Gerencial'!D6 -> 967
B10: Economia anual de RH (líquida de indenizações) | C10: =-'Apresentação Gerencial'!J84 -> 3442598.8 | D10: Custo evitado | E10: HC crítico (75,7%) | F10: ='Apresentação Gerencial'!D7 -> 732
B11: Custos evitados — iniciativas agrícolas (c/ impacto produção) | C11: ='Apresentação Gerencial'!C100 -> 8537813.9 | D11: Custo evitado | E11: Vinculado a equipamento | F11: ='Apresentação Gerencial'!D8 -> 654
B12: Custos evitados — iniciativas agrícolas (sem impacto) | C12: ='Apresentação Gerencial'!C117 -> 1082000 | D12: Custo evitado | E12: Redução possível | F12: ='Apresentação Gerencial'!D9 -> 105
B13: Custos evitados — frota / automotiva | C13: ='Apresentação Gerencial'!C125 -> 526151.92 | D13: Custo evitado | E13: Redução recomendada | F13: ='Apresentação Gerencial'!D10 -> 41
B14: TOTAL ANUAL DE GANHO POTENCIAL | C14: =SUM(C10:C13) -> 13588565 | E14: HC pós-redução | F14: ='Apresentação Gerencial'!D11 -> 926
B16: NOTA — RECEITA PROTEGIDA
B17: As iniciativas agrícolas com impacto em produtividade sustentam um ganho estimado de receita de etanol entre R$ 21,0 mi (cenário baixo) e R$ 43,5 mi (cenário alto), com R$ 32,2 mi no cenário médio — além dos custos evitados acima. Os ganhos de produtividade (TCH/ATR) reforçam o retorno do programa para muito além da redução de despesa.
B19: Fonte: aba 'Apresentação Gerencial' | Reestruturação Umoe.xlsb. Valores anuais.

Sheet 🖥️ Deck Slides
B9: REESTRUTURAÇÃO 2025
B12: Agrícola + Manutenção Automotiva | Apresentação Gerencial Executiva
B15: Headcount • Redução de Custos • Receita Protegida
B22: 1. PANORAMA GERAL
C25: ='Apresentação Gerencial'!D6 -> 967 | F25: ='Apresentação Gerencial'!D10 -> 41 | J25: ='📑 Resumo Diretoria'!C10 -> 3442598.8 | N25: ='📑 Resumo Diretoria'!C14 -> 13588565
C26: Headcount total | F26: Redução recomendada (4,2%) | J26: Economia anual de RH | N26: Ganho total potencial/ano
C31: • 754 colaboradores na operação Agrícola e 213 na Manutenção Automotiva
C33: • 732 posições (75,7%) classificadas como HC crítico; 654 vinculadas a equipamentos
C35: • Redução possível de 105 posições; recomenda-se 41, preservando funções protegidas
C37: • Programa combina otimização de pessoas + iniciativas agronômicas e de frota
B42: 2. REDUÇÃO POR FUNÇÃO — POSSÍVEL vs RECOMENDADA
B62: 3. ECONOMIA DE RH POR FUNÇÃO (R$/ANO)
B82: 4. CUSTOS EVITADOS & RECEITA PROTEGIDA
B105: CONCLUSÃO & RECOMENDAÇÃO
B109: Aprovar 41 desligamentos recomendados (4,2%) + avançar com iniciativas agronômicas e de frota
B112: ='📑 Resumo Diretoria'!C14 -> 13588565
B116: + receita de etanol protegida estimada em R$ 32,2 mi/ano (cenário médio)
C123: Frente | D123: R$ | F123: Cenário receita etanol | G123: R$
C124: RH (líquido) | D124: ='📑 Resumo Diretoria'!C10 -> 3442598.8 | F124: Baixo | G124: ='Apresentação Gerencial'!I100 -> 20953791
C125: Agr c/ impacto | D125: ='📑 Resumo Diretoria'!C11 -> 8537813.9 | F125: Médio | G125: ='Apresentação Gerencial'!J100 -> 32203498
C126: Agr sem impacto | D126: ='📑 Resumo Diretoria'!C12 -> 1082000 | F126: Alto | G126: ='Apresentação Gerencial'!K100 -> 43453205
C127: Frota/Automotiva | D127: ='📑 Resumo Diretoria'!C13 -> 526151.92
